Workbook
Name GlobalStartDate: Settings!$K$7
Name SizeList: Lists!$A$1:$A$15

Sheet Dashboard
A1: RING PARTS — PRODUCTION PLANNING DASHBOARD
A2: =TODAY() | C2: Auto-refreshed on open
A4: PLAN SUMMARY
A5: Total Jobs | B5: Released | C5: On Hold | D5: Cancelled | E5: High Priority | F5: Plan Start | G5: Plan End | H5: Plan Duration (Days)
A6: =COUNTA(Job_Master_Ring!A4:A1000) | B6: =COUNTIF(Job_Master_Ring!I4:I1000,"Released") | C6: =COUNTIF(Job_Master_Ring!I4:I1000,"On Hold") | D6: =COUNTIF(Job_Master_Ring!I4:I1000,"Cancelled") | E6: =COUNTIF(Job_Master_Ring!G4:G1000,"High") | F6: =MIN(Job_Master_Ring!E4:E1000) | G6: =MAX(Job_Master_Ring!F4:F1000) | H6: =IFERROR(INT(G6-F6),"")
B7: STAGE CAPACITY ANALYSIS
A8: STAGE LOAD vs CAPACITY SUMMARY | B8: Stage | C8: Machines | D8: Total Load (Hrs) | E8: Capacity (Hrs) | F8: Utilization % | G8: Target | J8: 🔴 Bottleneck: | K8: =INDEX(B9:B15,MATCH(MAX(F9:F15),F9:F15,0))
A9: Stage | B9: VTL | C9: 4 | D9: =IFERROR(SUM(VTL_Plan!L4:L103),0) | E9: =4*189*Settings!$K$4 | F9: =IFERROR(D9/E9,0) | G9: 0.9 | J9: Max Util: | K9: =MAX(F9:F15)
A10: CNC | B10: 8 | C10: =IFERROR(SUM(CNC_Plan!L4:L103),0) | D10: =8*189*Settings!$K$4 | E10: =IFERROR(C10/D10,0) | F10: 0.9 | G10: 0.9 | J10: 🟢 Lowest: | K10: =INDEX(B9:B15,MATCH(MIN(F9:F15),F9:F15,0))
A11: ENG | B11: 14 | C11: =IFERROR(SUM(ENG_Plan!L4:L103),0) | D11: =14*189*Settings!$K$4 | E11: =IFERROR(C11/D11,0) | F11: 0.9 | G11: 0.9
A12: VENT | B12: 8 | C12: =IFERROR(SUM(VENT_Plan!L4:L103),0) | D12: =8*189*Settings!$K$4 | E12: =IFERROR(C12/D12,0) | F12: 0.9 | G12: 0.9 | J12: Released Jobs %: | K12: =IFERROR(COUNTIF(Job_Master_Ring!I4:I1000,"Released")/COUNTA(Job_Master_Ring!A4:A1000),0)
A13: FID | B13: 10 | C13: =IFERROR(SUM(FID_Plan!L4:L103),0) | D13: =10*189*Settings!$K$4 | E13: =IFERROR(C13/D13,0) | F13: 0.9 | G13: 0.9 | J13: High Priority: | K13: =COUNTIF(Job_Master_Ring!G4:G1000,"High")
A14: QC | B14: 5 | C14: =IFERROR(SUM(QC_Plan!L4:L103),0) | D14: =5*189*Settings!$K$4 | E14: =IFERROR(C14/D14,0) | F14: 0.9 | G14: 0.9
G15: 0.9
A17: JOB TYPE BREAKDOWN
A18: BR1 | B18: BR2 | C18: CR2 | D18: CR3 | E18: CR4 | F18: RIM | G18: BPR
A19: =COUNTIF(Job_Master_Ring!C4:C1000,"BR1") | B19: =COUNTIF(Job_Master_Ring!C4:C1000,"BR2") | C19: =COUNTIF(Job_Master_Ring!C4:C1000,"CR2") | D19: =COUNTIF(Job_Master_Ring!C4:C1000,"CR3") | E19: =COUNTIF(Job_Master_Ring!C4:C1000,"CR4") | F19: =COUNTIF(Job_Master_Ring!C4:C1000,"RIM") | G19: =COUNTIF(Job_Master_Ring!C4:C1000,"BPR")
A21: PRIORITY BREAKDOWN | E21: STATUS BREAKDOWN
A22: High | B22: Medium | C22: Low | E22: Released | F22: On Hold | G22: Cancelled
A23: =COUNTIF(Job_Master_Ring!G4:G1000,"High") | B23: =COUNTIF(Job_Master_Ring!G4:G1000,"Medium") | C23: =COUNTIF(Job_Master_Ring!G4:G1000,"Low") | E23: =COUNTIF(Job_Master_Ring!I4:I1000,"Released") | F23: =COUNTIF(Job_Master_Ring!I4:I1000,"On Hold") | G23: =COUNTIF(Job_Master_Ring!I4:I1000,"Cancelled")
A25: BOTTLENECK ALERT
A26: Highest Loaded Stage: | B26: =INDEX(A10:A14,MATCH(MAX(E10:E14),E10:E14,0))
A27: Utilization %: | B27: =MAX(E10:E14)
A28: Lowest Loaded Stage: | B28: =INDEX(A10:A14,MATCH(MIN(E10:E14),E10:E14,0))
B33: JOB TYPE BREAKDOWN
B34: Type | C34: Count | D34: % of Total
B35: BR1 | C35: =COUNTIF(Job_Master_Ring!C4:C1000,"BR1") | D35: =IFERROR(C35/COUNTA(Job_Master_Ring!A4:A1000),0)
B36: BR2 | C36: =COUNTIF(Job_Master_Ring!C4:C1000,"BR2") | D36: =IFERROR(C36/COUNTA(Job_Master_Ring!A4:A1000),0)
B37: CR2 | C37: =COUNTIF(Job_Master_Ring!C4:C1000,"CR2") | D37: =IFERROR(C37/COUNTA(Job_Master_Ring!A4:A1000),0)
B38: CR3 | C38: =COUNTIF(Job_Master_Ring!C4:C1000,"CR3") | D38: =IFERROR(C38/COUNTA(Job_Master_Ring!A4:A1000),0)
B39: CR4 | C39: =COUNTIF(Job_Master_Ring!C4:C1000,"CR4") | D39: =IFERROR(C39/COUNTA(Job_Master_Ring!A4:A1000),0)
B40: RIM | C40: =COUNTIF(Job_Master_Ring!C4:C1000,"RIM") | D40: =IFERROR(C40/COUNTA(Job_Master_Ring!A4:A1000),0)
B41: BPR | C41: =COUNTIF(Job_Master_Ring!C4:C1000,"BPR") | D41: =IFERROR(C41/COUNTA(Job_Master_Ring!A4:A1000),0)

Sheet Job_Master_Ring
A1: JOB MASTER — RING PARTS
J2: ← Type to override auto date
A3: Job ID | B3: Size | C3: Type | D3: No of Parts | E3: Overall Start | F3: Overall End | G3: Priority | H3: End Month | I3: Status | J3: Due Date | K3: Customer | L3: 46113 | M3: 46114 | N3: 46115 | O3: 46116 | P3: 46118 | Q3: 46119 | R3: 46120 | S3: 46121 | T3: 46122 | U3: 46123 | V3: 46124 | W3: 46125 | X3: 46126 | Y3: 46127 | Z3: 46128 | AA3: 46129 | AB3: 46130 | AC3: 46131 | AD3: 46132 | AE3: 46133 | AF3: 46134 | AG3: 46135 | AH3: 46136 | AI3: 46137 | AJ3: 46138 | AK3: 46139 | AL3: 46140 | AM3: 46141 | AN3: 46142 | AO3: 46143 | AP3: 46144 | AQ3: 46145 | AR3: 46146 | AS3: 46147 | AT3: 46148 | AU3: 46149 | AV3: 46150 | AW3: 46151 | AX3: 46152 | AY3: 46153 | AZ3: 46154 | BA3: 46155 | BB3: 46156 | BC3: 46157 | BD3: 46158 | BE3: 46159 | BF3: 46160 | BG3: 46161 | BH3: 46162 | BI3: 46163 | BJ3: 46164 | BK3: 46165 | BL3: 46166 | BM3: 46167 | BN3: 46168 | BO3: 46169 | BP3: 46170 | BQ3: 46171 | BR3: 46172
A4: RJ-101 | B4: 15 | C4: BR2 | D4: =IF($A4="","",IFERROR(CHOOSE(MATCH($C4,Settings!$L$4:$L$10,0),OPR_BR1!$B$2,OPR_BR2!$B$2,OPR_CR2!$B$2,OPR_CR3!$B$2,OPR_CR4!$B$2,OPR_RIM!$B$2,OPR_BPR!$B$2),1)) | E4: 46220.292 | F4: 46244.292 | G4: High | H4: =IF($A4="","",TEXT($F4,"MMM-YYYY")) | I4: Cancelled | J4: =IF($A4="","",$F4+30) | K4: Gamma Inc | L4: =IF(AND(L$3>=$E4,L$3<=$F4),1,"") | M4: =IF(AND(M$3>=$E4,M$3<=$F4),1,"") | N4: =IF(AND(N$3>=$E4,N$3<=$F4),1,"") | O4: =IF(AND(O$3>=$E4,O$3<=$F4),1,"") | P4: =IF(AND(P$3>=$E4,P$3<=$F4),1,"") | Q4: =IF(AND(Q$3>=$E4,Q$3<=$F4),1,"") | R4: =IF(AND(R$3>=$E4,R$3<=$F4),1,"") | S4: =IF(AND(S$3>=$E4,S$3<=$F4),1,"") | ... BR4: =IF(AND(BR$3>=$E4,BR$3<=$F4),1,"")
A5: RJ-102 | B5: 54 | C5: BR2 | D5: =IF($A5="","",IFERROR(CHOOSE(MATCH($C5,Settings!$L$4:$L$10,0),OPR_BR1!$B$2,OPR_BR2!$B$2,OPR_CR2!$B$2,OPR_CR3!$B$2,OPR_CR4!$B$2,OPR_RIM!$B$2,OPR_BPR!$B$2),1)) | E5: 46230.292 | F5: 46304.292 | G5: Medium | H5: =IF($A5="","",TEXT($F5,"MMM-YYYY")) | I5: Released | J5: =IF($A5="","",$F5+30) | K5: Gamma Inc | L5: =IF(AND(L$3>=$E5,L$3<=$F5),1,"") | M5: =IF(AND(M$3>=$E5,M$3<=$F5),1,"") | N5: =IF(AND(N$3>=$E5,N$3<=$F5),1,"") | O5: =IF(AND(O$3>=$E5,O$3<=$F5),1,"") | P5: =IF(AND(P$3>=$E5,P$3<=$F5),1,"") | Q5: =IF(AND(Q$3>=$E5,Q$3<=$F5),1,"") | R5: =IF(AND(R$3>=$E5,R$3<=$F5),1,"") | S5: =IF(AND(S$3>=$E5,S$3<=$F5),1,"") | ... BR5: =IF(AND(BR$3>=$E5,BR$3<=$F5),1,"")
A6: RJ-103 | B6: 42 | C6: CR3 | D6: =IF($A6="","",IFERROR(CHOOSE(MATCH($C6,Settings!$L$4:$L$10,0),OPR_BR1!$B$2,OPR_BR2!$B$2,OPR_CR2!$B$2,OPR_CR3!$B$2,OPR_CR4!$B$2,OPR_RIM!$B$2,OPR_BPR!$B$2),1)) | E6: 46153.292 | F6: 46221.292 | G6: Medium | H6: =IF($A6="","",TEXT($F6,"MMM-YYYY")) | I6: Cancelled | J6: =IF($A6="","",$F6+30) | K6: Delta Co | L6: =IF(AND(L$3>=$E6,L$3<=$F6),1,"") | M6: =IF(AND(M$3>=$E6,M$3<=$F6),1,"") | N6: =IF(AND(N$3>=$E6,N$3<=$F6),1,"") | O6: =IF(AND(O$3>=$E6,O$3<=$F6),1,"") | P6: =IF(AND(P$3>=$E6,P$3<=$F6),1,"") | Q6: =IF(AND(Q$3>=$E6,Q$3<=$F6),1,"") | R6: =IF(AND(R$3>=$E6,R$3<=$F6),1,"") | S6: =IF(AND(S$3>=$E6,S$3<=$F6),1,"") | ... BR6: =IF(AND(BR$3>=$E6,BR$3<=$F6),1,"")
A7: RJ-104 | B7: 42 | C7: BPR | D7: =IF($A7="","",IFERROR(CHOOSE(MATCH($C7,Settings!$L$4:$L$10,0),OPR_BR1!$B$2,OPR_BR2!$B$2,OPR_CR2!$B$2,OPR_CR3!$B$2,OPR_CR4!$B$2,OPR_RIM!$B$2,OPR_BPR!$B$2),1)) | E7: 46118.292 | F7: 46161.292 | G7: Low | H7: =IF($A7="","",TEXT($F7,"MMM-YYYY")) | I7: Released | J7: =IF($A7="","",$F7+30) | K7: Gamma Inc | L7: =IF(AND(L$3>=$E7,L$3<=$F7),1,"") | M7: =IF(AND(M$3>=$E7,M$3<=$F7),1,"") | N7: =IF(AND(N$3>=$E7,N$3<=$F7),1,"") | O7: =IF(AND(O$3>=$E7,O$3<=$F7),1,"") | P7: =IF(AND(P$3>=$E7,P$3<=$F7),1,"") | Q7: =IF(AND(Q$3>=$E7,Q$3<=$F7),1,"") | R7: =IF(AND(R$3>=$E7,R$3<=$F7),1,"") | S7: =IF(AND(S$3>=$E7,S$3<=$F7),1,"") | ... BR7: =IF(AND(BR$3>=$E7,BR$3<=$F7),1,"")
A8: RJ-105 | B8: 42 | C8: RIM | D8: =IF($A8="","",IFERROR(CHOOSE(MATCH($C8,Settings!$L$4:$L$10,0),OPR_BR1!$B$2,OPR_BR2!$B$2,OPR_CR2!$B$2,OPR_CR3!$B$2,OPR_CR4!$B$2,OPR_RIM!$B$2,OPR_BPR!$B$2),1)) | E8: 46220.292 | F8: 46262.292 | G8: High | H8: =IF($A8="","",TEXT($F8,"MMM-YYYY")) | I8: Cancelled | J8: =IF($A8="","",$F8+30) | K8: Delta Co | L8: =IF(AND(L$3>=$E8,L$3<=$F8),1,"") | M8: =IF(AND(M$3>=$E8,M$3<=$F8),1,"") | N8: =IF(AND(N$3>=$E8,N$3<=$F8),1,"") | O8: =IF(AND(O$3>=$E8,O$3<=$F8),1,"") | P8: =IF(AND(P$3>=$E8,P$3<=$F8),1,"") | Q8: =IF(AND(Q$3>=$E8,Q$3<=$F8),1,"") | R8: =IF(AND(R$3>=$E8,R$3<=$F8),1,"") | S8: =IF(AND(S$3>=$E8,S$3<=$F8),1,"") | ... BR8: =IF(AND(BR$3>=$E8,BR$3<=$F8),1,"")
A9: RJ-106 | B9: 9 | C9: CR3 | D9: =IF($A9="","",IFERROR(CHOOSE(MATCH($C9,Settings!$L$4:$L$10,0),OPR_BR1!$B$2,OPR_BR2!$B$2,OPR_CR2!$B$2,OPR_CR3!$B$2,OPR_CR4!$B$2,OPR_RIM!$B$2,OPR_BPR!$B$2),1)) | E9: 46195.292 | F9: 46263.292 | G9: High | H9: =IF($A9="","",TEXT($F9,"MMM-YYYY")) | I9: Released | J9: =IF($A9="","",$F9+30) | K9: Sigma Mfg | L9: =IF(AND(L$3>=$E9,L$3<=$F9),1,"") | M9: =IF(AND(M$3>=$E9,M$3<=$F9),1,"") | N9: =IF(AND(N$3>=$E9,N$3<=$F9),1,"") | O9: =IF(AND(O$3>=$E9,O$3<=$F9),1,"") | P9: =IF(AND(P$3>=$E9,P$3<=$F9),1,"") | Q9: =IF(AND(Q$3>=$E9,Q$3<=$F9),1,"") | R9: =IF(AND(R$3>=$E9,R$3<=$F9),1,"") | S9: =IF(AND(S$3>=$E9,S$3<=$F9),1,"") | ... BR9: =IF(AND(BR$3>=$E9,BR$3<=$F9),1,"")
A10: RJ-107 | B10: 20 | C10: BR2 | D10: =IF($A10="","",IFERROR(CHOOSE(MATCH($C10,Settings!$L$4:$L$10,0),OPR_BR1!$B$2,OPR_BR2!$B$2,OPR_CR2!$B$2,OPR_CR3!$B$2,OPR_CR4!$B$2,OPR_RIM!$B$2,OPR_BPR!$B$2),1)) | E10: 46152.292 | F10: 46208.292 | G10: High | H10: =IF($A10="","",TEXT($F10,"MMM-YYYY")) | I10: On Hold | J10: =IF($A10="","",$F10+30) | K10: Beta Ltd | L10: =IF(AND(L$3>=$E10,L$3<=$F10),1,"") | M10: =IF(AND(M$3>=$E10,M$3<=$F10),1,"") | N10: =IF(AND(N$3>=$E10,N$3<=$F10),1,"") | O10: =IF(AND(O$3>=$E10,O$3<=$F10),1,"") | P10: =IF(AND(P$3>=$E10,P$3<=$F10),1,"") | Q10: =IF(AND(Q$3>=$E10,Q$3<=$F10),1,"") | R10: =IF(AND(R$3>=$E10,R$3<=$F10),1,"") | S10: =IF(AND(S$3>=$E10,S$3<=$F10),1,"") | ... BR10: =IF(AND(BR$3>=$E10,BR$3<=$F10),1,"")
A11: RJ-108 | B11: 63 | C11: BR1 | D11: =IF($A11="","",IFERROR(CHOOSE(MATCH($C11,Settings!$L$4:$L$10,0),OPR_BR1!$B$2,OPR_BR2!$B$2,OPR_CR2!$B$2,OPR_CR3!$B$2,OPR_CR4!$B$2,OPR_RIM!$B$2,OPR_BPR!$B$2),1)) | E11: 46154.292 | F11: 46214.292 | G11: High | H11: =IF($A11="","",TEXT($F11,"MMM-YYYY")) | I11: On Hold | J11: =IF($A11="","",$F11+30) | K11: Gamma Inc | L11: =IF(AND(L$3>=$E11,L$3<=$F11),1,"") | M11: =IF(AND(M$3>=$E11,M$3<=$F11),1,"") | N11: =IF(AND(N$3>=$E11,N$3<=$F11),1,"") | O11: =IF(AND(O$3>=$E11,O$3<=$F11),1,"") | P11: =IF(AND(P$3>=$E11,P$3<=$F11),1,"") | Q11: =IF(AND(Q$3>=$E11,Q$3<=$F11),1,"") | R11: =IF(AND(R$3>=$E11,R$3<=$F11),1,"") | S11: =IF(AND(S$3>=$E11,S$3<=$F11),1,"") | ... BR11: =IF(AND(BR$3>=$E11,BR$3<=$F11),1,"")
A12: RJ-109 | B12: 46 | C12: BR2 | D12: =IF($A12="","",IFERROR(CHOOSE(MATCH($C12,Settings!$L$4:$L$10,0),OPR_BR1!$B$2,OPR_BR2!$B$2,OPR_CR2!$B$2,OPR_CR3!$B$2,OPR_CR4!$B$2,OPR_RIM!$B$2,OPR_BPR!$B$2),1)) | E12: 46220.292 | F12: 46255.292 | G12: High | H12: =IF($A12="","",TEXT($F12,"MMM-YYYY")) | I12: On Hold | J12: =IF($A12="","",$F12+30) | K12: Beta Ltd | L12: =IF(AND(L$3>=$E12,L$3<=$F12),1,"") | M12: =IF(AND(M$3>=$E12,M$3<=$F12),1,"") | N12: =IF(AND(N$3>=$E12,N$3<=$F12),1,"") | O12: =IF(AND(O$3>=$E12,O$3<=$F12),1,"") | P12: =IF(AND(P$3>=$E12,P$3<=$F12),1,"") | Q12: =IF(AND(Q$3>=$E12,Q$3<=$F12),1,"") | R12: =IF(AND(R$3>=$E12,R$3<=$F12),1,"") | S12: =IF(AND(S$3>=$E12,S$3<=$F12),1,"") | ... BR12: =IF(AND(BR$3>=$E12,BR$3<=$F12),1,"")
A13: RJ-110 | B13: 20 | C13: CR2 | D13: =IF($A13="","",IFERROR(CHOOSE(MATCH($C13,Settings!$L$4:$L$10,0),OPR_BR1!$B$2,OPR_BR2!$B$2,OPR_CR2!$B$2,OPR_CR3!$B$2,OPR_CR4!$B$2,OPR_RIM!$B$2,OPR_BPR!$B$2),1)) | E13: 46139.292 | F13: 46191.292 | G13: Low | H13: =IF($A13="","",TEXT($F13,"MMM-YYYY")) | I13: Released | J13: =IF($A13="","",$F13+30) | K13: Delta Co | L13: =IF(AND(L$3>=$E13,L$3<=$F13),1,"") | M13: =IF(AND(M$3>=$E13,M$3<=$F13),1,"") | N13: =IF(AND(N$3>=$E13,N$3<=$F13),1,"") | O13: =IF(AND(O$3>=$E13,O$3<=$F13),1,"") | P13: =IF(AND(P$3>=$E13,P$3<=$F13),1,"") | Q13: =IF(AND(Q$3>=$E13,Q$3<=$F13),1,"") | R13: =IF(AND(R$3>=$E13,R$3<=$F13),1,"") | S13: =IF(AND(S$3>=$E13,S$3<=$F13),1,"") | ... BR13: =IF(AND(BR$3>=$E13,BR$3<=$F13),1,"")
A14: RJ-111 | B14: 50 | C14: BR2 | D14: =IF($A14="","",IFERROR(CHOOSE(MATCH($C14,Settings!$L$4:$L$10,0),OPR_BR1!$B$2,OPR_BR2!$B$2,OPR_CR2!$B$2,OPR_CR3!$B$2,OPR_CR4!$B$2,OPR_RIM!$B$2,OPR_BPR!$B$2),1)) | E14: 46218.292 | F14: 46292.292 | G14: Low | H14: =IF($A14="","",TEXT($F14,"MMM-YYYY")) | I14: Cancelled | J14: =IF($A14="","",$F14+30) | K14: Delta Co | L14: =IF(AND(L$3>=$E14,L$3<=$F14),1,"") | M14: =IF(AND(M$3>=$E14,M$3<=$F14),1,"") | N14: =IF(AND(N$3>=$E14,N$3<=$F14),1,"") | O14: =IF(AND(O$3>=$E14,O$3<=$F14),1,"") | P14: =IF(AND(P$3>=$E14,P$3<=$F14),1,"") | Q14: =IF(AND(Q$3>=$E14,Q$3<=$F14),1,"") | R14: =IF(AND(R$3>=$E14,R$3<=$F14),1,"") | S14: =IF(AND(S$3>=$E14,S$3<=$F14),1,"") | ... BR14: =IF(AND(BR$3>=$E14,BR$3<=$F14),1,"")
A15: RJ-112 | B15: 46 | C15: CR4 | D15: =IF($A15="","",IFERROR(CHOOSE(MATCH($C15,Settings!$L$4:$L$10,0),OPR_BR1!$B$2,OPR_BR2!$B$2,OPR_CR2!$B$2,OPR_CR3!$B$2,OPR_CR4!$B$2,OPR_RIM!$B$2,OPR_BPR!$B$2),1)) | E15: 46217.292 | F15: 46241.292 | G15: Low | H15: =IF($A15="","",TEXT($F15,"MMM-YYYY")) | I15: Released | J15: =IF($A15="","",$F15+30) | K15: Delta Co | L15: =IF(AND(L$3>=$E15,L$3<=$F15),1,"") | M15: =IF(AND(M$3>=$E15,M$3<=$F15),1,"") | N15: =IF(AND(N$3>=$E15,N$3<=$F15),1,"") | O15: =IF(AND(O$3>=$E15,O$3<=$F15),1,"") | P15: =IF(AND(P$3>=$E15,P$3<=$F15),1,"") | Q15: =IF(AND(Q$3>=$E15,Q$3<=$F15),1,"") | R15: =IF(AND(R$3>=$E15,R$3<=$F15),1,"") | S15: =IF(AND(S$3>=$E15,S$3<=$F15),1,"") | ... BR15: =IF(AND(BR$3>=$E15,BR$3<=$F15),1,"")
... A53: RJ-150 | B53: 17 | C53: RIM | D53: =IF($A53="","",IFERROR(CHOOSE(MATCH($C53,Settings!$L$4:$L$10,0),OPR_BR1!$B$2,OPR_BR2!$B$2,OPR_CR2!$B$2,OPR_CR3!$B$2,OPR_CR4!$B$2,OPR_RIM!$B$2,OPR_BPR!$B$2),1)) | E53: 46219.292 | F53: 46244.292 | G53: Medium | H53: =IF($A53="","",TEXT($F53,"MMM-YYYY")) | I53: Released | J53: =IF($A53="","",$F53+30) | K53: Gamma Inc | L53: =IF(AND(L$3>=$E53,L$3<=$F53),1,"") | M53: =IF(AND(M$3>=$E53,M$3<=$F53),1,"") | N53: =IF(AND(N$3>=$E53,N$3<=$F53),1,"") | O53: =IF(AND(O$3>=$E53,O$3<=$F53),1,"") | P53: =IF(AND(P$3>=$E53,P$3<=$F53),1,"") | Q53: =IF(AND(Q$3>=$E53,Q$3<=$F53),1,"") | R53: =IF(AND(R$3>=$E53,R$3<=$F53),1,"") | S53: =IF(AND(S$3>=$E53,S$3<=$F53),1,"") | ... BR53: =IF(AND(BR$3>=$E53,BR$3<=$F53),1,"")

Sheet OPR_BR1
A1: OPR_BR1
A2: Part No | B2: 1
A3: Size | B3: CNC | C3: SPM | D3: CARVING | E3: EDM | F3: ENG | G3: VENT | H3: FID | I3: QC | J3: Min ID | K3: Max OD
A4: 9 | B4: 8 | C4: 6 | D4: 12 | E4: 5 | F4: 2 | G4: 2 | H4: 8 | I4: 4 | J4: 100 | K4: 600
A5: 15 | B5: 6 | C5: 8 | D5: 3 | E5: 16 | F5: 6 | G5: 6 | H5: 12 | I5: 5 | J5: 300 | K5: 800
A6: 17 | B6: 9 | C6: 16 | D6: 3 | E6: 8 | F6: 8 | G6: 6 | H6: 7 | I6: 5 | J6: 500 | K6: 1000
A7: 20 | B7: 10 | C7: 7 | D7: 7 | E7: 21 | F7: 8 | G7: 12 | H7: 21 | I7: 4 | J7: 700 | K7: 1200
A8: 25 | B8: 9 | C8: 13 | D8: 6 | E8: 15 | F8: 16 | G8: 14 | H8: 22 | I8: 7 | J8: 900 | K8: 1400
A9: 28 | B9: 6 | C9: 24 | D9: 5 | E9: 21 | F9: 14 | G9: 12 | H9: 24 | I9: 7 | J9: 1100 | K9: 1600
A10: 30 | B10: 8 | C10: 25 | D10: 4 | E10: 22 | F10: 7 | G10: 9 | H10: 14 | I10: 7 | J10: 1300 | K10: 1800
A11: 34 | B11: 11 | C11: 11 | D11: 4 | E11: 14 | F11: 15 | G11: 15 | H11: 13 | I11: 7 | J11: 1500 | K11: 2000
A12: 42 | B12: 13 | C12: 23 | D12: 14 | E12: 19 | F12: 15 | G12: 14 | H12: 29 | I12: 5 | J12: 1700 | K12: 2200
A13: 46 | B13: 23 | C13: 28 | D13: 18 | E13: 25 | F13: 19 | G13: 15 | H13: 33 | I13: 11 | J13: 1900 | K13: 2400
A14: 50 | B14: 16 | C14: 27 | D14: 13 | E14: 37 | F14: 24 | G14: 21 | H14: 29 | I14: 13 | J14: 2100 | K14: 2600
A15: 54 | B15: 12 | C15: 37 | D15: 5 | E15: 30 | F15: 18 | G15: 24 | H15: 28 | I15: 6 | J15: 2300 | K15: 2800
... A18: 70 | B18: 22 | C18: 45 | D18: 7 | E18: 35 | F18: 30 | G18: 19 | H18: 42 | I18: 14 | J18: 2900 | K18: 3400

Sheet OPR_BR2
A1: OPR_BR2
A2: Part No | B2: 2
A3: Size | B3: CNC | C3: SPM | D3: CARVING | E3: EDM | F3: ENG | G3: VENT | H3: FID | I3: QC | J3: Min ID | K3: Max OD
A4: 9 | B4: 2 | C4: 14 | D4: 2 | E4: 14 | F4: 9 | G4: 6 | H4: 13 | I4: 3 | J4: 100 | K4: 600
A5: 15 | B5: 5 | C5: 16 | D5: 3 | E5: 13 | F5: 11 | G5: 7 | H5: 9 | I5: 2 | J5: 300 | K5: 800
A6: 17 | B6: 4 | C6: 19 | D6: 5 | E6: 8 | F6: 7 | G6: 10 | H6: 15 | I6: 3 | J6: 500 | K6: 1000
A7: 20 | B7: 12 | C7: 15 | D7: 7 | E7: 16 | F7: 11 | G7: 8 | H7: 17 | I7: 3 | J7: 700 | K7: 1200
A8: 25 | B8: 10 | C8: 19 | D8: 11 | E8: 20 | F8: 11 | G8: 11 | H8: 22 | I8: 6 | J8: 900 | K8: 1400
A9: 28 | B9: 17 | C9: 21 | D9: 14 | E9: 19 | F9: 15 | G9: 12 | H9: 14 | I9: 5 | J9: 1100 | K9: 1600
A10: 30 | B10: 10 | C10: 21 | D10: 3 | E10: 19 | F10: 14 | G10: 12 | H10: 23 | I10: 8 | J10: 1300 | K10: 1800
A11: 34 | B11: 18 | C11: 29 | D11: 14 | E11: 17 | F11: 7 | G11: 12 | H11: 15 | I11: 4 | J11: 1500 | K11: 2000
A12: 42 | B12: 11 | C12: 16 | D12: 6 | E12: 34 | F12: 16 | G12: 15 | H12: 34 | I12: 7 | J12: 1700 | K12: 2200
A13: 46 | B13: 13 | C13: 24 | D13: 14 | E13: 18 | F13: 17 | G13: 20 | H13: 21 | I13: 8 | J13: 1900 | K13: 2400
A14: 50 | B14: 16 | C14: 37 | D14: 16 | E14: 21 | F14: 21 | G14: 12 | H14: 19 | I14: 10 | J14: 2100 | K14: 2600
A15: 54 | B15: 16 | C15: 19 | D15: 13 | E15: 27 | F15: 24 | G15: 19 | H15: 26 | I15: 9 | J15: 2300 | K15: 2800
... A18: 70 | B18: 21 | C18: 38 | D18: 14 | E18: 35 | F18: 29 | G18: 29 | H18: 46 | I18: 14 | J18: 2900 | K18: 3400

Sheet OPR_CR2
A1: OPR_CR2
A2: Part No | B2: 2
A3: Size | B3: CNC | C3: SPM | D3: CARVING | E3: EDM | F3: ENG | G3: VENT | H3: FID | I3: QC | J3: Min ID | K3: Max OD
A4: 9 | B4: 3 | C4: 6 | D4: 11 | E4: 9 | F4: 6 | G4: 5 | H4: 7 | I4: 4 | J4: 100 | K4: 600
A5: 15 | B5: 8 | C5: 9 | D5: 6 | E5: 18 | F5: 5 | G5: 6 | H5: 10 | I5: 6 | J5: 300 | K5: 800
A6: 17 | B6: 11 | C6: 15 | D6: 3 | E6: 15 | F6: 9 | G6: 8 | H6: 7 | I6: 4 | J6: 500 | K6: 1000
A7: 20 | B7: 8 | C7: 15 | D7: 4 | E7: 9 | F7: 11 | G7: 5 | H7: 13 | I7: 4 | J7: 700 | K7: 1200
A8: 25 | B8: 12 | C8: 11 | D8: 10 | E8: 8 | F8: 13 | G8: 15 | H8: 17 | I8: 8 | J8: 900 | K8: 1400
A9: 28 | B9: 10 | C9: 17 | D9: 8 | E9: 9 | F9: 17 | G9: 13 | H9: 15 | I9: 5 | J9: 1100 | K9: 1600
A10: 30 | B10: 7 | C10: 21 | D10: 6 | E10: 19 | F10: 16 | G10: 14 | H10: 27 | I10: 8 | J10: 1300 | K10: 1800
A11: 34 | B11: 12 | C11: 20 | D11: 6 | E11: 21 | F11: 12 | G11: 14 | H11: 22 | I11: 8 | J11: 1500 | K11: 2000
A12: 42 | B12: 17 | C12: 33 | D12: 8 | E12: 30 | F12: 11 | G12: 20 | H12: 34 | I12: 10 | J12: 1700 | K12: 2200
A13: 46 | B13: 13 | C13: 22 | D13: 9 | E13: 16 | F13: 14 | G13: 20 | H13: 28 | I13: 5 | J13: 1900 | K13: 2400
A14: 50 | B14: 23 | C14: 33 | D14: 8 | E14: 20 | F14: 14 | G14: 20 | H14: 29 | I14: 11 | J14: 2100 | K14: 2600
A15: 54 | B15: 16 | C15: 40 | D15: 6 | E15: 24 | F15: 19 | G15: 21 | H15: 24 | I15: 13 | J15: 2300 | K15: 2800
... A18: 70 | B18: 30 | C18: 33 | D18: 15 | E18: 25 | F18: 31 | G18: 17 | H18: 42 | I18: 17 | J18: 2900 | K18: 3400

Sheet OPR_CR3
A1: OPR_CR3
A2: Part No | B2: 3
A3: Size | B3: CNC | C3: SPM | D3: CARVING | E3: EDM | F3: ENG | G3: VENT | H3: FID | I3: QC | J3: Min ID | K3: Max OD
A4: 9 | B4: 5 | C4: 5 | D4: 7 | E4: 10 | F4: 9 | G4: 9 | H4: 6 | I4: 4 | J4: 100 | K4: 600
A5: 15 | B5: 4 | C5: 6 | D5: 11 | E5: 12 | F5: 10 | G5: 6 | H5: 15 | I5: 5 | J5: 300 | K5: 800
A6: 17 | B6: 7 | C6: 18 | D6: 6 | E6: 7 | F6: 8 | G6: 7 | H6: 19 | I6: 6 | J6: 500 | K6: 1000
A7: 20 | B7: 7 | C7: 18 | D7: 2 | E7: 17 | F7: 11 | G7: 10 | H7: 18 | I7: 6 | J7: 700 | K7: 1200
A8: 25 | B8: 15 | C8: 18 | D8: 12 | E8: 14 | F8: 12 | G8: 13 | H8: 23 | I8: 7 | J8: 900 | K8: 1400
A9: 28 | B9: 11 | C9: 21 | D9: 11 | E9: 16 | F9: 6 | G9: 6 | H9: 25 | I9: 6 | J9: 1100 | K9: 1600
A10: 30 | B10: 9 | C10: 18 | D10: 4 | E10: 20 | F10: 7 | G10: 14 | H10: 16 | I10: 9 | J10: 1300 | K10: 1800
A11: 34 | B11: 11 | C11: 24 | D11: 9 | E11: 19 | F11: 14 | G11: 11 | H11: 12 | I11: 6 | J11: 1500 | K11: 2000
A12: 42 | B12: 18 | C12: 17 | D12: 7 | E12: 26 | F12: 11 | G12: 16 | H12: 32 | I12: 9 | J12: 1700 | K12: 2200
A13: 46 | B13: 16 | C13: 26 | D13: 13 | E13: 22 | F13: 24 | G13: 12 | H13: 33 | I13: 9 | J13: 1900 | K13: 2400
A14: 50 | B14: 12 | C14: 20 | D14: 8 | E14: 28 | F14: 12 | G14: 20 | H14: 28 | I14: 8 | J14: 2100 | K14: 2600
A15: 54 | B15: 17 | C15: 37 | D15: 15 | E15: 18 | F15: 20 | G15: 22 | H15: 25 | I15: 6 | J15: 2300 | K15: 2800
... A18: 70 | B18: 25 | C18: 26 | D18: 17 | E18: 22 | F18: 28 | G18: 19 | H18: 23 | I18: 14 | J18: 2900 | K18: 3400

Sheet OPR_CR4
A1: OPR_CR4
A2: Part No | B2: 4
A3: Size | B3: CNC | C3: SPM | D3: CARVING | E3: EDM | F3: ENG | G3: VENT | H3: FID | I3: QC | J3: Min ID | K3: Max OD
A4: 9 | B4: 5 | C4: 13 | D4: 5 | E4: 9 | F4: 2 | G4: 7 | H4: 13 | I4: 3 | J4: 100 | K4: 600
A5: 15 | B5: 12 | C5: 7 | D5: 5 | E5: 5 | F5: 11 | G5: 12 | H5: 13 | I5: 3 | J5: 300 | K5: 800
A6: 17 | B6: 4 | C6: 19 | D6: 2 | E6: 17 | F6: 5 | G6: 11 | H6: 6 | I6: 4 | J6: 500 | K6: 1000
A7: 20 | B7: 12 | C7: 19 | D7: 14 | E7: 8 | F7: 8 | G7: 13 | H7: 16 | I7: 3 | J7: 700 | K7: 1200
A8: 25 | B8: 7 | C8: 17 | D8: 5 | E8: 13 | F8: 11 | G8: 13 | H8: 18 | I8: 7 | J8: 900 | K8: 1400
A9: 28 | B9: 11 | C9: 11 | D9: 7 | E9: 11 | F9: 16 | G9: 12 | H9: 22 | I9: 6 | J9: 1100 | K9: 1600
A10: 30 | B10: 18 | C10: 14 | D10: 7 | E10: 13 | F10: 17 | G10: 11 | H10: 24 | I10: 9 | J10: 1300 | K10: 1800
A11: 34 | B11: 13 | C11: 13 | D11: 7 | E11: 18 | F11: 14 | G11: 12 | H11: 28 | I11: 6 | J11: 1500 | K11: 2000
A12: 42 | B12: 22 | C12: 14 | D12: 8 | E12: 20 | F12: 17 | G12: 10 | H12: 27 | I12: 9 | J12: 1700 | K12: 2200
A13: 46 | B13: 11 | C13: 30 | D13: 9 | E13: 32 | F13: 15 | G13: 17 | H13: 18 | I13: 5 | J13: 1900 | K13: 2400
A14: 50 | B14: 17 | C14: 19 | D14: 9 | E14: 32 | F14: 22 | G14: 14 | H14: 20 | I14: 8 | J14: 2100 | K14: 2600
A15: 54 | B15: 18 | C15: 35 | D15: 13 | E15: 23 | F15: 22 | G15: 20 | H15: 31 | I15: 13 | J15: 2300 | K15: 2800
... A18: 70 | B18: 34 | C18: 46 | D18: 13 | E18: 41 | F18: 29 | G18: 17 | H18: 49 | I18: 17 | J18: 2900 | K18: 3400

Sheet OPR_RIM
A1: OPR_RIM
A2: Part No | B2: 1
A3: Size | B3: CNC | C3: SPM | D3: CARVING | E3: EDM | F3: ENG | G3: VENT | H3: FID | I3: QC | J3: Min ID | K3: Max OD
A4: 9 | B4: 2 | C4: 7 | D4: 7 | E4: 10 | F4: 9 | G4: 9 | H4: 8 | I4: 4 | J4: 100 | K4: 600
A5: 15 | B5: 12 | C5: 7 | D5: 9 | E5: 9 | F5: 10 | G5: 12 | H5: 13 | I5: 4 | J5: 300 | K5: 800
A6: 17 | B6: 8 | C6: 18 | D6: 5 | E6: 6 | F6: 10 | G6: 5 | H6: 16 | I6: 2 | J6: 500 | K6: 1000
A7: 20 | B7: 8 | C7: 12 | D7: 12 | E7: 13 | F7: 14 | G7: 13 | H7: 17 | I7: 5 | J7: 700 | K7: 1200
A8: 25 | B8: 14 | C8: 21 | D8: 8 | E8: 21 | F8: 11 | G8: 13 | H8: 24 | I8: 5 | J8: 900 | K8: 1400
A9: 28 | B9: 10 | C9: 12 | D9: 13 | E9: 22 | F9: 15 | G9: 17 | H9: 21 | I9: 3 | J9: 1100 | K9: 1600
A10: 30 | B10: 16 | C10: 23 | D10: 15 | E10: 24 | F10: 8 | G10: 14 | H10: 24 | I10: 8 | J10: 1300 | K10: 1800
A11: 34 | B11: 18 | C11: 13 | D11: 7 | E11: 22 | F11: 17 | G11: 19 | H11: 22 | I11: 4 | J11: 1500 | K11: 2000
A12: 42 | B12: 17 | C12: 29 | D12: 14 | E12: 24 | F12: 22 | G12: 9 | H12: 19 | I12: 11 | J12: 1700 | K12: 2200
A13: 46 | B13: 22 | C13: 25 | D13: 17 | E13: 21 | F13: 10 | G13: 12 | H13: 30 | I13: 8 | J13: 1900 | K13: 2400
A14: 50 | B14: 22 | C14: 25 | D14: 9 | E14: 24 | F14: 21 | G14: 18 | H14: 20 | I14: 6 | J14: 2100 | K14: 2600
A15: 54 | B15: 18 | C15: 36 | D15: 14 | E15: 33 | F15: 12 | G15: 16 | H15: 36 | I15: 10 | J15: 2300 | K15: 2800
... A18: 70 | B18: 31 | C18: 43 | D18: 12 | E18: 23 | F18: 22 | G18: 17 | H18: 22 | I18: 17 | J18: 2900 | K18: 3400

Sheet OPR_BPR
A1: OPR_BPR
A2: Part No | B2: 2
A3: Size | B3: CNC | C3: SPM | D3: CARVING | E3: EDM | F3: ENG | G3: VENT | H3: FID | I3: QC | J3: Min ID | K3: Max OD
A4: 9 | B4: 5 | C4: 13 | D4: 9 | E4: 9 | F4: 4 | G4: 6 | H4: 8 | I4: 2 | J4: 100 | K4: 600
A5: 15 | B5: 6 | C5: 12 | D5: 8 | E5: 12 | F5: 12 | G5: 10 | H5: 12 | I5: 6 | J5: 300 | K5: 800
A6: 17 | B6: 10 | C6: 12 | D6: 7 | E6: 11 | F6: 4 | G6: 4 | H6: 17 | I6: 3 | J6: 500 | K6: 1000
A7: 20 | B7: 14 | C7: 15 | D7: 14 | E7: 18 | F7: 5 | G7: 14 | H7: 7 | I7: 7 | J7: 700 | K7: 1200
A8: 25 | B8: 7 | C8: 13 | D8: 13 | E8: 15 | F8: 13 | G8: 16 | H8: 19 | I8: 7 | J8: 900 | K8: 1400
A9: 28 | B9: 12 | C9: 20 | D9: 12 | E9: 22 | F9: 14 | G9: 17 | H9: 13 | I9: 6 | J9: 1100 | K9: 1600
A10: 30 | B10: 10 | C10: 27 | D10: 6 | E10: 18 | F10: 8 | G10: 17 | H10: 23 | I10: 8 | J10: 1300 | K10: 1800
A11: 34 | B11: 19 | C11: 19 | D11: 16 | E11: 22 | F11: 9 | G11: 19 | H11: 13 | I11: 6 | J11: 1500 | K11: 2000
A12: 42 | B12: 21 | C12: 26 | D12: 12 | E12: 20 | F12: 20 | G12: 18 | H12: 17 | I12: 10 | J12: 1700 | K12: 2200
A13: 46 | B13: 10 | C13: 21 | D13: 3 | E13: 23 | F13: 24 | G13: 17 | H13: 32 | I13: 8 | J13: 1900 | K13: 2400
A14: 50 | B14: 15 | C14: 38 | D14: 8 | E14: 29 | F14: 24 | G14: 15 | H14: 27 | I14: 13 | J14: 2100 | K14: 2600
A15: 54 | B15: 15 | C15: 29 | D15: 5 | E15: 25 | F15: 16 | G15: 24 | H15: 18 | I15: 7 | J15: 2300 | K15: 2800
... A18: 70 | B18: 15 | C18: 34 | D18: 9 | E18: 37 | F18: 15 | G18: 16 | H18: 28 | I18: 12 | J18: 2900 | K18: 3400

Sheet Settings
H2: Lunch/Tea Break hrs | I2: 0.8
A3: Shift | B3: Category | C3: Start | D3: End | E3: String | F3: Gen Qty | G3: Cont Qty | H3: Net Hrs | I3: Avl hrs
A4: Shift A | B4: General Workman | C4: 0.29166667 | D4: 0.625 | E4: 07:00 – 15:00 | F4: 40 | G4: 0 | H4: 8 | I4: 7.2 | J4: General Workman | K4: 21.6 | L4: BR1 | M4: 9
A5: Shift B | B5: General Workman | C5: 0.625 | D5: 0.95833333 | E5: 15:00 – 23:00 | F5: 40 | G5: 0 | H5: 8 | I5: 7.2 | J5: Contract Workman | K5: 22.4 | L5: BR2 | M5: 15
A6: Shift C | B6: General Workman | C6: 0.95833333 | D6: 0.29166667 | E6: 23:00 – 07:00 | F6: 40 | G6: 0 | H6: 8 | I6: 7.2 | L6: CR2 | M6: 17
A7: Shift S1 | B7: Contract Workman | C7: 0.33333333 | D7: 0.83333333 | E7: 08:00 – 20:00 | F7: 0 | G7: 60 | H7: 12 | I7: 11.2 | J7: Global Start | K7: 46113.292 | L7: CR3 | M7: 20
A8: Shift S2 | B8: Contract Workman | C8: 0.83333333 | D8: 0.33333333 | E8: 20:00 – 08:00 | F8: 0 | G8: 60 | H8: 12 | I8: 11.2 | L8: CR4 | M8: 25
L9: RIM | M9: 28
L10: BPR | M10: 30
M11: 34
M12: 42
M13: 46
M14: 50

Sheet Machine_List
A3: Operation | B3: Machine ID | C3: Next PM Date | D3: Dur | E3: Freq | F3: Status | G3: Worker Category | H3: Machine Min ID Limit | I3: Machine Max OD Limit (New) | J3: Compatible Size Range
A4: VTL | B4: VTL-MC-01 | C4: 46133 | D4: 6 | E4: 4 | F4: Active | G4: General Workman | H4: 100 | I4: 1600 | J4: 9, 15, 17, 20, 25, 28
A5: VTL | B5: VTL-MC-02 | C5: 46521 | D5: 6 | E5: 4 | F5: Active | G5: General Workman | H5: 600 | I5: 2500 | J5: 20, 25, 28, 30, 34, 42, 46
A6: VTL | B6: VTL-MC-03 | C6: 46174 | D6: 6 | E6: 4 | F6: Active | G6: General Workman | H6: 800 | I6: 3500 | J6: 25, 28, 30, 34, 42, 46, 50, 54, 57, 63, 70
A7: VTL | B7: VTL-MC-04 | C7: 46517 | D7: 6 | E7: 4 | F7: Active | G7: General Workman | H7: 1000 | I7: 4500 | J7: 28, 30, 34, 42, 46, 50, 54, 57, 63, 70
A8: SPM | B8: SPM-MC-01 | C8: 46285 | D8: 6 | E8: 4 | F8: Active | G8: General Workman | H8: 100 | I8: 3500 | J8: 9, 15, 17, 20, 25, 28, 30, 34, 42, 46, 50, 54, 57, 63, 70
A9: SPM | B9: SPM-MC-02 | C9: 46459 | D9: 6 | E9: 4 | F9: Active | G9: General Workman | H9: 100 | I9: 3500 | J9: 9, 15, 17, 20, 25, 28, 30, 34, 42, 46, 50, 54, 57, 63, 70
A10: SPM | B10: SPM-MC-03 | C10: 46104 | D10: 6 | E10: 4 | F10: Active | G10: General Workman | H10: 100 | I10: 4500 | J10: 9, 15, 17, 20, 25, 28, 30, 34, 42, 46, 50, 54, 57, 63, 70
A11: SPM | B11: SPM-MC-04 | C11: 46197 | D11: 6 | E11: 4 | F11: Active | G11: General Workman | H11: 100 | I11: 4500 | J11: 9, 15, 17, 20, 25, 28, 30, 34, 42, 46, 50, 54, 57, 63, 70
A12: SPM | B12: SPM-MC-05 | C12: 46271 | D12: 6 | E12: 4 | F12: Active | G12: General Workman | H12: 100 | I12: 4500 | J12: 9, 15, 17, 20, 25, 28, 30, 34, 42, 46, 50, 54, 57, 63, 70
A13: SPM | B13: SPM-MC-06 | C13: 46176 | D13: 6 | E13: 4 | F13: Active | G13: General Workman | H13: 100 | I13: 4500 | J13: 9, 15, 17, 20, 25, 28, 30, 34, 42, 46, 50, 54, 57, 63, 70
A14: CARVING | B14: CARVING-MC-01 | C14: 46418 | D14: 6 | E14: 4 | F14: Active | G14: General Workman | H14: 100 | I14: 4500 | J14: 9, 15, 17, 20, 25, 28, 30, 34, 42, 46, 50, 54, 57, 63, 70
A15: CARVING | B15: CARVING-MC-02 | C15: 46282 | D15: 6 | E15: 4 | F15: Active | G15: General Workman | H15: 100 | I15: 4500 | J15: 9, 15, 17, 20, 25, 28, 30, 34, 42, 46, 50, 54, 57, 63, 70
... A94: CNC | B94: CNC-MC-08 | C94: 46414 | D94: 6 | E94: 4 | F94: Active | G94: General Workman | H94: 100 | I94: 4500 | J94: All Sizes

Sheet Lists
A1: 9
A2: 15
A3: 17
A4: 20
A5: 25
A6: 28
A7: 30
A8: 34
A9: 42
A10: 46
A11: 50
A12: 54
... A15: 70

Sheet CNC_Plan
BX1: CNC — Monthly Load vs Capacity
BX2: Apr-26 | BY2: May-26 | BZ2: Jun-26 | CA2: Jul-26 | CB2: Aug-26 | CC2: Sep-26 | CD2: Oct-26 | CE2: Nov-26 | CF2: Dec-26 | CG2: Jan-27
A3: Job ID | B3: Size | C3: Type | D3: Parts | E3: Allocated Machine | F3: Worker | G3: PM Date | H3: PM Hrs | I3: Override | J3: Start Date | K3: Unit CT | L3: Total Load | M3: End Date | N3: Shift | Time | O3: Machine Helper (Pick Compatible) | P3: 46113 | Q3: 46114 | R3: 46115 | S3: 46116 | T3: 46118 | U3: 46119 | V3: 46120 | W3: 46121 | X3: 46122 | Y3: 46123 | Z3: 46124 | AA3: 46125 | AB3: 46126 | AC3: 46127 | AD3: 46128 | AE3: 46129 | AF3: 46130 | AG3: 46131 | AH3: 46132 | AI3: 46133 | AJ3: 46134 | AK3: 46135 | AL3: 46136 | AM3: 46137 | AN3: 46138 | AO3: 46139 | AP3: 46140 | AQ3: 46141 | AR3: 46142 | AS3: 46143 | AT3: 46144 | AU3: 46145 | AV3: 46146 | AW3: 46147 | AX3: 46148 | AY3: 46149 | AZ3: 46150 | BA3: 46151 | BB3: 46152 | BC3: 46153 | BD3: 46154 | BE3: 46155 | BF3: 46156 | BG3: 46157 | BH3: 46158 | BI3: 46159 | BJ3: 46160 | BK3: 46161 | BL3: 46162 | BM3: 46163 | BN3: 46164 | BO3: 46165 | BP3: 46166 | BQ3: 46167 | BR3: 46168 | BS3: 46169 | BT3: 46170 | BU3: 46171 | BV3: 46172 | BW3: Load (Hrs) | BX3: 0 | BY3: 0 | BZ3: 0 | CA3: 0 | CB3: 0 | CC3: 0 | CD3: 0 | CE3: 0 | CF3: 0 | CG3: 0
A4: =IF(Job_Master_Ring!$A4="","",Job_Master_Ring!$A4) | B4: =IF($A4="","",Job_Master_Ring!B4) | C4: =IF($A4="","",Job_Master_Ring!C4) | D4: =IF($A4="","",Job_Master_Ring!D4) | E4: =IF($A4="","",IF($I4<>"",$I4,IFERROR(INDEX(Machine_List!$B$87:$B$94,MATCH(1,(Machine_List!$H$87:$H$94<=IFERROR(VLOOKUP($B4,CHOOSE(MATCH($C4,Settings!$L$4:$L$10,0),OPR_BR1!$A$4:$K$18,OPR_BR2!$A$4:$K$18,OPR_CR2!$A$4:$K$18,OPR_CR3!$A$4:$K$18,OPR_CR4!$A$4:$K$18,OPR_RIM!$A$4:$K$18,OPR_BPR!$A$4:$K$18),10,0),0))*(Machine_List!$I$87:$I$94>=IFERROR(VLOOKUP($B4,CHOOSE(MATCH($C4,Settings!$L$4:$L$10,0),OPR_BR1!$A$4:$K$18,OPR_BR2!$A$4:$K$18,OPR_CR2!$A$4:$K$18,OPR_CR3!$A$4:$K$18,OPR_CR4!$A$4:$K$18,OPR_RIM!$A$4:$K$18,OPR_BPR!$A$4:$K$18),11,0),9999)),0)),"NO COMPATIBLE MACHINE"))) | F4: =IF($E4="","",IFERROR(VLOOKUP($E4,Machine_List!$B:$G,6,0),"")) | G4: =IF($E4="","",IFERROR(VLOOKUP($E4,Machine_List!$B:$C,2,0),"")) | H4: =IF($E4="","",IFERROR(VLOOKUP($E4,Machine_List!$B:$D,3,0),"")) | J4: =IF($A4="","",IF($I4<>"",$I4,MAX(GlobalStartDate,IFERROR(LOOKUP(2,1/($E$3:INDIRECT("E"&(ROW()-1))=$E4),$M$3:INDIRECT("M"&(ROW()-1))),GlobalStartDate)))) | K4: =IF($A4="","",IFERROR(VLOOKUP(B4,CHOOSE(MATCH($C4,Settings!$L$4:$L$10,0),OPR_BR1!$A$4:$I$18,OPR_BR2!$A$4:$I$18,OPR_CR2!$A$4:$I$18,OPR_CR3!$A$4:$I$18,OPR_CR4!$A$4:$I$18,OPR_RIM!$A$4:$I$18,OPR_BPR!$A$4:$I$18),2,0),0)) | L4: =IF($A4="","",K4*D4) | M4: =IF($A4="","",IF(AND(ISNUMBER(G4),G4>=J4,G4<=(J4+(L4/(IF(F4="Contract Workman",Settings!$K$5,Settings!$K$4))))),J4+(L4/(IF(F4="Contract Workman",Settings!$K$5,Settings!$K$4)))+(H4/(IF(F4="Contract Workman",Settings!$K$5,Settings!$K$4))),J4+(L4/(IF(F4="Contract Workman",Settings!$K$5,Settings!$K$4))))) | N4: =IF($A4="","",IF(F4="Contract Workman",IF(AND(MOD(M4,1)>=8/24,MOD(M4,1)<20/24),"Shift S1","Shift S2"),IF(AND(MOD(M4,1)>=7/24,MOD(M4,1)<15/24),"Shift A",IF(AND(MOD(M4,1)>=15/24,MOD(M4,1)<23/24),"Shift B","Shift C")))) | O4: =IF(B4="","",IF(IFERROR(ISNUMBER(SEARCH(TEXT(B4,"0"),VLOOKUP(E4,Machine_List!$B:$J,9,0))),FALSE),"✅ "&E4,"❌ ?")) | P4: =IF(AND($A4<>"",P$3>=$J4,P$3<=$M4),1,"") | Q4: =IF(AND($A4<>"",Q$3>=$J4,Q$3<=$M4),1,"") | R4: =IF(AND($A4<>"",R$3>=$J4,R$3<=$M4),1,"") | S4: =IF(AND($A4<>"",S$3>=$J4,S$3<=$M4),1,"") | T4: =IF(AND($A4<>"",T$3>=$J4,T$3<=$M4),1,"") | U4: =IF(AND($A4<>"",U$3>=$J4,U$3<=$M4),1,"") | V4: =IF(AND($A4<>"",V$3>=$J4,V$3<=$M4),1,"") | W4: =IF(AND($A4<>"",W$3>=$J4,W$3<=$M4),1,"") | ... BV4: =IF(AND($A4<>"",BV$3>=$J4,BV$3<=$M4),1,"") | BW4: Capacity (Hrs) | BX4: 5184 | BY4: 5356.8 | BZ4: 5184 | CA4: 5356.8 | CB4: 5356.8 | CC4: 5184 | CD4: 5356.8 | CE4: 5184 | CF4: 5356.8 | CG4: 5356.8
A5: =IF(Job_Master_Ring!$A5="","",Job_Master_Ring!$A5) | B5: =IF($A5="","",Job_Master_Ring!B5) | C5: =IF($A5="","",Job_Master_Ring!C5) | D5: =IF($A5="","",Job_Master_Ring!D5) | E5: =IF($A5="","",IF($I5<>"",$I5,IFERROR(INDEX(Machine_List!$B$87:$B$94,MATCH(1,(Machine_List!$H$87:$H$94<=IFERROR(VLOOKUP($B5,CHOOSE(MATCH($C5,Settings!$L$4:$L$10,0),OPR_BR1!$A$4:$K$18,OPR_BR2!$A$4:$K$18,OPR_CR2!$A$4:$K$18,OPR_CR3!$A$4:$K$18,OPR_CR4!$A$4:$K$18,OPR_RIM!$A$4:$K$18,OPR_BPR!$A$4:$K$18),10,0),0))*(Machine_List!$I$87:$I$94>=IFERROR(VLOOKUP($B5,CHOOSE(MATCH($C5,Settings!$L$4:$L$10,0),OPR_BR1!$A$4:$K$18,OPR_BR2!$A$4:$K$18,OPR_CR2!$A$4:$K$18,OPR_CR3!$A$4:$K$18,OPR_CR4!$A$4:$K$18,OPR_RIM!$A$4:$K$18,OPR_BPR!$A$4:$K$18),11,0),9999)),0)),"NO COMPATIBLE MACHINE"))) | F5: =IF($E5="","",IFERROR(VLOOKUP($E5,Machine_List!$B:$G,6,0),"")) | G5: =IF($E5="","",IFERROR(VLOOKUP($E5,Machine_List!$B:$C,2,0),"")) | H5: =IF($E5="","",IFERROR(VLOOKUP($E5,Machine_List!$B:$D,3,0),"")) | J5: =IF($A5="","",IF($I5<>"",$I5,MAX(GlobalStartDate,IFERROR(LOOKUP(2,1/($E$3:INDIRECT("E"&(ROW()-1))=$E5),$M$3:INDIRECT("M"&(ROW()-1))),GlobalStartDate)))) | K5: =IF($A5="","",IFERROR(VLOOKUP(B5,CHOOSE(MATCH($C5,Settings!$L$4:$L$10,0),OPR_BR1!$A$4:$I$18,OPR_BR2!$A$4:$I$18,OPR_CR2!$A$4:$I$18,OPR_CR3!$A$4:$I$18,OPR_CR4!$A$4:$I$18,OPR_RIM!$A$4:$I$18,OPR_BPR!$A$4:$I$18),2,0),0)) | L5: =IF($A5="","",K5*D5) | M5: =IF($A5="","",IF(AND(ISNUMBER(G5),G5>=J5,G5<=(J5+(L5/(IF(F5="Contract Workman",Settings!$K$5,Settings!$K$4))))),J5+(L5/(IF(F5="Contract Workman",Settings!$K$5,Settings!$K$4)))+(H5/(IF(F5="Contract Workman",Settings!$K$5,Settings!$K$4))),J5+(L5/(IF(F5="Contract Workman",Settings!$K$5,Settings!$K$4))))) | N5: =IF($A5="","",IF(F5="Contract Workman",IF(AND(MOD(M5,1)>=8/24,MOD(M5,1)<20/24),"Shift S1","Shift S2"),IF(AND(MOD(M5,1)>=7/24,MOD(M5,1)<15/24),"Shift A",IF(AND(MOD(M5,1)>=15/24,MOD(M5,1)<23/24),"Shift B","Shift C")))) | O5: =IF(B5="","",IF(IFERROR(ISNUMBER(SEARCH(TEXT(B5,"0"),VLOOKUP(E5,Machine_List!$B:$J,9,0))),FALSE),"✅ "&E5,"❌ ?")) | P5: =IF(AND($A5<>"",P$3>=$J5,P$3<=$M5),1,"") | Q5: =IF(AND($A5<>"",Q$3>=$J5,Q$3<=$M5),1,"") | R5: =IF(AND($A5<>"",R$3>=$J5,R$3<=$M5),1,"") | S5: =IF(AND($A5<>"",S$3>=$J5,S$3<=$M5),1,"") | T5: =IF(AND($A5<>"",T$3>=$J5,T$3<=$M5),1,"") | U5: =IF(AND($A5<>"",U$3>=$J5,U$3<=$M5),1,"") | V5: =IF(AND($A5<>"",V$3>=$J5,V$3<=$M5),1,"") | W5: =IF(AND($A5<>"",W$3>=$J5,W$3<=$M5),1,"") | ... BV5: =IF(AND($A5<>"",BV$3>=$J5,BV$3<=$M5),1,"")
A6: =IF(Job_Master_Ring!$A6="","",Job_Master_Ring!$A6) | B6: =IF($A6="","",Job_Master_Ring!B6) | C6: =IF($A6="","",Job_Master_Ring!C6) | D6: =IF($A6="","",Job_Master_Ring!D6) | E6: =IF($A6="","",IF($I6<>"",$I6,IFERROR(INDEX(Machine_List!$B$87:$B$94,MATCH(1,(Machine_List!$H$87:$H$94<=IFERROR(VLOOKUP($B6,CHOOSE(MATCH($C6,Settings!$L$4:$L$10,0),OPR_BR1!$A$4:$K$18,OPR_BR2!$A$4:$K$18,OPR_CR2!$A$4:$K$18,OPR_CR3!$A$4:$K$18,OPR_CR4!$A$4:$K$18,OPR_RIM!$A$4:$K$18,OPR_BPR!$A$4:$K$18),10,0),0))*(Machine_List!$I$87:$I$94>=IFERROR(VLOOKUP($B6,CHOOSE(MATCH($C6,Settings!$L$4:$L$10,0),OPR_BR1!$A$4:$K$18,OPR_BR2!$A$4:$K$18,OPR_CR2!$A$4:$K$18,OPR_CR3!$A$4:$K$18,OPR_CR4!$A$4:$K$18,OPR_RIM!$A$4:$K$18,OPR_BPR!$A$4:$K$18),11,0),9999)),0)),"NO COMPATIBLE MACHINE"))) | F6: =IF($E6="","",IFERROR(VLOOKUP($E6,Machine_List!$B:$G,6,0),"")) | G6: =IF($E6="","",IFERROR(VLOOKUP($E6,Machine_List!$B:$C,2,0),"")) | H6: =IF($E6="","",IFERROR(VLOOKUP($E6,Machine_List!$B:$D,3,0),"")) | J6: =IF($A6="","",IF($I6<>"",$I6,MAX(GlobalStartDate,IFERROR(LOOKUP(2,1/($E$3:INDIRECT("E"&(ROW()-1))=$E6),$M$3:INDIRECT("M"&(ROW()-1))),GlobalStartDate)))) | K6: =IF($A6="","",IFERROR(VLOOKUP(B6,CHOOSE(MATCH($C6,Settings!$L$4:$L$10,0),OPR_BR1!$A$4:$I$18,OPR_BR2!$A$4:$I$18,OPR_CR2!$A$4:$I$18,OPR_CR3!$A$4:$I$18,OPR_CR4!$A$4:$I$18,OPR_RIM!$A$4:$I$18,OPR_BPR!$A$4:$I$18),2,0),0)) | L6: =IF($A6="","",K6*D6) | M6: =IF($A6="","",IF(AND(ISNUMBER(G6),G6>=J6,G6<=(J6+(L6/(IF(F6="Contract Workman",Settings!$K$5,Settings!$K$4))))),J6+(L6/(IF(F6="Contract Workman",Settings!$K$5,Settings!$K$4)))+(H6/(IF(F6="Contract Workman",Settings!$K$5,Settings!$K$4))),J6+(L6/(IF(F6="Contract Workman",Settings!$K$5,Settings!$K$4))))) | N6: =IF($A6="","",IF(F6="Contract Workman",IF(AND(MOD(M6,1)>=8/24,MOD(M6,1)<20/24),"Shift S1","Shift S2"),IF(AND(MOD(M6,1)>=7/24,MOD(M6,1)<15/24),"Shift A",IF(AND(MOD(M6,1)>=15/24,MOD(M6,1)<23/24),"Shift B","Shift C")))) | O6: =IF(B6="","",IF(IFERROR(ISNUMBER(SEARCH(TEXT(B6,"0"),VLOOKUP(E6,Machine_List!$B:$J,9,0))),FALSE),"✅ "&E6,"❌ ?")) | P6: =IF(AND($A6<>"",P$3>=$J6,P$3<=$M6),1,"") | Q6: =IF(AND($A6<>"",Q$3>=$J6,Q$3<=$M6),1,"") | R6: =IF(AND($A6<>"",R$3>=$J6,R$3<=$M6),1,"") | S6: =IF(AND($A6<>"",S$3>=$J6,S$3<=$M6),1,"") | T6: =IF(AND($A6<>"",T$3>=$J6,T$3<=$M6),1,"") | U6: =IF(AND($A6<>"",U$3>=$J6,U$3<=$M6),1,"") | V6: =IF(AND($A6<>"",V$3>=$J6,V$3<=$M6),1,"") | W6: =IF(AND($A6<>"",W$3>=$J6,W$3<=$M6),1,"") | ... BV6: =IF(AND($A6<>"",BV$3>=$J6,BV$3<=$M6),1,"")
A7: =IF(Job_Master_Ring!$A7="","",Job_Master_Ring!$A7) | B7: =IF($A7="","",Job_Master_Ring!B7) | C7: =IF($A7="","",Job_Master_Ring!C7) | D7: =IF($A7="","",Job_Master_Ring!D7) | E7: =IF($A7="","",IF($I7<>"",$I7,IFERROR(INDEX(Machine_List!$B$87:$B$94,MATCH(1,(Machine_List!$H$87:$H$94<=IFERROR(VLOOKUP($B7,CHOOSE(MATCH($C7,Settings!$L$4:$L$10,0),OPR_BR1!$A$4:$K$18,OPR_BR2!$A$4:$K$18,OPR_CR2!$A$4:$K$18,OPR_CR3!$A$4:$K$18,OPR_CR4!$A$4:$K$18,OPR_RIM!$A$4:$K$18,OPR_BPR!$A$4:$K$18),10,0),0))*(Machine_List!$I$87:$I$94>=IFERROR(VLOOKUP($B7,CHOOSE(MATCH($C7,Settings!$L$4:$L$10,0),OPR_BR1!$A$4:$K$18,OPR_BR2!$A$4:$K$18,OPR_CR2!$A$4:$K$18,OPR_CR3!$A$4:$K$18,OPR_CR4!$A$4:$K$18,OPR_RIM!$A$4:$K$18,OPR_BPR!$A$4:$K$18),11,0),9999)),0)),"NO COMPATIBLE MACHINE"))) | F7: =IF($E7="","",IFERROR(VLOOKUP($E7,Machine_List!$B:$G,6,0),"")) | G7: =IF($E7="","",IFERROR(VLOOKUP($E7,Machine_List!$B:$C,2,0),"")) | H7: =IF($E7="","",IFERROR(VLOOKUP($E7,Machine_List!$B:$D,3,0),"")) | J7: =IF($A7="","",IF($I7<>"",$I7,MAX(GlobalStartDate,IFERROR(LOOKUP(2,1/($E$3:INDIRECT("E"&(ROW()-1))=$E7),$M$3:INDIRECT("M"&(ROW()-1))),GlobalStartDate)))) | K7: =IF($A7="","",IFERROR(VLOOKUP(B7,CHOOSE(MATCH($C7,Settings!$L$4:$L$10,0),OPR_BR1!$A$4:$I$18,OPR_BR2!$A$4:$I$18,OPR_CR2!$A$4:$I$18,OPR_CR3!$A$4:$I$18,OPR_CR4!$A$4:$I$18,OPR_RIM!$A$4:$I$18,OPR_BPR!$A$4:$I$18),2,0),0)) | L7: =IF($A7="","",K7*D7) | M7: =IF($A7="","",IF(AND(ISNUMBER(G7),G7>=J7,G7<=(J7+(L7/(IF(F7="Contract Workman",Settings!$K$5,Settings!$K$4))))),J7+(L7/(IF(F7="Contract Workman",Settings!$K$5,Settings!$K$4)))+(H7/(IF(F7="Contract Workman",Settings!$K$5,Settings!$K$4))),J7+(L7/(IF(F7="Contract Workman",Settings!$K$5,Settings!$K$4))))) | N7: =IF($A7="","",IF(F7="Contract Workman",IF(AND(MOD(M7,1)>=8/24,MOD(M7,1)<20/24),"Shift S1","Shift S2"),IF(AND(MOD(M7,1)>=7/24,MOD(M7,1)<15/24),"Shift A",IF(AND(MOD(M7,1)>=15/24,MOD(M7,1)<23/24),"Shift B","Shift C")))) | O7: =IF(B7="","",IF(IFERROR(ISNUMBER(SEARCH(TEXT(B7,"0"),VLOOKUP(E7,Machine_List!$B:$J,9,0))),FALSE),"✅ "&E7,"❌ ?")) | P7: =IF(AND($A7<>"",P$3>=$J7,P$3<=$M7),1,"") | Q7: =IF(AND($A7<>"",Q$3>=$J7,Q$3<=$M7),1,"") | R7: =IF(AND($A7<>"",R$3>=$J7,R$3<=$M7),1,"") | S7: =IF(AND($A7<>"",S$3>=$J7,S$3<=$M7),1,"") | T7: =IF(AND($A7<>"",T$3>=$J7,T$3<=$M7),1,"") | U7: =IF(AND($A7<>"",U$3>=$J7,U$3<=$M7),1,"") | V7: =IF(AND($A7<>"",V$3>=$J7,V$3<=$M7),1,"") | W7: =IF(AND($A7<>"",W$3>=$J7,W$3<=$M7),1,"") | ... BV7: =IF(AND($A7<>"",BV$3>=$J7,BV$3<=$M7),1,"")
A8: =IF(Job_Master_Ring!$A8="","",Job_Master_Ring!$A8) | B8: =IF($A8="","",Job_Master_Ring!B8) | C8: =IF($A8="","",Job_Master_Ring!C8) | D8: =IF($A8="","",Job_Master_Ring!D8) | E8: =IF($A8="","",IF($I8<>"",$I8,IFERROR(INDEX(Machine_List!$B$87:$B$94,MATCH(1,(Machine_List!$H$87:$H$94<=IFERROR(VLOOKUP($B8,CHOOSE(MATCH($C8,Settings!$L$4:$L$10,0),OPR_BR1!$A$4:$K$18,OPR_BR2!$A$4:$K$18,OPR_CR2!$A$4:$K$18,OPR_CR3!$A$4:$K$18,OPR_CR4!$A$4:$K$18,OPR_RIM!$A$4:$K$18,OPR_BPR!$A$4:$K$18),10,0),0))*(Machine_List!$I$87:$I$94>=IFERROR(VLOOKUP($B8,CHOOSE(MATCH($C8,Settings!$L$4:$L$10,0),OPR_BR1!$A$4:$K$18,OPR_BR2!$A$4:$K$18,OPR_CR2!$A$4:$K$18,OPR_CR3!$A$4:$K$18,OPR_CR4!$A$4:$K$18,OPR_RIM!$A$4:$K$18,OPR_BPR!$A$4:$K$18),11,0),9999)),0)),"NO COMPATIBLE MACHINE"))) | F8: =IF($E8="","",IFERROR(VLOOKUP($E8,Machine_List!$B:$G,6,0),"")) | G8: =IF($E8="","",IFERROR(VLOOKUP($E8,Machine_List!$B:$C,2,0),"")) | H8: =IF($E8="","",IFERROR(VLOOKUP($E8,Machine_List!$B:$D,3,0),"")) | J8: =IF($A8="","",IF($I8<>"",$I8,MAX(GlobalStartDate,IFERROR(LOOKUP(2,1/($E$3:INDIRECT("E"&(ROW()-1))=$E8),$M$3:INDIRECT("M"&(ROW()-1))),GlobalStartDate)))) | K8: =IF($A8="","",IFERROR(VLOOKUP(B8,CHOOSE(MATCH($C8,Settings!$L$4:$L$10,0),OPR_BR1!$A$4:$I$18,OPR_BR2!$A$4:$I$18,OPR_CR2!$A$4:$I$18,OPR_CR3!$A$4:$I$18,OPR_CR4!$A$4:$I$18,OPR_RIM!$A$4:$I$18,OPR_BPR!$A$4:$I$18),2,0),0)) | L8: =IF($A8="","",K8*D8) | M8: =IF($A8="","",IF(AND(ISNUMBER(G8),G8>=J8,G8<=(J8+(L8/(IF(F8="Contract Workman",Settings!$K$5,Settings!$K$4))))),J8+(L8/(IF(F8="Contract Workman",Settings!$K$5,Settings!$K$4)))+(H8/(IF(F8="Contract Workman",Settings!$K$5,Settings!$K$4))),J8+(L8/(IF(F8="Contract Workman",Settings!$K$5,Settings!$K$4))))) | N8: =IF($A8="","",IF(F8="Contract Workman",IF(AND(MOD(M8,1)>=8/24,MOD(M8,1)<20/24),"Shift S1","Shift S2"),IF(AND(MOD(M8,1)>=7/24,MOD(M8,1)<15/24),"Shift A",IF(AND(MOD(M8,1)>=15/24,MOD(M8,1)<23/24),"Shift B","Shift C")))) | O8: =IF(B8="","",IF(IFERROR(ISNUMBER(SEARCH(TEXT(B8,"0"),VLOOKUP(E8,Machine_List!$B:$J,9,0))),FALSE),"✅ "&E8,"❌ ?")) | P8: =IF(AND($A8<>"",P$3>=$J8,P$3<=$M8),1,"") | Q8: =IF(AND($A8<>"",Q$3>=$J8,Q$3<=$M8),1,"") | R8: =IF(AND($A8<>"",R$3>=$J8,R$3<=$M8),1,"") | S8: =IF(AND($A8<>"",S$3>=$J8,S$3<=$M8),1,"") | T8: =IF(AND($A8<>"",T$3>=$J8,T$3<=$M8),1,"") | U8: =IF(AND($A8<>"",U$3>=$J8,U$3<=$M8),1,"") | V8: =IF(AND($A8<>"",V$3>=$J8,V$3<=$M8),1,"") | W8: =IF(AND($A8<>"",W$3>=$J8,W$3<=$M8),1,"") | ... BV8: =IF(AND($A8<>"",BV$3>=$J8,BV$3<=$M8),1,"")
A9: =IF(Job_Master_Ring!$A9="","",Job_Master_Ring!$A9) | B9: =IF($A9="","",Job_Master_Ring!B9) | C9: =IF($A9="","",Job_Master_Ring!C9) | D9: =IF($A9="","",Job_Master_Ring!D9) | E9: =IF($A9="","",IF($I9<>"",$I9,IFERROR(INDEX(Machine_List!$B$87:$B$94,MATCH(1,(Machine_List!$H$87:$H$94<=IFERROR(VLOOKUP($B9,CHOOSE(MATCH($C9,Settings!$L$4:$L$10,0),OPR_BR1!$A$4:$K$18,OPR_BR2!$A$4:$K$18,OPR_CR2!$A$4:$K$18,OPR_CR3!$A$4:$K$18,OPR_CR4!$A$4:$K$18,OPR_RIM!$A$4:$K$18,OPR_BPR!$A$4:$K$18),10,0),0))*(Machine_List!$I$87:$I$94>=IFERROR(VLOOKUP($B9,CHOOSE(MATCH($C9,Settings!$L$4:$L$10,0),OPR_BR1!$A$4:$K$18,OPR_BR2!$A$4:$K$18,OPR_CR2!$A$4:$K$18,OPR_CR3!$A$4:$K$18,OPR_CR4!$A$4:$K$18,OPR_RIM!$A$4:$K$18,OPR_BPR!$A$4:$K$18),11,0),9999)),0)),"NO COMPATIBLE MACHINE"))) | F9: =IF($E9="","",IFERROR(VLOOKUP($E9,Machine_List!$B:$G,6,0),"")) | G9: =IF($E9="","",IFERROR(VLOOKUP($E9,Machine_List!$B:$C,2,0),"")) | H9: =IF($E9="","",IFERROR(VLOOKUP($E9,Machine_List!$B:$D,3,0),"")) | J9: =IF($A9="","",IF($I9<>"",$I9,MAX(GlobalStartDate,IFERROR(LOOKUP(2,1/($E$3:INDIRECT("E"&(ROW()-1))=$E9),$M$3:INDIRECT("M"&(ROW()-1))),GlobalStartDate)))) | K9: =IF($A9="","",IFERROR(VLOOKUP(B9,CHOOSE(MATCH($C9,Settings!$L$4:$L$10,0),OPR_BR1!$A$4:$I$18,OPR_BR2!$A$4:$I$18,OPR_CR2!$A$4:$I$18,OPR_CR3!$A$4:$I$18,OPR_CR4!$A$4:$I$18,OPR_RIM!$A$4:$I$18,OPR_BPR!$A$4:$I$18),2,0),0)) | L9: =IF($A9="","",K9*D9) | M9: =IF($A9="","",IF(AND(ISNUMBER(G9),G9>=J9,G9<=(J9+(L9/(IF(F9="Contract Workman",Settings!$K$5,Settings!$K$4))))),J9+(L9/(IF(F9="Contract Workman",Settings!$K$5,Settings!$K$4)))+(H9/(IF(F9="Contract Workman",Settings!$K$5,Settings!$K$4))),J9+(L9/(IF(F9="Contract Workman",Settings!$K$5,Settings!$K$4))))) | N9: =IF($A9="","",IF(F9="Contract Workman",IF(AND(MOD(M9,1)>=8/24,MOD(M9,1)<20/24),"Shift S1","Shift S2"),IF(AND(MOD(M9,1)>=7/24,MOD(M9,1)<15/24),"Shift A",IF(AND(MOD(M9,1)>=15/24,MOD(M9,1)<23/24),"Shift B","Shift C")))) | O9: =IF(B9="","",IF(IFERROR(ISNUMBER(SEARCH(TEXT(B9,"0"),VLOOKUP(E9,Machine_List!$B:$J,9,0))),FALSE),"✅ "&E9,"❌ ?")) | P9: =IF(AND($A9<>"",P$3>=$J9,P$3<=$M9),1,"") | Q9: =IF(AND($A9<>"",Q$3>=$J9,Q$3<=$M9),1,"") | R9: =IF(AND($A9<>"",R$3>=$J9,R$3<=$M9),1,"") | S9: =IF(AND($A9<>"",S$3>=$J9,S$3<=$M9),1,"") | T9: =IF(AND($A9<>"",T$3>=$J9,T$3<=$M9),1,"") | U9: =IF(AND($A9<>"",U$3>=$J9,U$3<=$M9),1,"") | V9: =IF(AND($A9<>"",V$3>=$J9,V$3<=$M9),1,"") | W9: =IF(AND($A9<>"",W$3>=$J9,W$3<=$M9),1,"") | ... BV9: =IF(AND($A9<>"",BV$3>=$J9,BV$3<=$M9),1,"")
A10: =IF(Job_Master_Ring!$A10="","",Job_Master_Ring!$A10) | B10: =IF($A10="","",Job_Master_Ring!B10) | C10: =IF($A10="","",Job_Master_Ring!C10) | D10: =IF($A10="","",Job_Master_Ring!D10) | E10: =IF($A10="","",IF($I10<>"",$I10,IFERROR(INDEX(Machine_List!$B$87:$B$94,MATCH(1,(Machine_List!$H$87:$H$94<=IFERROR(VLOOKUP($B10,CHOOSE(MATCH($C10,Settings!$L$4:$L$10,0),OPR_BR1!$A$4:$K$18,OPR_BR2!$A$4:$K$18,OPR_CR2!$A$4:$K$18,OPR_CR3!$A$4:$K$18,OPR_CR4!$A$4:$K$18,OPR_RIM!$A$4:$K$18,OPR_BPR!$A$4:$K$18),10,0),0))*(Machine_List!$I$87:$I$94>=IFERROR(VLOOKUP($B10,CHOOSE(MATCH($C10,Settings!$L$4:$L$10,0),OPR_BR1!$A$4:$K$18,OPR_BR2!$A$4:$K$18,OPR_CR2!$A$4:$K$18,OPR_CR3!$A$4:$K$18,OPR_CR4!$A$4:$K$18,OPR_RIM!$A$4:$K$18,OPR_BPR!$A$4:$K$18),11,0),9999)),0)),"NO COMPATIBLE MACHINE"))) | F10: =IF($E10="","",IFERROR(VLOOKUP($E10,Machine_List!$B:$G,6,0),"")) | G10: =IF($E10="","",IFERROR(VLOOKUP($E10,Machine_List!$B:$C,2,0),"")) | H10: =IF($E10="","",IFERROR(VLOOKUP($E10,Machine_List!$B:$D,3,0),"")) | J10: =IF($A10="","",IF($I10<>"",$I10,MAX(GlobalStartDate,IFERROR(LOOKUP(2,1/($E$3:INDIRECT("E"&(ROW()-1))=$E10),$M$3:INDIRECT("M"&(ROW()-1))),GlobalStartDate)))) | K10: =IF($A10="","",IFERROR(VLOOKUP(B10,CHOOSE(MATCH($C10,Settings!$L$4:$L$10,0),OPR_BR1!$A$4:$I$18,OPR_BR2!$A$4:$I$18,OPR_CR2!$A$4:$I$18,OPR_CR3!$A$4:$I$18,OPR_CR4!$A$4:$I$18,OPR_RIM!$A$4:$I$18,OPR_BPR!$A$4:$I$18),2,0),0)) | L10: =IF($A10="","",K10*D10) | M10: =IF($A10="","",IF(AND(ISNUMBER(G10),G10>=J10,G10<=(J10+(L10/(IF(F10="Contract Workman",Settings!$K$5,Settings!$K$4))))),J10+(L10/(IF(F10="Contract Workman",Settings!$K$5,Settings!$K$4)))+(H10/(IF(F10="Contract Workman",Settings!$K$5,Settings!$K$4))),J10+(L10/(IF(F10="Contract Workman",Settings!$K$5,Settings!$K$4))))) | N10: =IF($A10="","",IF(F10="Contract Workman",IF(AND(MOD(M10,1)>=8/24,MOD(M10,1)<20/24),"Shift S1","Shift S2"),IF(AND(MOD(M10,1)>=7/24,MOD(M10,1)<15/24),"Shift A",IF(AND(MOD(M10,1)>=15/24,MOD(M10,1)<23/24),"Shift B","Shift C")))) | O10: =IF(B10="","",IF(IFERROR(ISNUMBER(SEARCH(TEXT(B10,"0"),VLOOKUP(E10,Machine_List!$B:$J,9,0))),FALSE),"✅ "&E10,"❌ ?")) | P10: =IF(AND($A10<>"",P$3>=$J10,P$3<=$M10),1,"") | Q10: =IF(AND($A10<>"",Q$3>=$J10,Q$3<=$M10),1,"") | R10: =IF(AND($A10<>"",R$3>=$J10,R$3<=$M10),1,"") | S10: =IF(AND($A10<>"",S$3>=$J10,S$3<=$M10),1,"") | T10: =IF(AND($A10<>"",T$3>=$J10,T$3<=$M10),1,"") | U10: =IF(AND($A10<>"",U$3>=$J10,U$3<=$M10),1,"") | V10: =IF(AND($A10<>"",V$3>=$J10,V$3<=$M10),1,"") | W10: =IF(AND($A10<>"",W$3>=$J10,W$3<=$M10),1,"") | ... BV10: =IF(AND($A10<>"",BV$3>=$J10,BV$3<=$M10),1,"")
A11: =IF(Job_Master_Ring!$A11="","",Job_Master_Ring!$A11) | B11: =IF($A11="","",Job_Master_Ring!B11) | C11: =IF($A11="","",Job_Master_Ring!C11) | D11: =IF($A11="","",Job_Master_Ring!D11) | E11: =IF($A11="","",IF($I11<>"",$I11,IFERROR(INDEX(Machine_List!$B$87:$B$94,MATCH(1,(Machine_List!$H$87:$H$94<=IFERROR(VLOOKUP($B11,CHOOSE(MATCH($C11,Settings!$L$4:$L$10,0),OPR_BR1!$A$4:$K$18,OPR_BR2!$A$4:$K$18,OPR_CR2!$A$4:$K$18,OPR_CR3!$A$4:$K$18,OPR_CR4!$A$4:$K$18,OPR_RIM!$A$4:$K$18,OPR_BPR!$A$4:$K$18),10,0),0))*(Machine_List!$I$87:$I$94>=IFERROR(VLOOKUP($B11,CHOOSE(MATCH($C11,Settings!$L$4:$L$10,0),OPR_BR1!$A$4:$K$18,OPR_BR2!$A$4:$K$18,OPR_CR2!$A$4:$K$18,OPR_CR3!$A$4:$K$18,OPR_CR4!$A$4:$K$18,OPR_RIM!$A$4:$K$18,OPR_BPR!$A$4:$K$18),11,0),9999)),0)),"NO COMPATIBLE MACHINE"))) | F11: =IF($E11="","",IFERROR(VLOOKUP($E11,Machine_List!$B:$G,6,0),"")) | G11: =IF($E11="","",IFERROR(VLOOKUP($E11,Machine_List!$B:$C,2,0),"")) | H11: =IF($E11="","",IFERROR(VLOOKUP($E11,Machine_List!$B:$D,3,0),"")) | J11: =IF($A11="","",IF($I11<>"",$I11,MAX(GlobalStartDate,IFERROR(LOOKUP(2,1/($E$3:INDIRECT("E"&(ROW()-1))=$E11),$M$3:INDIRECT("M"&(ROW()-1))),GlobalStartDate)))) | K11: =IF($A11="","",IFERROR(VLOOKUP(B11,CHOOSE(MATCH($C11,Settings!$L$4:$L$10,0),OPR_BR1!$A$4:$I$18,OPR_BR2!$A$4:$I$18,OPR_CR2!$A$4:$I$18,OPR_CR3!$A$4:$I$18,OPR_CR4!$A$4:$I$18,OPR_RIM!$A$4:$I$18,OPR_BPR!$A$4:$I$18),2,0),0)) | L11: =IF($A11="","",K11*D11) | M11: =IF($A11="","",IF(AND(ISNUMBER(G11),G11>=J11,G11<=(J11+(L11/(IF(F11="Contract Workman",Settings!$K$5,Settings!$K$4))))),J11+(L11/(IF(F11="Contract Workman",Settings!$K$5,Settings!$K$4)))+(H11/(IF(F11="Contract Workman",Settings!$K$5,Settings!$K$4))),J11+(L11/(IF(F11="Contract Workman",Settings!$K$5,Settings!$K$4))))) | N11: =IF($A11="","",IF(F11="Contract Workman",IF(AND(MOD(M11,1)>=8/24,MOD(M11,1)<20/24),"Shift S1","Shift S2"),IF(AND(MOD(M11,1)>=7/24,MOD(M11,1)<15/24),"Shift A",IF(AND(MOD(M11,1)>=15/24,MOD(M11,1)<23/24),"Shift B","Shift C")))) | O11: =IF(B11="","",IF(IFERROR(ISNUMBER(SEARCH(TEXT(B11,"0"),VLOOKUP(E11,Machine_List!$B:$J,9,0))),FALSE),"✅ "&E11,"❌ ?")) | P11: =IF(AND($A11<>"",P$3>=$J11,P$3<=$M11),1,"") | Q11: =IF(AND($A11<>"",Q$3>=$J11,Q$3<=$M11),1,"") | R11: =IF(AND($A11<>"",R$3>=$J11,R$3<=$M11),1,"") | S11: =IF(AND($A11<>"",S$3>=$J11,S$3<=$M11),1,"") | T11: =IF(AND($A11<>"",T$3>=$J11,T$3<=$M11),1,"") | U11: =IF(AND($A11<>"",U$3>=$J11,U$3<=$M11),1,"") | V11: =IF(AND($A11<>"",V$3>=$J11,V$3<=$M11),1,"") | W11: =IF(AND($A11<>"",W$3>=$J11,W$3<=$M11),1,"") | ... BV11: =IF(AND($A11<>"",BV$3>=$J11,BV$3<=$M11),1,"")
A12: =IF(Job_Master_Ring!$A12="","",Job_Master_Ring!$A12) | B12: =IF($A12="","",Job_Master_Ring!B12) | C12: =IF($A12="","",Job_Master_Ring!C12) | D12: =IF($A12="","",Job_Master_Ring!D12) | E12: =IF($A12="","",IF($I12<>"",$I12,IFERROR(INDEX(Machine_List!$B$87:$B$94,MATCH(1,(Machine_List!$H$87:$H$94<=IFERROR(VLOOKUP($B12,CHOOSE(MATCH($C12,Settings!$L$4:$L$10,0),OPR_BR1!$A$4:$K$18,OPR_BR2!$A$4:$K$18,OPR_CR2!$A$4:$K$18,OPR_CR3!$A$4:$K$18,OPR_CR4!$A$4:$K$18,OPR_RIM!$A$4:$K$18,OPR_BPR!$A$4:$K$18),10,0),0))*(Machine_List!$I$87:$I$94>=IFERROR(VLOOKUP($B12,CHOOSE(MATCH($C12,Settings!$L$4:$L$10,0),OPR_BR1!$A$4:$K$18,OPR_BR2!$A$4:$K$18,OPR_CR2!$A$4:$K$18,OPR_CR3!$A$4:$K$18,OPR_CR4!$A$4:$K$18,OPR_RIM!$A$4:$K$18,OPR_BPR!$A$4:$K$18),11,0),9999)),0)),"NO COMPATIBLE MACHINE"))) | F12: =IF($E12="","",IFERROR(VLOOKUP($E12,Machine_List!$B:$G,6,0),"")) | G12: =IF($E12="","",IFERROR(VLOOKUP($E12,Machine_List!$B:$C,2,0),"")) | H12: =IF($E12="","",IFERROR(VLOOKUP($E12,Machine_List!$B:$D,3,0),"")) | J12: =IF($A12="","",IF($I12<>"",$I12,MAX(GlobalStartDate,IFERROR(LOOKUP(2,1/($E$3:INDIRECT("E"&(ROW()-1))=$E12),$M$3:INDIRECT("M"&(ROW()-1))),GlobalStartDate)))) | K12: =IF($A12="","",IFERROR(VLOOKUP(B12,CHOOSE(MATCH($C12,Settings!$L$4:$L$10,0),OPR_BR1!$A$4:$I$18,OPR_BR2!$A$4:$I$18,OPR_CR2!$A$4:$I$18,OPR_CR3!$A$4:$I$18,OPR_CR4!$A$4:$I$18,OPR_RIM!$A$4:$I$18,OPR_BPR!$A$4:$I$18),2,0),0)) | L12: =IF($A12="","",K12*D12) | M12: =IF($A12="","",IF(AND(ISNUMBER(G12),G12>=J12,G12<=(J12+(L12/(IF(F12="Contract Workman",Settings!$K$5,Settings!$K$4))))),J12+(L12/(IF(F12="Contract Workman",Settings!$K$5,Settings!$K$4)))+(H12/(IF(F12="Contract Workman",Settings!$K$5,Settings!$K$4))),J12+(L12/(IF(F12="Contract Workman",Settings!$K$5,Settings!$K$4))))) | N12: =IF($A12="","",IF(F12="Contract Workman",IF(AND(MOD(M12,1)>=8/24,MOD(M12,1)<20/24),"Shift S1","Shift S2"),IF(AND(MOD(M12,1)>=7/24,MOD(M12,1)<15/24),"Shift A",IF(AND(MOD(M12,1)>=15/24,MOD(M12,1)<23/24),"Shift B","Shift C")))) | O12: =IF(B12="","",IF(IFERROR(ISNUMBER(SEARCH(TEXT(B12,"0"),VLOOKUP(E12,Machine_List!$B:$J,9,0))),FALSE),"✅ "&E12,"❌ ?")) | P12: =IF(AND($A12<>"",P$3>=$J12,P$3<=$M12),1,"") | Q12: =IF(AND($A12<>"",Q$3>=$J12,Q$3<=$M12),1,"") | R12: =IF(AND($A12<>"",R$3>=$J12,R$3<=$M12),1,"") | S12: =IF(AND($A12<>"",S$3>=$J12,S$3<=$M12),1,"") | T12: =IF(AND($A12<>"",T$3>=$J12,T$3<=$M12),1,"") | U12: =IF(AND($A12<>"",U$3>=$J12,U$3<=$M12),1,"") | V12: =IF(AND($A12<>"",V$3>=$J12,V$3<=$M12),1,"") | W12: =IF(AND($A12<>"",W$3>=$J12,W$3<=$M12),1,"") | ... BV12: =IF(AND($A12<>"",BV$3>=$J12,BV$3<=$M12),1,"")
A13: =IF(Job_Master_Ring!$A13="","",Job_Master_Ring!$A13) | B13: =IF($A13="","",Job_Master_Ring!B13) | C13: =IF($A13="","",Job_Master_Ring!C13) | D13: =IF($A13="","",Job_Master_Ring!D13) | E13: =IF($A13="","",IF($I13<>"",$I13,IFERROR(INDEX(Machine_List!$B$87:$B$94,MATCH(1,(Machine_List!$H$87:$H$94<=IFERROR(VLOOKUP($B13,CHOOSE(MATCH($C13,Settings!$L$4:$L$10,0),OPR_BR1!$A$4:$K$18,OPR_BR2!$A$4:$K$18,OPR_CR2!$A$4:$K$18,OPR_CR3!$A$4:$K$18,OPR_CR4!$A$4:$K$18,OPR_RIM!$A$4:$K$18,OPR_BPR!$A$4:$K$18),10,0),0))*(Machine_List!$I$87:$I$94>=IFERROR(VLOOKUP($B13,CHOOSE(MATCH($C13,Settings!$L$4:$L$10,0),OPR_BR1!$A$4:$K$18,OPR_BR2!$A$4:$K$18,OPR_CR2!$A$4:$K$18,OPR_CR3!$A$4:$K$18,OPR_CR4!$A$4:$K$18,OPR_RIM!$A$4:$K$18,OPR_BPR!$A$4:$K$18),11,0),9999)),0)),"NO COMPATIBLE MACHINE"))) | F13: =IF($E13="","",IFERROR(VLOOKUP($E13,Machine_List!$B:$G,6,0),"")) | G13: =IF($E13="","",IFERROR(VLOOKUP($E13,Machine_List!$B:$C,2,0),"")) | H13: =IF($E13="","",IFERROR(VLOOKUP($E13,Machine_List!$B:$D,3,0),"")) | J13: =IF($A13="","",IF($I13<>"",$I13,MAX(GlobalStartDate,IFERROR(LOOKUP(2,1/($E$3:INDIRECT("E"&(ROW()-1))=$E13),$M$3:INDIRECT("M"&(ROW()-1))),GlobalStartDate)))) | K13: =IF($A13="","",IFERROR(VLOOKUP(B13,CHOOSE(MATCH($C13,Settings!$L$4:$L$10,0),OPR_BR1!$A$4:$I$18,OPR_BR2!$A$4:$I$18,OPR_CR2!$A$4:$I$18,OPR_CR3!$A$4:$I$18,OPR_CR4!$A$4:$I$18,OPR_RIM!$A$4:$I$18,OPR_BPR!$A$4:$I$18),2,0),0)) | L13: =IF($A13="","",K13*D13) | M13: =IF($A13="","",IF(AND(ISNUMBER(G13),G13>=J13,G13<=(J13+(L13/(IF(F13="Contract Workman",Settings!$K$5,Settings!$K$4))))),J13+(L13/(IF(F13="Contract Workman",Settings!$K$5,Settings!$K$4)))+(H13/(IF(F13="Contract Workman",Settings!$K$5,Settings!$K$4))),J13+(L13/(IF(F13="Contract Workman",Settings!$K$5,Settings!$K$4))))) | N13: =IF($A13="","",IF(F13="Contract Workman",IF(AND(MOD(M13,1)>=8/24,MOD(M13,1)<20/24),"Shift S1","Shift S2"),IF(AND(MOD(M13,1)>=7/24,MOD(M13,1)<15/24),"Shift A",IF(AND(MOD(M13,1)>=15/24,MOD(M13,1)<23/24),"Shift B","Shift C")))) | O13: =IF(B13="","",IF(IFERROR(ISNUMBER(SEARCH(TEXT(B13,"0"),VLOOKUP(E13,Machine_List!$B:$J,9,0))),FALSE),"✅ "&E13,"❌ ?")) | P13: =IF(AND($A13<>"",P$3>=$J13,P$3<=$M13),1,"") | Q13: =IF(AND($A13<>"",Q$3>=$J13,Q$3<=$M13),1,"") | R13: =IF(AND($A13<>"",R$3>=$J13,R$3<=$M13),1,"") | S13: =IF(AND($A13<>"",S$3>=$J13,S$3<=$M13),1,"") | T13: =IF(AND($A13<>"",T$3>=$J13,T$3<=$M13),1,"") | U13: =IF(AND($A13<>"",U$3>=$J13,U$3<=$M13),1,"") | V13: =IF(AND($A13<>"",V$3>=$J13,V$3<=$M13),1,"") | W13: =IF(AND($A13<>"",W$3>=$J13,W$3<=$M13),1,"") | ... BV13: =IF(AND($A13<>"",BV$3>=$J13,BV$3<=$M13),1,"")
A14: =IF(Job_Master_Ring!$A14="","",Job_Master_Ring!$A14) | B14: =IF($A14="","",Job_Master_Ring!B14) | C14: =IF($A14="","",Job_Master_Ring!C14) | D14: =IF($A14="","",Job_Master_Ring!D14) | E14: =IF($A14="","",IF($I14<>"",$I14,IFERROR(INDEX(Machine_List!$B$87:$B$94,MATCH(1,(Machine_List!$H$87:$H$94<=IFERROR(VLOOKUP($B14,CHOOSE(MATCH($C14,Settings!$L$4:$L$10,0),OPR_BR1!$A$4:$K$18,OPR_BR2!$A$4:$K$18,OPR_CR2!$A$4:$K$18,OPR_CR3!$A$4:$K$18,OPR_CR4!$A$4:$K$18,OPR_RIM!$A$4:$K$18,OPR_BPR!$A$4:$K$18),10,0),0))*(Machine_List!$I$87:$I$94>=IFERROR(VLOOKUP($B14,CHOOSE(MATCH($C14,Settings!$L$4:$L$10,0),OPR_BR1!$A$4:$K$18,OPR_BR2!$A$4:$K$18,OPR_CR2!$A$4:$K$18,OPR_CR3!$A$4:$K$18,OPR_CR4!$A$4:$K$18,OPR_RIM!$A$4:$K$18,OPR_BPR!$A$4:$K$18),11,0),9999)),0)),"NO COMPATIBLE MACHINE"))) | F14: =IF($E14="","",IFERROR(VLOOKUP($E14,Machine_List!$B:$G,6,0),"")) | G14: =IF($E14="","",IFERROR(VLOOKUP($E14,Machine_List!$B:$C,2,0),"")) | H14: =IF($E14="","",IFERROR(VLOOKUP($E14,Machine_List!$B:$D,3,0),"")) | J14: =IF($A14="","",IF($I14<>"",$I14,MAX(GlobalStartDate,IFERROR(LOOKUP(2,1/($E$3:INDIRECT("E"&(ROW()-1))=$E14),$M$3:INDIRECT("M"&(ROW()-1))),GlobalStartDate)))) | K14: =IF($A14="","",IFERROR(VLOOKUP(B14,CHOOSE(MATCH($C14,Settings!$L$4:$L$10,0),OPR_BR1!$A$4:$I$18,OPR_BR2!$A$4:$I$18,OPR_CR2!$A$4:$I$18,OPR_CR3!$A$4:$I$18,OPR_CR4!$A$4:$I$18,OPR_RIM!$A$4:$I$18,OPR_BPR!$A$4:$I$18),2,0),0)) | L14: =IF($A14="","",K14*D14) | M14: =IF($A14="","",IF(AND(ISNUMBER(G14),G14>=J14,G14<=(J14+(L14/(IF(F14="Contract Workman",Settings!$K$5,Settings!$K$4))))),J14+(L14/(IF(F14="Contract Workman",Settings!$K$5,Settings!$K$4)))+(H14/(IF(F14="Contract Workman",Settings!$K$5,Settings!$K$4))),J14+(L14/(IF(F14="Contract Workman",Settings!$K$5,Settings!$K$4))))) | N14: =IF($A14="","",IF(F14="Contract Workman",IF(AND(MOD(M14,1)>=8/24,MOD(M14,1)<20/24),"Shift S1","Shift S2"),IF(AND(MOD(M14,1)>=7/24,MOD(M14,1)<15/24),"Shift A",IF(AND(MOD(M14,1)>=15/24,MOD(M14,1)<23/24),"Shift B","Shift C")))) | O14: =IF(B14="","",IF(IFERROR(ISNUMBER(SEARCH(TEXT(B14,"0"),VLOOKUP(E14,Machine_List!$B:$J,9,0))),FALSE),"✅ "&E14,"❌ ?")) | P14: =IF(AND($A14<>"",P$3>=$J14,P$3<=$M14),1,"") | Q14: =IF(AND($A14<>"",Q$3>=$J14,Q$3<=$M14),1,"") | R14: =IF(AND($A14<>"",R$3>=$J14,R$3<=$M14),1,"") | S14: =IF(AND($A14<>"",S$3>=$J14,S$3<=$M14),1,"") | T14: =IF(AND($A14<>"",T$3>=$J14,T$3<=$M14),1,"") | U14: =IF(AND($A14<>"",U$3>=$J14,U$3<=$M14),1,"") | V14: =IF(AND($A14<>"",V$3>=$J14,V$3<=$M14),1,"") | W14: =IF(AND($A14<>"",W$3>=$J14,W$3<=$M14),1,"") | ... BV14: =IF(AND($A14<>"",BV$3>=$J14,BV$3<=$M14),1,"")
