Workbook

Sheet Settings
H2: Lunch/Tea Break hrs | I2: 0.8
A3: Shift | B3: Category | C3: Start | D3: End | E3: String | F3: Gen Qty | G3: Cont Qty | H3: Net Hrs | I3: Avl hrs | J3: =B3 -> Category | K3: Net Hrs | L3: Type | M3: Size
A4: Shift A | B4: =J$4 -> Gen | C4: 0.29166667 | D4: 0.625 | E4: 07:00 – 15:00 | F4: =IF(B4="General Workman",40,0) -> 0 | G4: =IF(B4="Contract Workman",60,0) -> 0 | H4: =ROUND((IF(D4<C4,D4+1,D4)-C4)*24,0) -> 8 | I4: =H4-I$2 -> 7.2 | J4: Gen | K4: =SUM(I4:I6) -> 21.6 | L4: 2P | M4: 9
A5: Shift B | B5: =J$4 -> Gen | C5: 0.625 | D5: 0.95833333 | E5: 15:00 – 23:00 | F5: =IF(B5="General Workman",40,0) -> 0 | G5: =IF(B5="Contract Workman",60,0) -> 0 | H5: =ROUND((IF(D5<C5,D5+1,D5)-C5)*24,0) -> 8 | I5: =H5-I$2 -> 7.2 | J5: Cont | K5: =SUM(I7:I8) -> 22.4 | L5: SEG | M5: 15
A6: Shift C | B6: =J$4 -> Gen | C6: 0.95833333 | D6: 0.29166667 | E6: 23:00 – 07:00 | F6: =IF(B6="General Workman",40,0) -> 0 | G6: =IF(B6="Contract Workman",60,0) -> 0 | H6: =ROUND((IF(D6<C6,D6+1,D6)-C6)*24,0) -> 8 | I6: =H6-I$2 -> 7.2 | L6: SOL | M6: 17
A7: Shift S1 | B7: =J$5 -> Cont | C7: 0.33333333 | D7: 0.83333333 | E7: 08:00 – 20:00 | F7: =IF(B7="General Workman",40,0) -> 0 | G7: =IF(B7="Contract Workman",60,0) -> 0 | H7: =ROUND((IF(D7<C7,D7+1,D7)-C7)*24,0) -> 12 | I7: =H7-I$2 -> 11.2 | L7: RW | M7: 20
A8: Shift S2 | B8: =J$5 -> Cont | C8: 0.83333333 | D8: 0.33333333 | E8: 20:00 – 08:00 | F8: =IF(B8="General Workman",40,0) -> 0 | G8: =IF(B8="Contract Workman",60,0) -> 0 | H8: =ROUND((IF(D8<C8,D8+1,D8)-C8)*24,0) -> 12 | I8: =H8-I$2 -> 11.2 | L8: RW2 | M8: 25
L9: FLAP | M9: 28
L10: TUBE | M10: 30
M11: 34
M12: 42
M13: 46
M14: 50
M15: 54
M16: 57
M17: 63
M18: 70

Sheet Machine_List
A3: Operation | B3: Machine ID | C3: Next PM Date | D3: Dur | E3: Freq | F3: Status | G3: Worker Category | H3: Machine Min ID Limit | I3: Machine Max OD Limit (New) | J3: Compatible Size Range
A4: VTL | B4: VTL-MC-01 | C4: 46133 | D4: 6 | E4: 4 | F4: Active | G4: General Workman | H4: 100 | I4: 1600 | J4: =IFERROR(LEFT(IF((OPR_2P!$J$4>=H4)*(OPR_2P!$K$4<=I4), OPR_2P!$A$4 & ", ", "") & IF((OPR_2P!$J$5>=H4)*(OPR_2P!$K$5<=I4), OPR_2P!$A$5 & ", ", "") & IF((OPR_2P!$J$6>=H4)*(OPR_2P!$K$6<=I4), OPR_2P!$A$6 & ", ", "") & IF((OPR_2P!$J$7>=H4)*(OPR_2P!$K$7<=I4), OPR_2P!$A$7 & ", ", "") & IF((OPR_2P!$J$8>=H4)*(OPR_2P!$K$8<=I4), OPR_2P!$A$8 & ", ", "") & IF((OPR_2P!$J$9>=H4)*(OPR_2P!$K$9<=I4), OPR_2P!$A$9 & ", ", "") & IF((OPR_2P!$J$10>=H4)*(OPR_2P!$K$10<=I4), OPR_2P!$A$10 & ", ", "") & IF((OPR_2P!$J$11>=H4)*(OPR_2P!$K$11<=I4), OPR_2P!$A$11 & ", ", "") & IF((OPR_2P!$J$12>=H4)*(OPR_2P!$K$12<=I4), OPR_2P!$A$12 & ", ", "") & IF((OPR_2P!$J$13>=H4)*(OPR_2P!$K$13<=I4), OPR_2P!$A$13 & ", ", "") & IF((OPR_2P!$J$14>=H4)*(OPR_2P!$K$14<=I4), OPR_2P!$A$14 & ", ", "") & IF((OPR_2P!$J$15>=H4)*(OPR_2P!$K$15<=I4), OPR_2P!$A$15 & ", ", "") & IF((OPR_2P!$J$16>=H4)*(OPR_2P!$K$16<=I4), OPR_2P!$A$16 & ", ", "") & IF((OPR_2P!$J$17>=H4)*(OPR_2P!$K$17<=I4), OPR_2P!$A$17 & ", ", "") & IF((OPR_2P!$J$18>=H4)*(OPR_2P!$K$18<=I4), OPR_2P!$A$18 & ", ", ""), LEN(IF((OPR_2P!$J$4>=H4)*(OPR_2P!$K$4<=I4), OPR_2P!$A$4 & ", ", "") & IF((OPR_2P!$J$5>=H4)*(OPR_2P!$K$5<=I4), OPR_2P!$A$5 & ", ", "") & IF((OPR_2P!$J$6>=H4)*(OPR_2P!$K$6<=I4), OPR_2P!$A$6 & ", ", "") & IF((OPR_2P!$J$7>=H4)*(OPR_2P!$K$7<=I4), OPR_2P!$A$7 & ", ", "") & IF((OPR_2P!$J$8>=H4)*(OPR_2P!$K$8<=I4), OPR_2P!$A$8 & ", ", "") & IF((OPR_2P!$J$9>=H4)*(OPR_2P!$K$9<=I4), OPR_2P!$A$9 & ", ", "") & IF((OPR_2P!$J$10>=H4)*(OPR_2P!$K$10<=I4), OPR_2P!$A$10 & ", ", "") & IF((OPR_2P!$J$11>=H4)*(OPR_2P!$K$11<=I4), OPR_2P!$A$11 & ", ", "") & IF((OPR_2P!$J$12>=H4)*(OPR_2P!$K$12<=I4), OPR_2P!$A$12 & ", ", "") & IF((OPR_2P!$J$13>=H4)*(OPR_2P!$K$13<=I4), OPR_2P!$A$13 & ", ", "") & IF((OPR_2P!$J$14>=H4)*(OPR_2P!$K$14<=I4), OPR_2P!$A$14 & ", ", "") & IF((OPR_2P!$J$15>=H4)*(OPR_2P!$K$15<=I4), OPR_2P!$A$15 & ", ", "") & IF((OPR_2P!$J$16>=H4)*(OPR_2P!$K$16<=I4), OPR_2P!$A$16 & ", ", "") & IF((OPR_2P!$J$17>=H4)*(OPR_2P!$K$17<=I4), OPR_2P!$A$17 & ", ", "") & IF((OPR_2P!$J$18>=H4)*(OPR_2P!$K$18<=I4), OPR_2P!$A$18 & ", ", ""))-2), "None") -> 9, 15, 17, 20, 25, 28
A5: VTL | B5: VTL-MC-02 | C5: 46521 | D5: 6 | E5: 4 | F5: Active | G5: General Workman | H5: 600 | I5: 2500 | J5: =IFERROR(LEFT(IF((OPR_2P!$J$4>=H5)*(OPR_2P!$K$4<=I5), OPR_2P!$A$4 & ", ", "") & IF((OPR_2P!$J$5>=H5)*(OPR_2P!$K$5<=I5), OPR_2P!$A$5 & ", ", "") & IF((OPR_2P!$J$6>=H5)*(OPR_2P!$K$6<=I5), OPR_2P!$A$6 & ", ", "") & IF((OPR_2P!$J$7>=H5)*(OPR_2P!$K$7<=I5), OPR_2P!$A$7 & ", ", "") & IF((OPR_2P!$J$8>=H5)*(OPR_2P!$K$8<=I5), OPR_2P!$A$8 & ", ", "") & IF((OPR_2P!$J$9>=H5)*(OPR_2P!$K$9<=I5), OPR_2P!$A$9 & ", ", "") & IF((OPR_2P!$J$10>=H5)*(OPR_2P!$K$10<=I5), OPR_2P!$A$10 & ", ", "") & IF((OPR_2P!$J$11>=H5)*(OPR_2P!$K$11<=I5), OPR_2P!$A$11 & ", ", "") & IF((OPR_2P!$J$12>=H5)*(OPR_2P!$K$12<=I5), OPR_2P!$A$12 & ", ", "") & IF((OPR_2P!$J$13>=H5)*(OPR_2P!$K$13<=I5), OPR_2P!$A$13 & ", ", "") & IF((OPR_2P!$J$14>=H5)*(OPR_2P!$K$14<=I5), OPR_2P!$A$14 & ", ", "") & IF((OPR_2P!$J$15>=H5)*(OPR_2P!$K$15<=I5), OPR_2P!$A$15 & ", ", "") & IF((OPR_2P!$J$16>=H5)*(OPR_2P!$K$16<=I5), OPR_2P!$A$16 & ", ", "") & IF((OPR_2P!$J$17>=H5)*(OPR_2P!$K$17<=I5), OPR_2P!$A$17 & ", ", "") & IF((OPR_2P!$J$18>=H5)*(OPR_2P!$K$18<=I5), OPR_2P!$A$18 & ", ", ""), LEN(IF((OPR_2P!$J$4>=H5)*(OPR_2P!$K$4<=I5), OPR_2P!$A$4 & ", ", "") & IF((OPR_2P!$J$5>=H5)*(OPR_2P!$K$5<=I5), OPR_2P!$A$5 & ", ", "") & IF((OPR_2P!$J$6>=H5)*(OPR_2P!$K$6<=I5), OPR_2P!$A$6 & ", ", "") & IF((OPR_2P!$J$7>=H5)*(OPR_2P!$K$7<=I5), OPR_2P!$A$7 & ", ", "") & IF((OPR_2P!$J$8>=H5)*(OPR_2P!$K$8<=I5), OPR_2P!$A$8 & ", ", "") & IF((OPR_2P!$J$9>=H5)*(OPR_2P!$K$9<=I5), OPR_2P!$A$9 & ", ", "") & IF((OPR_2P!$J$10>=H5)*(OPR_2P!$K$10<=I5), OPR_2P!$A$10 & ", ", "") & IF((OPR_2P!$J$11>=H5)*(OPR_2P!$K$11<=I5), OPR_2P!$A$11 & ", ", "") & IF((OPR_2P!$J$12>=H5)*(OPR_2P!$K$12<=I5), OPR_2P!$A$12 & ", ", "") & IF((OPR_2P!$J$13>=H5)*(OPR_2P!$K$13<=I5), OPR_2P!$A$13 & ", ", "") & IF((OPR_2P!$J$14>=H5)*(OPR_2P!$K$14<=I5), OPR_2P!$A$14 & ", ", "") & IF((OPR_2P!$J$15>=H5)*(OPR_2P!$K$15<=I5), OPR_2P!$A$15 & ", ", "") & IF((OPR_2P!$J$16>=H5)*(OPR_2P!$K$16<=I5), OPR_2P!$A$16 & ", ", "") & IF((OPR_2P!$J$17>=H5)*(OPR_2P!$K$17<=I5), OPR_2P!$A$17 & ", ", "") & IF((OPR_2P!$J$18>=H5)*(OPR_2P!$K$18<=I5), OPR_2P!$A$18 & ", ", ""))-2), "None") -> 20, 25, 28, 30, 34, 42, 46
A6: VTL | B6: VTL-MC-03 | C6: 46174 | D6: 6 | E6: 4 | F6: Active | G6: General Workman | H6: 800 | I6: 3500 | J6: =IFERROR(LEFT(IF((OPR_2P!$J$4>=H6)*(OPR_2P!$K$4<=I6), OPR_2P!$A$4 & ", ", "") & IF((OPR_2P!$J$5>=H6)*(OPR_2P!$K$5<=I6), OPR_2P!$A$5 & ", ", "") & IF((OPR_2P!$J$6>=H6)*(OPR_2P!$K$6<=I6), OPR_2P!$A$6 & ", ", "") & IF((OPR_2P!$J$7>=H6)*(OPR_2P!$K$7<=I6), OPR_2P!$A$7 & ", ", "") & IF((OPR_2P!$J$8>=H6)*(OPR_2P!$K$8<=I6), OPR_2P!$A$8 & ", ", "") & IF((OPR_2P!$J$9>=H6)*(OPR_2P!$K$9<=I6), OPR_2P!$A$9 & ", ", "") & IF((OPR_2P!$J$10>=H6)*(OPR_2P!$K$10<=I6), OPR_2P!$A$10 & ", ", "") & IF((OPR_2P!$J$11>=H6)*(OPR_2P!$K$11<=I6), OPR_2P!$A$11 & ", ", "") & IF((OPR_2P!$J$12>=H6)*(OPR_2P!$K$12<=I6), OPR_2P!$A$12 & ", ", "") & IF((OPR_2P!$J$13>=H6)*(OPR_2P!$K$13<=I6), OPR_2P!$A$13 & ", ", "") & IF((OPR_2P!$J$14>=H6)*(OPR_2P!$K$14<=I6), OPR_2P!$A$14 & ", ", "") & IF((OPR_2P!$J$15>=H6)*(OPR_2P!$K$15<=I6), OPR_2P!$A$15 & ", ", "") & IF((OPR_2P!$J$16>=H6)*(OPR_2P!$K$16<=I6), OPR_2P!$A$16 & ", ", "") & IF((OPR_2P!$J$17>=H6)*(OPR_2P!$K$17<=I6), OPR_2P!$A$17 & ", ", "") & IF((OPR_2P!$J$18>=H6)*(OPR_2P!$K$18<=I6), OPR_2P!$A$18 & ", ", ""), LEN(IF((OPR_2P!$J$4>=H6)*(OPR_2P!$K$4<=I6), OPR_2P!$A$4 & ", ", "") & IF((OPR_2P!$J$5>=H6)*(OPR_2P!$K$5<=I6), OPR_2P!$A$5 & ", ", "") & IF((OPR_2P!$J$6>=H6)*(OPR_2P!$K$6<=I6), OPR_2P!$A$6 & ", ", "") & IF((OPR_2P!$J$7>=H6)*(OPR_2P!$K$7<=I6), OPR_2P!$A$7 & ", ", "") & IF((OPR_2P!$J$8>=H6)*(OPR_2P!$K$8<=I6), OPR_2P!$A$8 & ", ", "") & IF((OPR_2P!$J$9>=H6)*(OPR_2P!$K$9<=I6), OPR_2P!$A$9 & ", ", "") & IF((OPR_2P!$J$10>=H6)*(OPR_2P!$K$10<=I6), OPR_2P!$A$10 & ", ", "") & IF((OPR_2P!$J$11>=H6)*(OPR_2P!$K$11<=I6), OPR_2P!$A$11 & ", ", "") & IF((OPR_2P!$J$12>=H6)*(OPR_2P!$K$12<=I6), OPR_2P!$A$12 & ", ", "") & IF((OPR_2P!$J$13>=H6)*(OPR_2P!$K$13<=I6), OPR_2P!$A$13 & ", ", "") & IF((OPR_2P!$J$14>=H6)*(OPR_2P!$K$14<=I6), OPR_2P!$A$14 & ", ", "") & IF((OPR_2P!$J$15>=H6)*(OPR_2P!$K$15<=I6), OPR_2P!$A$15 & ", ", "") & IF((OPR_2P!$J$16>=H6)*(OPR_2P!$K$16<=I6), OPR_2P!$A$16 & ", ", "") & IF((OPR_2P!$J$17>=H6)*(OPR_2P!$K$17<=I6), OPR_2P!$A$17 & ", ", "") & IF((OPR_2P!$J$18>=H6)*(OPR_2P!$K$18<=I6), OPR_2P!$A$18 & ", ", ""))-2), "None") -> 25, 28, 30, 34, 42, 46, 50, 54, 57, 63, 70
A7: VTL | B7: VTL-MC-04 | C7: 46517 | D7: 6 | E7: 4 | F7: Active | G7: General Workman | H7: 1000 | I7: 4500 | J7: =IFERROR(LEFT(IF((OPR_2P!$J$4>=H7)*(OPR_2P!$K$4<=I7), OPR_2P!$A$4 & ", ", "") & IF((OPR_2P!$J$5>=H7)*(OPR_2P!$K$5<=I7), OPR_2P!$A$5 & ", ", "") & IF((OPR_2P!$J$6>=H7)*(OPR_2P!$K$6<=I7), OPR_2P!$A$6 & ", ", "") & IF((OPR_2P!$J$7>=H7)*(OPR_2P!$K$7<=I7), OPR_2P!$A$7 & ", ", "") & IF((OPR_2P!$J$8>=H7)*(OPR_2P!$K$8<=I7), OPR_2P!$A$8 & ", ", "") & IF((OPR_2P!$J$9>=H7)*(OPR_2P!$K$9<=I7), OPR_2P!$A$9 & ", ", "") & IF((OPR_2P!$J$10>=H7)*(OPR_2P!$K$10<=I7), OPR_2P!$A$10 & ", ", "") & IF((OPR_2P!$J$11>=H7)*(OPR_2P!$K$11<=I7), OPR_2P!$A$11 & ", ", "") & IF((OPR_2P!$J$12>=H7)*(OPR_2P!$K$12<=I7), OPR_2P!$A$12 & ", ", "") & IF((OPR_2P!$J$13>=H7)*(OPR_2P!$K$13<=I7), OPR_2P!$A$13 & ", ", "") & IF((OPR_2P!$J$14>=H7)*(OPR_2P!$K$14<=I7), OPR_2P!$A$14 & ", ", "") & IF((OPR_2P!$J$15>=H7)*(OPR_2P!$K$15<=I7), OPR_2P!$A$15 & ", ", "") & IF((OPR_2P!$J$16>=H7)*(OPR_2P!$K$16<=I7), OPR_2P!$A$16 & ", ", "") & IF((OPR_2P!$J$17>=H7)*(OPR_2P!$K$17<=I7), OPR_2P!$A$17 & ", ", "") & IF((OPR_2P!$J$18>=H7)*(OPR_2P!$K$18<=I7), OPR_2P!$A$18 & ", ", ""), LEN(IF((OPR_2P!$J$4>=H7)*(OPR_2P!$K$4<=I7), OPR_2P!$A$4 & ", ", "") & IF((OPR_2P!$J$5>=H7)*(OPR_2P!$K$5<=I7), OPR_2P!$A$5 & ", ", "") & IF((OPR_2P!$J$6>=H7)*(OPR_2P!$K$6<=I7), OPR_2P!$A$6 & ", ", "") & IF((OPR_2P!$J$7>=H7)*(OPR_2P!$K$7<=I7), OPR_2P!$A$7 & ", ", "") & IF((OPR_2P!$J$8>=H7)*(OPR_2P!$K$8<=I7), OPR_2P!$A$8 & ", ", "") & IF((OPR_2P!$J$9>=H7)*(OPR_2P!$K$9<=I7), OPR_2P!$A$9 & ", ", "") & IF((OPR_2P!$J$10>=H7)*(OPR_2P!$K$10<=I7), OPR_2P!$A$10 & ", ", "") & IF((OPR_2P!$J$11>=H7)*(OPR_2P!$K$11<=I7), OPR_2P!$A$11 & ", ", "") & IF((OPR_2P!$J$12>=H7)*(OPR_2P!$K$12<=I7), OPR_2P!$A$12 & ", ", "") & IF((OPR_2P!$J$13>=H7)*(OPR_2P!$K$13<=I7), OPR_2P!$A$13 & ", ", "") & IF((OPR_2P!$J$14>=H7)*(OPR_2P!$K$14<=I7), OPR_2P!$A$14 & ", ", "") & IF((OPR_2P!$J$15>=H7)*(OPR_2P!$K$15<=I7), OPR_2P!$A$15 & ", ", "") & IF((OPR_2P!$J$16>=H7)*(OPR_2P!$K$16<=I7), OPR_2P!$A$16 & ", ", "") & IF((OPR_2P!$J$17>=H7)*(OPR_2P!$K$17<=I7), OPR_2P!$A$17 & ", ", "") & IF((OPR_2P!$J$18>=H7)*(OPR_2P!$K$18<=I7), OPR_2P!$A$18 & ", ", ""))-2), "None") -> 28, 30, 34, 42, 46, 50, 54, 57, 63, 70
A8: SPM | B8: SPM-MC-01 | C8: 46285 | D8: 6 | E8: 4 | F8: Active | G8: General Workman | H8: 100 | I8: 3500 | J8: =IFERROR(LEFT(IF((OPR_2P!$J$4>=H8)*(OPR_2P!$K$4<=I8), OPR_2P!$A$4 & ", ", "") & IF((OPR_2P!$J$5>=H8)*(OPR_2P!$K$5<=I8), OPR_2P!$A$5 & ", ", "") & IF((OPR_2P!$J$6>=H8)*(OPR_2P!$K$6<=I8), OPR_2P!$A$6 & ", ", "") & IF((OPR_2P!$J$7>=H8)*(OPR_2P!$K$7<=I8), OPR_2P!$A$7 & ", ", "") & IF((OPR_2P!$J$8>=H8)*(OPR_2P!$K$8<=I8), OPR_2P!$A$8 & ", ", "") & IF((OPR_2P!$J$9>=H8)*(OPR_2P!$K$9<=I8), OPR_2P!$A$9 & ", ", "") & IF((OPR_2P!$J$10>=H8)*(OPR_2P!$K$10<=I8), OPR_2P!$A$10 & ", ", "") & IF((OPR_2P!$J$11>=H8)*(OPR_2P!$K$11<=I8), OPR_2P!$A$11 & ", ", "") & IF((OPR_2P!$J$12>=H8)*(OPR_2P!$K$12<=I8), OPR_2P!$A$12 & ", ", "") & IF((OPR_2P!$J$13>=H8)*(OPR_2P!$K$13<=I8), OPR_2P!$A$13 & ", ", "") & IF((OPR_2P!$J$14>=H8)*(OPR_2P!$K$14<=I8), OPR_2P!$A$14 & ", ", "") & IF((OPR_2P!$J$15>=H8)*(OPR_2P!$K$15<=I8), OPR_2P!$A$15 & ", ", "") & IF((OPR_2P!$J$16>=H8)*(OPR_2P!$K$16<=I8), OPR_2P!$A$16 & ", ", "") & IF((OPR_2P!$J$17>=H8)*(OPR_2P!$K$17<=I8), OPR_2P!$A$17 & ", ", "") & IF((OPR_2P!$J$18>=H8)*(OPR_2P!$K$18<=I8), OPR_2P!$A$18 & ", ", ""), LEN(IF((OPR_2P!$J$4>=H8)*(OPR_2P!$K$4<=I8), OPR_2P!$A$4 & ", ", "") & IF((OPR_2P!$J$5>=H8)*(OPR_2P!$K$5<=I8), OPR_2P!$A$5 & ", ", "") & IF((OPR_2P!$J$6>=H8)*(OPR_2P!$K$6<=I8), OPR_2P!$A$6 & ", ", "") & IF((OPR_2P!$J$7>=H8)*(OPR_2P!$K$7<=I8), OPR_2P!$A$7 & ", ", "") & IF((OPR_2P!$J$8>=H8)*(OPR_2P!$K$8<=I8), OPR_2P!$A$8 & ", ", "") & IF((OPR_2P!$J$9>=H8)*(OPR_2P!$K$9<=I8), OPR_2P!$A$9 & ", ", "") & IF((OPR_2P!$J$10>=H8)*(OPR_2P!$K$10<=I8), OPR_2P!$A$10 & ", ", "") & IF((OPR_2P!$J$11>=H8)*(OPR_2P!$K$11<=I8), OPR_2P!$A$11 & ", ", "") & IF((OPR_2P!$J$12>=H8)*(OPR_2P!$K$12<=I8), OPR_2P!$A$12 & ", ", "") & IF((OPR_2P!$J$13>=H8)*(OPR_2P!$K$13<=I8), OPR_2P!$A$13 & ", ", "") & IF((OPR_2P!$J$14>=H8)*(OPR_2P!$K$14<=I8), OPR_2P!$A$14 & ", ", "") & IF((OPR_2P!$J$15>=H8)*(OPR_2P!$K$15<=I8), OPR_2P!$A$15 & ", ", "") & IF((OPR_2P!$J$16>=H8)*(OPR_2P!$K$16<=I8), OPR_2P!$A$16 & ", ", "") & IF((OPR_2P!$J$17>=H8)*(OPR_2P!$K$17<=I8), OPR_2P!$A$17 & ", ", "") & IF((OPR_2P!$J$18>=H8)*(OPR_2P!$K$18<=I8), OPR_2P!$A$18 & ", ", ""))-2), "None") -> 9, 15, 17, 20, 25, 28, 30, 34, 42, 46, 50, 54, 57, 63, 70
A9: SPM | B9: SPM-MC-02 | C9: 46459 | D9: 6 | E9: 4 | F9: Active | G9: General Workman | H9: 100 | I9: 3500 | J9: =IFERROR(LEFT(IF((OPR_2P!$J$4>=H9)*(OPR_2P!$K$4<=I9), OPR_2P!$A$4 & ", ", "") & IF((OPR_2P!$J$5>=H9)*(OPR_2P!$K$5<=I9), OPR_2P!$A$5 & ", ", "") & IF((OPR_2P!$J$6>=H9)*(OPR_2P!$K$6<=I9), OPR_2P!$A$6 & ", ", "") & IF((OPR_2P!$J$7>=H9)*(OPR_2P!$K$7<=I9), OPR_2P!$A$7 & ", ", "") & IF((OPR_2P!$J$8>=H9)*(OPR_2P!$K$8<=I9), OPR_2P!$A$8 & ", ", "") & IF((OPR_2P!$J$9>=H9)*(OPR_2P!$K$9<=I9), OPR_2P!$A$9 & ", ", "") & IF((OPR_2P!$J$10>=H9)*(OPR_2P!$K$10<=I9), OPR_2P!$A$10 & ", ", "") & IF((OPR_2P!$J$11>=H9)*(OPR_2P!$K$11<=I9), OPR_2P!$A$11 & ", ", "") & IF((OPR_2P!$J$12>=H9)*(OPR_2P!$K$12<=I9), OPR_2P!$A$12 & ", ", "") & IF((OPR_2P!$J$13>=H9)*(OPR_2P!$K$13<=I9), OPR_2P!$A$13 & ", ", "") & IF((OPR_2P!$J$14>=H9)*(OPR_2P!$K$14<=I9), OPR_2P!$A$14 & ", ", "") & IF((OPR_2P!$J$15>=H9)*(OPR_2P!$K$15<=I9), OPR_2P!$A$15 & ", ", "") & IF((OPR_2P!$J$16>=H9)*(OPR_2P!$K$16<=I9), OPR_2P!$A$16 & ", ", "") & IF((OPR_2P!$J$17>=H9)*(OPR_2P!$K$17<=I9), OPR_2P!$A$17 & ", ", "") & IF((OPR_2P!$J$18>=H9)*(OPR_2P!$K$18<=I9), OPR_2P!$A$18 & ", ", ""), LEN(IF((OPR_2P!$J$4>=H9)*(OPR_2P!$K$4<=I9), OPR_2P!$A$4 & ", ", "") & IF((OPR_2P!$J$5>=H9)*(OPR_2P!$K$5<=I9), OPR_2P!$A$5 & ", ", "") & IF((OPR_2P!$J$6>=H9)*(OPR_2P!$K$6<=I9), OPR_2P!$A$6 & ", ", "") & IF((OPR_2P!$J$7>=H9)*(OPR_2P!$K$7<=I9), OPR_2P!$A$7 & ", ", "") & IF((OPR_2P!$J$8>=H9)*(OPR_2P!$K$8<=I9), OPR_2P!$A$8 & ", ", "") & IF((OPR_2P!$J$9>=H9)*(OPR_2P!$K$9<=I9), OPR_2P!$A$9 & ", ", "") & IF((OPR_2P!$J$10>=H9)*(OPR_2P!$K$10<=I9), OPR_2P!$A$10 & ", ", "") & IF((OPR_2P!$J$11>=H9)*(OPR_2P!$K$11<=I9), OPR_2P!$A$11 & ", ", "") & IF((OPR_2P!$J$12>=H9)*(OPR_2P!$K$12<=I9), OPR_2P!$A$12 & ", ", "") & IF((OPR_2P!$J$13>=H9)*(OPR_2P!$K$13<=I9), OPR_2P!$A$13 & ", ", "") & IF((OPR_2P!$J$14>=H9)*(OPR_2P!$K$14<=I9), OPR_2P!$A$14 & ", ", "") & IF((OPR_2P!$J$15>=H9)*(OPR_2P!$K$15<=I9), OPR_2P!$A$15 & ", ", "") & IF((OPR_2P!$J$16>=H9)*(OPR_2P!$K$16<=I9), OPR_2P!$A$16 & ", ", "") & IF((OPR_2P!$J$17>=H9)*(OPR_2P!$K$17<=I9), OPR_2P!$A$17 & ", ", "") & IF((OPR_2P!$J$18>=H9)*(OPR_2P!$K$18<=I9), OPR_2P!$A$18 & ", ", ""))-2), "None") -> 9, 15, 17, 20, 25, 28, 30, 34, 42, 46, 50, 54, 57, 63, 70
A10: SPM | B10: SPM-MC-03 | C10: 46104 | D10: 6 | E10: 4 | F10: Active | G10: General Workman | H10: 100 | I10: 4500 | J10: =IFERROR(LEFT(IF((OPR_2P!$J$4>=H10)*(OPR_2P!$K$4<=I10), OPR_2P!$A$4 & ", ", "") & IF((OPR_2P!$J$5>=H10)*(OPR_2P!$K$5<=I10), OPR_2P!$A$5 & ", ", "") & IF((OPR_2P!$J$6>=H10)*(OPR_2P!$K$6<=I10), OPR_2P!$A$6 & ", ", "") & IF((OPR_2P!$J$7>=H10)*(OPR_2P!$K$7<=I10), OPR_2P!$A$7 & ", ", "") & IF((OPR_2P!$J$8>=H10)*(OPR_2P!$K$8<=I10), OPR_2P!$A$8 & ", ", "") & IF((OPR_2P!$J$9>=H10)*(OPR_2P!$K$9<=I10), OPR_2P!$A$9 & ", ", "") & IF((OPR_2P!$J$10>=H10)*(OPR_2P!$K$10<=I10), OPR_2P!$A$10 & ", ", "") & IF((OPR_2P!$J$11>=H10)*(OPR_2P!$K$11<=I10), OPR_2P!$A$11 & ", ", "") & IF((OPR_2P!$J$12>=H10)*(OPR_2P!$K$12<=I10), OPR_2P!$A$12 & ", ", "") & IF((OPR_2P!$J$13>=H10)*(OPR_2P!$K$13<=I10), OPR_2P!$A$13 & ", ", "") & IF((OPR_2P!$J$14>=H10)*(OPR_2P!$K$14<=I10), OPR_2P!$A$14 & ", ", "") & IF((OPR_2P!$J$15>=H10)*(OPR_2P!$K$15<=I10), OPR_2P!$A$15 & ", ", "") & IF((OPR_2P!$J$16>=H10)*(OPR_2P!$K$16<=I10), OPR_2P!$A$16 & ", ", "") & IF((OPR_2P!$J$17>=H10)*(OPR_2P!$K$17<=I10), OPR_2P!$A$17 & ", ", "") & IF((OPR_2P!$J$18>=H10)*(OPR_2P!$K$18<=I10), OPR_2P!$A$18 & ", ", ""), LEN(IF((OPR_2P!$J$4>=H10)*(OPR_2P!$K$4<=I10), OPR_2P!$A$4 & ", ", "") & IF((OPR_2P!$J$5>=H10)*(OPR_2P!$K$5<=I10), OPR_2P!$A$5 & ", ", "") & IF((OPR_2P!$J$6>=H10)*(OPR_2P!$K$6<=I10), OPR_2P!$A$6 & ", ", "") & IF((OPR_2P!$J$7>=H10)*(OPR_2P!$K$7<=I10), OPR_2P!$A$7 & ", ", "") & IF((OPR_2P!$J$8>=H10)*(OPR_2P!$K$8<=I10), OPR_2P!$A$8 & ", ", "") & IF((OPR_2P!$J$9>=H10)*(OPR_2P!$K$9<=I10), OPR_2P!$A$9 & ", ", "") & IF((OPR_2P!$J$10>=H10)*(OPR_2P!$K$10<=I10), OPR_2P!$A$10 & ", ", "") & IF((OPR_2P!$J$11>=H10)*(OPR_2P!$K$11<=I10), OPR_2P!$A$11 & ", ", "") & IF((OPR_2P!$J$12>=H10)*(OPR_2P!$K$12<=I10), OPR_2P!$A$12 & ", ", "") & IF((OPR_2P!$J$13>=H10)*(OPR_2P!$K$13<=I10), OPR_2P!$A$13 & ", ", "") & IF((OPR_2P!$J$14>=H10)*(OPR_2P!$K$14<=I10), OPR_2P!$A$14 & ", ", "") & IF((OPR_2P!$J$15>=H10)*(OPR_2P!$K$15<=I10), OPR_2P!$A$15 & ", ", "") & IF((OPR_2P!$J$16>=H10)*(OPR_2P!$K$16<=I10), OPR_2P!$A$16 & ", ", "") & IF((OPR_2P!$J$17>=H10)*(OPR_2P!$K$17<=I10), OPR_2P!$A$17 & ", ", "") & IF((OPR_2P!$J$18>=H10)*(OPR_2P!$K$18<=I10), OPR_2P!$A$18 & ", ", ""))-2), "None") -> 9, 15, 17, 20, 25, 28, 30, 34, 42, 46, 50, 54, 57, 63, 70
A11: SPM | B11: SPM-MC-04 | C11: 46197 | D11: 6 | E11: 4 | F11: Active | G11: General Workman | H11: 100 | I11: 4500 | J11: =IFERROR(LEFT(IF((OPR_2P!$J$4>=H11)*(OPR_2P!$K$4<=I11), OPR_2P!$A$4 & ", ", "") & IF((OPR_2P!$J$5>=H11)*(OPR_2P!$K$5<=I11), OPR_2P!$A$5 & ", ", "") & IF((OPR_2P!$J$6>=H11)*(OPR_2P!$K$6<=I11), OPR_2P!$A$6 & ", ", "") & IF((OPR_2P!$J$7>=H11)*(OPR_2P!$K$7<=I11), OPR_2P!$A$7 & ", ", "") & IF((OPR_2P!$J$8>=H11)*(OPR_2P!$K$8<=I11), OPR_2P!$A$8 & ", ", "") & IF((OPR_2P!$J$9>=H11)*(OPR_2P!$K$9<=I11), OPR_2P!$A$9 & ", ", "") & IF((OPR_2P!$J$10>=H11)*(OPR_2P!$K$10<=I11), OPR_2P!$A$10 & ", ", "") & IF((OPR_2P!$J$11>=H11)*(OPR_2P!$K$11<=I11), OPR_2P!$A$11 & ", ", "") & IF((OPR_2P!$J$12>=H11)*(OPR_2P!$K$12<=I11), OPR_2P!$A$12 & ", ", "") & IF((OPR_2P!$J$13>=H11)*(OPR_2P!$K$13<=I11), OPR_2P!$A$13 & ", ", "") & IF((OPR_2P!$J$14>=H11)*(OPR_2P!$K$14<=I11), OPR_2P!$A$14 & ", ", "") & IF((OPR_2P!$J$15>=H11)*(OPR_2P!$K$15<=I11), OPR_2P!$A$15 & ", ", "") & IF((OPR_2P!$J$16>=H11)*(OPR_2P!$K$16<=I11), OPR_2P!$A$16 & ", ", "") & IF((OPR_2P!$J$17>=H11)*(OPR_2P!$K$17<=I11), OPR_2P!$A$17 & ", ", "") & IF((OPR_2P!$J$18>=H11)*(OPR_2P!$K$18<=I11), OPR_2P!$A$18 & ", ", ""), LEN(IF((OPR_2P!$J$4>=H11)*(OPR_2P!$K$4<=I11), OPR_2P!$A$4 & ", ", "") & IF((OPR_2P!$J$5>=H11)*(OPR_2P!$K$5<=I11), OPR_2P!$A$5 & ", ", "") & IF((OPR_2P!$J$6>=H11)*(OPR_2P!$K$6<=I11), OPR_2P!$A$6 & ", ", "") & IF((OPR_2P!$J$7>=H11)*(OPR_2P!$K$7<=I11), OPR_2P!$A$7 & ", ", "") & IF((OPR_2P!$J$8>=H11)*(OPR_2P!$K$8<=I11), OPR_2P!$A$8 & ", ", "") & IF((OPR_2P!$J$9>=H11)*(OPR_2P!$K$9<=I11), OPR_2P!$A$9 & ", ", "") & IF((OPR_2P!$J$10>=H11)*(OPR_2P!$K$10<=I11), OPR_2P!$A$10 & ", ", "") & IF((OPR_2P!$J$11>=H11)*(OPR_2P!$K$11<=I11), OPR_2P!$A$11 & ", ", "") & IF((OPR_2P!$J$12>=H11)*(OPR_2P!$K$12<=I11), OPR_2P!$A$12 & ", ", "") & IF((OPR_2P!$J$13>=H11)*(OPR_2P!$K$13<=I11), OPR_2P!$A$13 & ", ", "") & IF((OPR_2P!$J$14>=H11)*(OPR_2P!$K$14<=I11), OPR_2P!$A$14 & ", ", "") & IF((OPR_2P!$J$15>=H11)*(OPR_2P!$K$15<=I11), OPR_2P!$A$15 & ", ", "") & IF((OPR_2P!$J$16>=H11)*(OPR_2P!$K$16<=I11), OPR_2P!$A$16 & ", ", "") & IF((OPR_2P!$J$17>=H11)*(OPR_2P!$K$17<=I11), OPR_2P!$A$17 & ", ", "") & IF((OPR_2P!$J$18>=H11)*(OPR_2P!$K$18<=I11), OPR_2P!$A$18 & ", ", ""))-2), "None") -> 9, 15, 17, 20, 25, 28, 30, 34, 42, 46, 50, 54, 57, 63, 70
A12: SPM | B12: SPM-MC-05 | C12: 46271 | D12: 6 | E12: 4 | F12: Active | G12: General Workman | H12: 100 | I12: 4500 | J12: =IFERROR(LEFT(IF((OPR_2P!$J$4>=H12)*(OPR_2P!$K$4<=I12), OPR_2P!$A$4 & ", ", "") & IF((OPR_2P!$J$5>=H12)*(OPR_2P!$K$5<=I12), OPR_2P!$A$5 & ", ", "") & IF((OPR_2P!$J$6>=H12)*(OPR_2P!$K$6<=I12), OPR_2P!$A$6 & ", ", "") & IF((OPR_2P!$J$7>=H12)*(OPR_2P!$K$7<=I12), OPR_2P!$A$7 & ", ", "") & IF((OPR_2P!$J$8>=H12)*(OPR_2P!$K$8<=I12), OPR_2P!$A$8 & ", ", "") & IF((OPR_2P!$J$9>=H12)*(OPR_2P!$K$9<=I12), OPR_2P!$A$9 & ", ", "") & IF((OPR_2P!$J$10>=H12)*(OPR_2P!$K$10<=I12), OPR_2P!$A$10 & ", ", "") & IF((OPR_2P!$J$11>=H12)*(OPR_2P!$K$11<=I12), OPR_2P!$A$11 & ", ", "") & IF((OPR_2P!$J$12>=H12)*(OPR_2P!$K$12<=I12), OPR_2P!$A$12 & ", ", "") & IF((OPR_2P!$J$13>=H12)*(OPR_2P!$K$13<=I12), OPR_2P!$A$13 & ", ", "") & IF((OPR_2P!$J$14>=H12)*(OPR_2P!$K$14<=I12), OPR_2P!$A$14 & ", ", "") & IF((OPR_2P!$J$15>=H12)*(OPR_2P!$K$15<=I12), OPR_2P!$A$15 & ", ", "") & IF((OPR_2P!$J$16>=H12)*(OPR_2P!$K$16<=I12), OPR_2P!$A$16 & ", ", "") & IF((OPR_2P!$J$17>=H12)*(OPR_2P!$K$17<=I12), OPR_2P!$A$17 & ", ", "") & IF((OPR_2P!$J$18>=H12)*(OPR_2P!$K$18<=I12), OPR_2P!$A$18 & ", ", ""), LEN(IF((OPR_2P!$J$4>=H12)*(OPR_2P!$K$4<=I12), OPR_2P!$A$4 & ", ", "") & IF((OPR_2P!$J$5>=H12)*(OPR_2P!$K$5<=I12), OPR_2P!$A$5 & ", ", "") & IF((OPR_2P!$J$6>=H12)*(OPR_2P!$K$6<=I12), OPR_2P!$A$6 & ", ", "") & IF((OPR_2P!$J$7>=H12)*(OPR_2P!$K$7<=I12), OPR_2P!$A$7 & ", ", "") & IF((OPR_2P!$J$8>=H12)*(OPR_2P!$K$8<=I12), OPR_2P!$A$8 & ", ", "") & IF((OPR_2P!$J$9>=H12)*(OPR_2P!$K$9<=I12), OPR_2P!$A$9 & ", ", "") & IF((OPR_2P!$J$10>=H12)*(OPR_2P!$K$10<=I12), OPR_2P!$A$10 & ", ", "") & IF((OPR_2P!$J$11>=H12)*(OPR_2P!$K$11<=I12), OPR_2P!$A$11 & ", ", "") & IF((OPR_2P!$J$12>=H12)*(OPR_2P!$K$12<=I12), OPR_2P!$A$12 & ", ", "") & IF((OPR_2P!$J$13>=H12)*(OPR_2P!$K$13<=I12), OPR_2P!$A$13 & ", ", "") & IF((OPR_2P!$J$14>=H12)*(OPR_2P!$K$14<=I12), OPR_2P!$A$14 & ", ", "") & IF((OPR_2P!$J$15>=H12)*(OPR_2P!$K$15<=I12), OPR_2P!$A$15 & ", ", "") & IF((OPR_2P!$J$16>=H12)*(OPR_2P!$K$16<=I12), OPR_2P!$A$16 & ", ", "") & IF((OPR_2P!$J$17>=H12)*(OPR_2P!$K$17<=I12), OPR_2P!$A$17 & ", ", "") & IF((OPR_2P!$J$18>=H12)*(OPR_2P!$K$18<=I12), OPR_2P!$A$18 & ", ", ""))-2), "None") -> 9, 15, 17, 20, 25, 28, 30, 34, 42, 46, 50, 54, 57, 63, 70
A13: SPM | B13: SPM-MC-06 | C13: 46176 | D13: 6 | E13: 4 | F13: Active | G13: General Workman | H13: 100 | I13: 4500 | J13: =IFERROR(LEFT(IF((OPR_2P!$J$4>=H13)*(OPR_2P!$K$4<=I13), OPR_2P!$A$4 & ", ", "") & IF((OPR_2P!$J$5>=H13)*(OPR_2P!$K$5<=I13), OPR_2P!$A$5 & ", ", "") & IF((OPR_2P!$J$6>=H13)*(OPR_2P!$K$6<=I13), OPR_2P!$A$6 & ", ", "") & IF((OPR_2P!$J$7>=H13)*(OPR_2P!$K$7<=I13), OPR_2P!$A$7 & ", ", "") & IF((OPR_2P!$J$8>=H13)*(OPR_2P!$K$8<=I13), OPR_2P!$A$8 & ", ", "") & IF((OPR_2P!$J$9>=H13)*(OPR_2P!$K$9<=I13), OPR_2P!$A$9 & ", ", "") & IF((OPR_2P!$J$10>=H13)*(OPR_2P!$K$10<=I13), OPR_2P!$A$10 & ", ", "") & IF((OPR_2P!$J$11>=H13)*(OPR_2P!$K$11<=I13), OPR_2P!$A$11 & ", ", "") & IF((OPR_2P!$J$12>=H13)*(OPR_2P!$K$12<=I13), OPR_2P!$A$12 & ", ", "") & IF((OPR_2P!$J$13>=H13)*(OPR_2P!$K$13<=I13), OPR_2P!$A$13 & ", ", "") & IF((OPR_2P!$J$14>=H13)*(OPR_2P!$K$14<=I13), OPR_2P!$A$14 & ", ", "") & IF((OPR_2P!$J$15>=H13)*(OPR_2P!$K$15<=I13), OPR_2P!$A$15 & ", ", "") & IF((OPR_2P!$J$16>=H13)*(OPR_2P!$K$16<=I13), OPR_2P!$A$16 & ", ", "") & IF((OPR_2P!$J$17>=H13)*(OPR_2P!$K$17<=I13), OPR_2P!$A$17 & ", ", "") & IF((OPR_2P!$J$18>=H13)*(OPR_2P!$K$18<=I13), OPR_2P!$A$18 & ", ", ""), LEN(IF((OPR_2P!$J$4>=H13)*(OPR_2P!$K$4<=I13), OPR_2P!$A$4 & ", ", "") & IF((OPR_2P!$J$5>=H13)*(OPR_2P!$K$5<=I13), OPR_2P!$A$5 & ", ", "") & IF((OPR_2P!$J$6>=H13)*(OPR_2P!$K$6<=I13), OPR_2P!$A$6 & ", ", "") & IF((OPR_2P!$J$7>=H13)*(OPR_2P!$K$7<=I13), OPR_2P!$A$7 & ", ", "") & IF((OPR_2P!$J$8>=H13)*(OPR_2P!$K$8<=I13), OPR_2P!$A$8 & ", ", "") & IF((OPR_2P!$J$9>=H13)*(OPR_2P!$K$9<=I13), OPR_2P!$A$9 & ", ", "") & IF((OPR_2P!$J$10>=H13)*(OPR_2P!$K$10<=I13), OPR_2P!$A$10 & ", ", "") & IF((OPR_2P!$J$11>=H13)*(OPR_2P!$K$11<=I13), OPR_2P!$A$11 & ", ", "") & IF((OPR_2P!$J$12>=H13)*(OPR_2P!$K$12<=I13), OPR_2P!$A$12 & ", ", "") & IF((OPR_2P!$J$13>=H13)*(OPR_2P!$K$13<=I13), OPR_2P!$A$13 & ", ", "") & IF((OPR_2P!$J$14>=H13)*(OPR_2P!$K$14<=I13), OPR_2P!$A$14 & ", ", "") & IF((OPR_2P!$J$15>=H13)*(OPR_2P!$K$15<=I13), OPR_2P!$A$15 & ", ", "") & IF((OPR_2P!$J$16>=H13)*(OPR_2P!$K$16<=I13), OPR_2P!$A$16 & ", ", "") & IF((OPR_2P!$J$17>=H13)*(OPR_2P!$K$17<=I13), OPR_2P!$A$17 & ", ", "") & IF((OPR_2P!$J$18>=H13)*(OPR_2P!$K$18<=I13), OPR_2P!$A$18 & ", ", ""))-2), "None") -> 9, 15, 17, 20, 25, 28, 30, 34, 42, 46, 50, 54, 57, 63, 70
A14: CARVING | B14: CARVING-MC-01 | C14: 46418 | D14: 6 | E14: 4 | F14: Active | G14: General Workman | H14: 100 | I14: 4500 | J14: =IFERROR(LEFT(IF((OPR_2P!$J$4>=H14)*(OPR_2P!$K$4<=I14), OPR_2P!$A$4 & ", ", "") & IF((OPR_2P!$J$5>=H14)*(OPR_2P!$K$5<=I14), OPR_2P!$A$5 & ", ", "") & IF((OPR_2P!$J$6>=H14)*(OPR_2P!$K$6<=I14), OPR_2P!$A$6 & ", ", "") & IF((OPR_2P!$J$7>=H14)*(OPR_2P!$K$7<=I14), OPR_2P!$A$7 & ", ", "") & IF((OPR_2P!$J$8>=H14)*(OPR_2P!$K$8<=I14), OPR_2P!$A$8 & ", ", "") & IF((OPR_2P!$J$9>=H14)*(OPR_2P!$K$9<=I14), OPR_2P!$A$9 & ", ", "") & IF((OPR_2P!$J$10>=H14)*(OPR_2P!$K$10<=I14), OPR_2P!$A$10 & ", ", "") & IF((OPR_2P!$J$11>=H14)*(OPR_2P!$K$11<=I14), OPR_2P!$A$11 & ", ", "") & IF((OPR_2P!$J$12>=H14)*(OPR_2P!$K$12<=I14), OPR_2P!$A$12 & ", ", "") & IF((OPR_2P!$J$13>=H14)*(OPR_2P!$K$13<=I14), OPR_2P!$A$13 & ", ", "") & IF((OPR_2P!$J$14>=H14)*(OPR_2P!$K$14<=I14), OPR_2P!$A$14 & ", ", "") & IF((OPR_2P!$J$15>=H14)*(OPR_2P!$K$15<=I14), OPR_2P!$A$15 & ", ", "") & IF((OPR_2P!$J$16>=H14)*(OPR_2P!$K$16<=I14), OPR_2P!$A$16 & ", ", "") & IF((OPR_2P!$J$17>=H14)*(OPR_2P!$K$17<=I14), OPR_2P!$A$17 & ", ", "") & IF((OPR_2P!$J$18>=H14)*(OPR_2P!$K$18<=I14), OPR_2P!$A$18 & ", ", ""), LEN(IF((OPR_2P!$J$4>=H14)*(OPR_2P!$K$4<=I14), OPR_2P!$A$4 & ", ", "") & IF((OPR_2P!$J$5>=H14)*(OPR_2P!$K$5<=I14), OPR_2P!$A$5 & ", ", "") & IF((OPR_2P!$J$6>=H14)*(OPR_2P!$K$6<=I14), OPR_2P!$A$6 & ", ", "") & IF((OPR_2P!$J$7>=H14)*(OPR_2P!$K$7<=I14), OPR_2P!$A$7 & ", ", "") & IF((OPR_2P!$J$8>=H14)*(OPR_2P!$K$8<=I14), OPR_2P!$A$8 & ", ", "") & IF((OPR_2P!$J$9>=H14)*(OPR_2P!$K$9<=I14), OPR_2P!$A$9 & ", ", "") & IF((OPR_2P!$J$10>=H14)*(OPR_2P!$K$10<=I14), OPR_2P!$A$10 & ", ", "") & IF((OPR_2P!$J$11>=H14)*(OPR_2P!$K$11<=I14), OPR_2P!$A$11 & ", ", "") & IF((OPR_2P!$J$12>=H14)*(OPR_2P!$K$12<=I14), OPR_2P!$A$12 & ", ", "") & IF((OPR_2P!$J$13>=H14)*(OPR_2P!$K$13<=I14), OPR_2P!$A$13 & ", ", "") & IF((OPR_2P!$J$14>=H14)*(OPR_2P!$K$14<=I14), OPR_2P!$A$14 & ", ", "") & IF((OPR_2P!$J$15>=H14)*(OPR_2P!$K$15<=I14), OPR_2P!$A$15 & ", ", "") & IF((OPR_2P!$J$16>=H14)*(OPR_2P!$K$16<=I14), OPR_2P!$A$16 & ", ", "") & IF((OPR_2P!$J$17>=H14)*(OPR_2P!$K$17<=I14), OPR_2P!$A$17 & ", ", "") & IF((OPR_2P!$J$18>=H14)*(OPR_2P!$K$18<=I14), OPR_2P!$A$18 & ", ", ""))-2), "None") -> 9, 15, 17, 20, 25, 28, 30, 34, 42, 46, 50, 54, 57, 63, 70
A15: CARVING | B15: CARVING-MC-02 | C15: 46282 | D15: 6 | E15: 4 | F15: Active | G15: General Workman | H15: 100 | I15: 4500 | J15: =IFERROR(LEFT(IF((OPR_2P!$J$4>=H15)*(OPR_2P!$K$4<=I15), OPR_2P!$A$4 & ", ", "") & IF((OPR_2P!$J$5>=H15)*(OPR_2P!$K$5<=I15), OPR_2P!$A$5 & ", ", "") & IF((OPR_2P!$J$6>=H15)*(OPR_2P!$K$6<=I15), OPR_2P!$A$6 & ", ", "") & IF((OPR_2P!$J$7>=H15)*(OPR_2P!$K$7<=I15), OPR_2P!$A$7 & ", ", "") & IF((OPR_2P!$J$8>=H15)*(OPR_2P!$K$8<=I15), OPR_2P!$A$8 & ", ", "") & IF((OPR_2P!$J$9>=H15)*(OPR_2P!$K$9<=I15), OPR_2P!$A$9 & ", ", "") & IF((OPR_2P!$J$10>=H15)*(OPR_2P!$K$10<=I15), OPR_2P!$A$10 & ", ", "") & IF((OPR_2P!$J$11>=H15)*(OPR_2P!$K$11<=I15), OPR_2P!$A$11 & ", ", "") & IF((OPR_2P!$J$12>=H15)*(OPR_2P!$K$12<=I15), OPR_2P!$A$12 & ", ", "") & IF((OPR_2P!$J$13>=H15)*(OPR_2P!$K$13<=I15), OPR_2P!$A$13 & ", ", "") & IF((OPR_2P!$J$14>=H15)*(OPR_2P!$K$14<=I15), OPR_2P!$A$14 & ", ", "") & IF((OPR_2P!$J$15>=H15)*(OPR_2P!$K$15<=I15), OPR_2P!$A$15 & ", ", "") & IF((OPR_2P!$J$16>=H15)*(OPR_2P!$K$16<=I15), OPR_2P!$A$16 & ", ", "") & IF((OPR_2P!$J$17>=H15)*(OPR_2P!$K$17<=I15), OPR_2P!$A$17 & ", ", "") & IF((OPR_2P!$J$18>=H15)*(OPR_2P!$K$18<=I15), OPR_2P!$A$18 & ", ", ""), LEN(IF((OPR_2P!$J$4>=H15)*(OPR_2P!$K$4<=I15), OPR_2P!$A$4 & ", ", "") & IF((OPR_2P!$J$5>=H15)*(OPR_2P!$K$5<=I15), OPR_2P!$A$5 & ", ", "") & IF((OPR_2P!$J$6>=H15)*(OPR_2P!$K$6<=I15), OPR_2P!$A$6 & ", ", "") & IF((OPR_2P!$J$7>=H15)*(OPR_2P!$K$7<=I15), OPR_2P!$A$7 & ", ", "") & IF((OPR_2P!$J$8>=H15)*(OPR_2P!$K$8<=I15), OPR_2P!$A$8 & ", ", "") & IF((OPR_2P!$J$9>=H15)*(OPR_2P!$K$9<=I15), OPR_2P!$A$9 & ", ", "") & IF((OPR_2P!$J$10>=H15)*(OPR_2P!$K$10<=I15), OPR_2P!$A$10 & ", ", "") & IF((OPR_2P!$J$11>=H15)*(OPR_2P!$K$11<=I15), OPR_2P!$A$11 & ", ", "") & IF((OPR_2P!$J$12>=H15)*(OPR_2P!$K$12<=I15), OPR_2P!$A$12 & ", ", "") & IF((OPR_2P!$J$13>=H15)*(OPR_2P!$K$13<=I15), OPR_2P!$A$13 & ", ", "") & IF((OPR_2P!$J$14>=H15)*(OPR_2P!$K$14<=I15), OPR_2P!$A$14 & ", ", "") & IF((OPR_2P!$J$15>=H15)*(OPR_2P!$K$15<=I15), OPR_2P!$A$15 & ", ", "") & IF((OPR_2P!$J$16>=H15)*(OPR_2P!$K$16<=I15), OPR_2P!$A$16 & ", ", "") & IF((OPR_2P!$J$17>=H15)*(OPR_2P!$K$17<=I15), OPR_2P!$A$17 & ", ", "") & IF((OPR_2P!$J$18>=H15)*(OPR_2P!$K$18<=I15), OPR_2P!$A$18 & ", ", ""))-2), "None") -> 9, 15, 17, 20, 25, 28, 30, 34, 42, 46, 50, 54, 57, 63, 70
... A86: QC | B86: QC-MC-05 | C86: 46373 | D86: 6 | E86: 4 | F86: Active | G86: General Workman | H86: 100 | I86: 4500 | J86: =IFERROR(LEFT(IF((OPR_2P!$J$4>=H86)*(OPR_2P!$K$4<=I86), OPR_2P!$A$4 & ", ", "") & IF((OPR_2P!$J$5>=H86)*(OPR_2P!$K$5<=I86), OPR_2P!$A$5 & ", ", "") & IF((OPR_2P!$J$6>=H86)*(OPR_2P!$K$6<=I86), OPR_2P!$A$6 & ", ", "") & IF((OPR_2P!$J$7>=H86)*(OPR_2P!$K$7<=I86), OPR_2P!$A$7 & ", ", "") & IF((OPR_2P!$J$8>=H86)*(OPR_2P!$K$8<=I86), OPR_2P!$A$8 & ", ", "") & IF((OPR_2P!$J$9>=H86)*(OPR_2P!$K$9<=I86), OPR_2P!$A$9 & ", ", "") & IF((OPR_2P!$J$10>=H86)*(OPR_2P!$K$10<=I86), OPR_2P!$A$10 & ", ", "") & IF((OPR_2P!$J$11>=H86)*(OPR_2P!$K$11<=I86), OPR_2P!$A$11 & ", ", "") & IF((OPR_2P!$J$12>=H86)*(OPR_2P!$K$12<=I86), OPR_2P!$A$12 & ", ", "") & IF((OPR_2P!$J$13>=H86)*(OPR_2P!$K$13<=I86), OPR_2P!$A$13 & ", ", "") & IF((OPR_2P!$J$14>=H86)*(OPR_2P!$K$14<=I86), OPR_2P!$A$14 & ", ", "") & IF((OPR_2P!$J$15>=H86)*(OPR_2P!$K$15<=I86), OPR_2P!$A$15 & ", ", "") & IF((OPR_2P!$J$16>=H86)*(OPR_2P!$K$16<=I86), OPR_2P!$A$16 & ", ", "") & IF((OPR_2P!$J$17>=H86)*(OPR_2P!$K$17<=I86), OPR_2P!$A$17 & ", ", "") & IF((OPR_2P!$J$18>=H86)*(OPR_2P!$K$18<=I86), OPR_2P!$A$18 & ", ", ""), LEN(IF((OPR_2P!$J$4>=H86)*(OPR_2P!$K$4<=I86), OPR_2P!$A$4 & ", ", "") & IF((OPR_2P!$J$5>=H86)*(OPR_2P!$K$5<=I86), OPR_2P!$A$5 & ", ", "") & IF((OPR_2P!$J$6>=H86)*(OPR_2P!$K$6<=I86), OPR_2P!$A$6 & ", ", "") & IF((OPR_2P!$J$7>=H86)*(OPR_2P!$K$7<=I86), OPR_2P!$A$7 & ", ", "") & IF((OPR_2P!$J$8>=H86)*(OPR_2P!$K$8<=I86), OPR_2P!$A$8 & ", ", "") & IF((OPR_2P!$J$9>=H86)*(OPR_2P!$K$9<=I86), OPR_2P!$A$9 & ", ", "") & IF((OPR_2P!$J$10>=H86)*(OPR_2P!$K$10<=I86), OPR_2P!$A$10 & ", ", "") & IF((OPR_2P!$J$11>=H86)*(OPR_2P!$K$11<=I86), OPR_2P!$A$11 & ", ", "") & IF((OPR_2P!$J$12>=H86)*(OPR_2P!$K$12<=I86), OPR_2P!$A$12 & ", ", "") & IF((OPR_2P!$J$13>=H86)*(OPR_2P!$K$13<=I86), OPR_2P!$A$13 & ", ", "") & IF((OPR_2P!$J$14>=H86)*(OPR_2P!$K$14<=I86), OPR_2P!$A$14 & ", ", "") & IF((OPR_2P!$J$15>=H86)*(OPR_2P!$K$15<=I86), OPR_2P!$A$15 & ", ", "") & IF((OPR_2P!$J$16>=H86)*(OPR_2P!$K$16<=I86), OPR_2P!$A$16 & ", ", "") & IF((OPR_2P!$J$17>=H86)*(OPR_2P!$K$17<=I86), OPR_2P!$A$17 & ", ", "") & IF((OPR_2P!$J$18>=H86)*(OPR_2P!$K$18<=I86), OPR_2P!$A$18 & ", ", ""))-2), "None") -> 9, 15, 17, 20, 25, 28, 30, 34, 42, 46, 50, 54, 57, 63, 70

Sheet Job_Master
A2: Global Start | B2: 46113.292 | J2: ← Type to override auto date
A3: Job ID | B3: Size | C3: Type | D3: No of Parts | E3: Overall Start | F3: Overall End | G3: Priority | H3: End Month | I3: Status | J3: Due Date | K3: Customer | L3: 46113 | M3: 46114 | N3: 46115 | O3: 46116 | P3: 46117 | Q3: 46118 | R3: 46119 | S3: 46120 | T3: 46121 | U3: 46122 | V3: 46123 | W3: 46124 | X3: 46125 | Y3: 46126 | Z3: 46127 | AA3: 46128 | AB3: 46129 | AC3: 46130 | AD3: 46131 | AE3: 46132 | AF3: 46133 | AG3: 46134 | AH3: 46135 | AI3: 46136 | AJ3: 46137 | AK3: 46138 | AL3: 46139 | AM3: 46140 | AN3: 46141 | AO3: 46142 | AP3: 46143 | AQ3: 46144 | AR3: 46145 | AS3: 46146 | AT3: 46147 | AU3: 46148 | AV3: 46149 | AW3: 46150 | AX3: 46151 | AY3: 46152 | AZ3: 46153 | BA3: 46154 | BB3: 46155 | BC3: 46156 | BD3: 46157 | BE3: 46158 | BF3: 46159 | BG3: 46160 | BH3: 46161 | BI3: 46162 | BJ3: 46163 | BK3: 46164 | BL3: 46165 | BM3: 46166 | BN3: 46167 | BO3: 46168 | BP3: 46169 | BQ3: 46170 | BR3: 46171
A4: BJ-104 | B4: 28 | C4: 2P | D4: =IF($A4="","",IFERROR(CHOOSE(MATCH($C4,Settings!$L$4:$L$10,0),OPR_2P!$B$2,SEG_6P!$B$2,SOL_4P!$B$2,RW_2P!$B$2,RW2_4P!$B$2,FLAP_4P!$B$2,TUBE_4P!$B$2),2)) -> 2 | E4: =IF($A4="","",VTL_Plan!$J4) -> 46113.292 | F4: =IF($A4="","",QC_Plan!$M4) -> 46132.339 | G4: Medium | H4: =IF($A4="","",TEXT(QC_Plan!M4,"MMM-YYYY")) -> Apr-2026 | I4: Released | J4: =IF($A4="","",F4+30) -> 46162.339 | K4: Alpha Corp
A5: BJ-101 | B5: 42 | C5: SOL | D5: =IF($A5="","",IFERROR(CHOOSE(MATCH($C5,Settings!$L$4:$L$10,0),OPR_2P!$B$2,SEG_6P!$B$2,SOL_4P!$B$2,RW_2P!$B$2,RW2_4P!$B$2,FLAP_4P!$B$2,TUBE_4P!$B$2),2)) -> 4 | E5: =IF($A5="","",VTL_Plan!$J5) -> 46113.292 | F5: =IF($A5="","",QC_Plan!$M5) -> 46170.368 | G5: Medium | H5: =IF($A5="","",TEXT(QC_Plan!M5,"MMM-YYYY")) -> May-2026 | I5: On Hold | J5: =IF($A5="","",F5+30) -> 46200.368 | K5: Beta Ltd
A6: BJ-105 | B6: 28 | C6: RW | D6: =IF($A6="","",IFERROR(CHOOSE(MATCH($C6,Settings!$L$4:$L$10,0),OPR_2P!$B$2,SEG_6P!$B$2,SOL_4P!$B$2,RW_2P!$B$2,RW2_4P!$B$2,FLAP_4P!$B$2,TUBE_4P!$B$2),2)) -> 2 | E6: =IF($A6="","",VTL_Plan!$J6) -> 46115.884 | F6: =IF($A6="","",QC_Plan!$M6) -> 46173.517 | G6: Medium | H6: =IF($A6="","",TEXT(QC_Plan!M6,"MMM-YYYY")) -> May-2026 | I6: Released | J6: =IF($A6="","",F6+30) -> 46203.517 | K6: Alpha Corp
A7: BJ-100 | B7: 25 | C7: SEG | D7: =IF($A7="","",IFERROR(CHOOSE(MATCH($C7,Settings!$L$4:$L$10,0),OPR_2P!$B$2,SEG_6P!$B$2,SOL_4P!$B$2,RW_2P!$B$2,RW2_4P!$B$2,FLAP_4P!$B$2,TUBE_4P!$B$2),2)) -> 6 | E7: =IF($A7="","",VTL_Plan!$J7) -> 46118.477 | F7: =IF($A7="","",QC_Plan!$M7) -> 46184.519 | G7: Low | H7: =IF($A7="","",TEXT(QC_Plan!M7,"MMM-YYYY")) -> Jun-2026 | I7: Released | J7: =IF($A7="","",F7+30) -> 46214.519 | K7: Gamma Inc
A8: BJ-102 | B8: 34 | C8: SEG | D8: =IF($A8="","",IFERROR(CHOOSE(MATCH($C8,Settings!$L$4:$L$10,0),OPR_2P!$B$2,SEG_6P!$B$2,SOL_4P!$B$2,RW_2P!$B$2,RW2_4P!$B$2,FLAP_4P!$B$2,TUBE_4P!$B$2),2)) -> 6 | E8: =IF($A8="","",VTL_Plan!$J8) -> 46121.069 | F8: =IF($A8="","",QC_Plan!$M8) -> 46208.943 | G8: Medium | H8: =IF($A8="","",TEXT(QC_Plan!M8,"MMM-YYYY")) -> Jul-2026 | I8: Cancelled | J8: =IF($A8="","",F8+30) -> 46238.943 | K8: Beta Ltd
A9: BJ-103 | B9: 20 | C9: RW | D9: =IF($A9="","",IFERROR(CHOOSE(MATCH($C9,Settings!$L$4:$L$10,0),OPR_2P!$B$2,SEG_6P!$B$2,SOL_4P!$B$2,RW_2P!$B$2,RW2_4P!$B$2,FLAP_4P!$B$2,TUBE_4P!$B$2),2)) -> 2 | E9: =IF($A9="","",VTL_Plan!$J9) -> 46125.421 | F9: =IF($A9="","",QC_Plan!$M9) -> 46210.702 | G9: Low | H9: =IF($A9="","",TEXT(QC_Plan!M9,"MMM-YYYY")) -> Jul-2026 | I9: Released | J9: =IF($A9="","",F9+30) -> 46240.702 | K9: Delta Co
A10: BJ-108 | B10: 70 | C10: RW | D10: =IF($A10="","",IFERROR(CHOOSE(MATCH($C10,Settings!$L$4:$L$10,0),OPR_2P!$B$2,SEG_6P!$B$2,SOL_4P!$B$2,RW_2P!$B$2,RW2_4P!$B$2,FLAP_4P!$B$2,TUBE_4P!$B$2),2)) -> 2 | E10: =IF($A10="","",VTL_Plan!$J10) -> 46113.292 | F10: =IF($A10="","",QC_Plan!$M10) -> 46219.591 | G10: High | H10: =IF($A10="","",TEXT(QC_Plan!M10,"MMM-YYYY")) -> Jul-2026 | I10: Released | J10: =IF($A10="","",F10+30) -> 46249.591 | K10: Alpha Corp
A11: BJ-106 | B11: 15 | C11: RW | D11: =IF($A11="","",IFERROR(CHOOSE(MATCH($C11,Settings!$L$4:$L$10,0),OPR_2P!$B$2,SEG_6P!$B$2,SOL_4P!$B$2,RW_2P!$B$2,RW2_4P!$B$2,FLAP_4P!$B$2,TUBE_4P!$B$2),2)) -> 2 | E11: =IF($A11="","",VTL_Plan!$J11) -> 46127.273 | F11: =IF($A11="","",QC_Plan!$M11) -> 46220.239 | G11: Low | H11: =IF($A11="","",TEXT(QC_Plan!M11,"MMM-YYYY")) -> Jul-2026 | I11: On Hold | J11: =IF($A11="","",F11+30) -> 46250.239 | K11: Gamma Inc
A12: BJ-109 | B12: 30 | C12: RW | D12: =IF($A12="","",IFERROR(CHOOSE(MATCH($C12,Settings!$L$4:$L$10,0),OPR_2P!$B$2,SEG_6P!$B$2,SOL_4P!$B$2,RW_2P!$B$2,RW2_4P!$B$2,FLAP_4P!$B$2,TUBE_4P!$B$2),2)) -> 2 | E12: =IF($A12="","",VTL_Plan!$J12) -> 46130.514 | F12: =IF($A12="","",QC_Plan!$M12) -> 46223.48 | G12: Medium | H12: =IF($A12="","",TEXT(QC_Plan!M12,"MMM-YYYY")) -> Jul-2026 | I12: Released | J12: =IF($A12="","",F12+30) -> 46253.48 | K12: Beta Ltd
A13: BJ-110 | B13: 17 | C13: 2P | D13: =IF($A13="","",IFERROR(CHOOSE(MATCH($C13,Settings!$L$4:$L$10,0),OPR_2P!$B$2,SEG_6P!$B$2,SOL_4P!$B$2,RW_2P!$B$2,RW2_4P!$B$2,FLAP_4P!$B$2,TUBE_4P!$B$2),2)) -> 2 | E13: =IF($A13="","",VTL_Plan!$J13) -> 46128.662 | F13: =IF($A13="","",QC_Plan!$M13) -> 46224.684 | G13: Low | H13: =IF($A13="","",TEXT(QC_Plan!M13,"MMM-YYYY")) -> Jul-2026 | I13: Released | J13: =IF($A13="","",F13+30) -> 46254.684 | K13: Delta Co
A14: BJ-111 | B14: 25 | C14: RW | D14: =IF($A14="","",IFERROR(CHOOSE(MATCH($C14,Settings!$L$4:$L$10,0),OPR_2P!$B$2,SEG_6P!$B$2,SOL_4P!$B$2,RW_2P!$B$2,RW2_4P!$B$2,FLAP_4P!$B$2,TUBE_4P!$B$2),2)) -> 2 | E14: =IF($A14="","",VTL_Plan!$J14) -> 46130.236 | F14: =IF($A14="","",QC_Plan!$M14) -> 46226.165 | G14: Low | H14: =IF($A14="","",TEXT(QC_Plan!M14,"MMM-YYYY")) -> Jul-2026 | I14: Released | J14: =IF($A14="","",F14+30) -> 46256.165 | K14: Alpha Corp
A15: BJ-107 | B15: 20 | C15: SEG | D15: =IF($A15="","",IFERROR(CHOOSE(MATCH($C15,Settings!$L$4:$L$10,0),OPR_2P!$B$2,SEG_6P!$B$2,SOL_4P!$B$2,RW_2P!$B$2,RW2_4P!$B$2,FLAP_4P!$B$2,TUBE_4P!$B$2),2)) -> 6 | E15: =IF($A15="","",VTL_Plan!$J15) -> 46132.551 | F15: =IF($A15="","",QC_Plan!$M15) -> 46232.276 | G15: Low | H15: =IF($A15="","",TEXT(QC_Plan!M15,"MMM-YYYY")) -> Jul-2026 | I15: On Hold | J15: =IF($A15="","",F15+30) -> 46262.276 | K15: Beta Ltd
... A73: BJ-169 | B73: 17 | C73: SEG | D73: =IF($A73="","",IFERROR(CHOOSE(MATCH($C73,Settings!$L$4:$L$10,0),OPR_2P!$B$2,SEG_6P!$B$2,SOL_4P!$B$2,RW_2P!$B$2,RW2_4P!$B$2,FLAP_4P!$B$2,TUBE_4P!$B$2),2)) -> 6 | E73: =IF($A73="","",VTL_Plan!$J73) -> 46196.532 | F73: =IF($A73="","",QC_Plan!$M73) -> 46670.534 | G73: Low | H73: =IF($A73="","",TEXT(QC_Plan!M73,"MMM-YYYY")) -> Oct-2027 | I73: Released | J73: =IF($A73="","",F73+30) -> 46700.534 | K73: Delta Co
H74: =IF($A74="","",TEXT(QC_Plan!M74,"MMM-YYYY"))
H75: =IF($A75="","",TEXT(QC_Plan!M75,"MMM-YYYY"))
H76: =IF($A76="","",TEXT(QC_Plan!M76,"MMM-YYYY"))
H77: =IF($A77="","",TEXT(QC_Plan!M77,"MMM-YYYY"))
H78: =IF($A78="","",TEXT(QC_Plan!M78,"MMM-YYYY"))
H79: =IF($A79="","",TEXT(QC_Plan!M79,"MMM-YYYY"))
H80: =IF($A80="","",TEXT(QC_Plan!M80,"MMM-YYYY"))
H81: =IF($A81="","",TEXT(QC_Plan!M81,"MMM-YYYY"))
H82: =IF($A82="","",TEXT(QC_Plan!M82,"MMM-YYYY"))
H83: =IF($A83="","",TEXT(QC_Plan!M83,"MMM-YYYY"))
H84: =IF($A84="","",TEXT(QC_Plan!M84,"MMM-YYYY"))
H85: =IF($A85="","",TEXT(QC_Plan!M85,"MMM-YYYY"))
... H103: =IF($A103="","",TEXT(QC_Plan!M103,"MMM-YYYY"))
D104: =IF(A104="","",IF(C104="2P",OPR_2P!B$2,IF(C104="SEG",SEG_6P!B$2,IF(C104="SOL",SOL_4P!B$2,IF(C104="RW",RW_2P!B$2,IF(C104="RW2",RW2_4P!B$2,0)))))) | F104: =IF(A104="","", QC_Plan!M104) | G104: =IF(B104="","",IF(H104>1000,"High",IF(H104>500,"Medium","Low")))
D105: =IF(A105="","",IF(C105="2P",OPR_2P!B$2,IF(C105="SEG",SEG_6P!B$2,IF(C105="SOL",SOL_4P!B$2,IF(C105="RW",RW_2P!B$2,IF(C105="RW2",RW2_4P!B$2,0)))))) | F105: =IF(A105="","", QC_Plan!M105) | G105: =IF(B105="","",IF(H105>1000,"High",IF(H105>500,"Medium","Low")))
D106: =IF(A106="","",IF(C106="2P",OPR_2P!B$2,IF(C106="SEG",SEG_6P!B$2,IF(C106="SOL",SOL_4P!B$2,IF(C106="RW",RW_2P!B$2,IF(C106="RW2",RW2_4P!B$2,0)))))) | F106: =IF(A106="","", QC_Plan!M106) | G106: =IF(B106="","",IF(H106>1000,"High",IF(H106>500,"Medium","Low")))
D107: =IF(A107="","",IF(C107="2P",OPR_2P!B$2,IF(C107="SEG",SEG_6P!B$2,IF(C107="SOL",SOL_4P!B$2,IF(C107="RW",RW_2P!B$2,IF(C107="RW2",RW2_4P!B$2,0)))))) | F107: =IF(A107="","", QC_Plan!M107) | G107: =IF(B107="","",IF(H107>1000,"High",IF(H107>500,"Medium","Low")))
D108: =IF(A108="","",IF(C108="2P",OPR_2P!B$2,IF(C108="SEG",SEG_6P!B$2,IF(C108="SOL",SOL_4P!B$2,IF(C108="RW",RW_2P!B$2,IF(C108="RW2",RW2_4P!B$2,0)))))) | F108: =IF(A108="","", QC_Plan!M108) | G108: =IF(B108="","",IF(H108>1000,"High",IF(H108>500,"Medium","Low")))
D109: =IF(A109="","",IF(C109="2P",OPR_2P!B$2,IF(C109="SEG",SEG_6P!B$2,IF(C109="SOL",SOL_4P!B$2,IF(C109="RW",RW_2P!B$2,IF(C109="RW2",RW2_4P!B$2,0)))))) | F109: =IF(A109="","", QC_Plan!M109) | G109: =IF(B109="","",IF(H109>1000,"High",IF(H109>500,"Medium","Low")))
D110: =IF(A110="","",IF(C110="2P",OPR_2P!B$2,IF(C110="SEG",SEG_6P!B$2,IF(C110="SOL",SOL_4P!B$2,IF(C110="RW",RW_2P!B$2,IF(C110="RW2",RW2_4P!B$2,0)))))) | F110: =IF(A110="","", QC_Plan!M110) | G110: =IF(B110="","",IF(H110>1000,"High",IF(H110>500,"Medium","Low")))
D111: =IF(A111="","",IF(C111="2P",OPR_2P!B$2,IF(C111="SEG",SEG_6P!B$2,IF(C111="SOL",SOL_4P!B$2,IF(C111="RW",RW_2P!B$2,IF(C111="RW2",RW2_4P!B$2,0)))))) | F111: =IF(A111="","", QC_Plan!M111) | G111: =IF(B111="","",IF(H111>1000,"High",IF(H111>500,"Medium","Low")))
D112: =IF(A112="","",IF(C112="2P",OPR_2P!B$2,IF(C112="SEG",SEG_6P!B$2,IF(C112="SOL",SOL_4P!B$2,IF(C112="RW",RW_2P!B$2,IF(C112="RW2",RW2_4P!B$2,0)))))) | F112: =IF(A112="","", QC_Plan!M112) | G112: =IF(B112="","",IF(H112>1000,"High",IF(H112>500,"Medium","Low")))
D113: =IF(A113="","",IF(C113="2P",OPR_2P!B$2,IF(C113="SEG",SEG_6P!B$2,IF(C113="SOL",SOL_4P!B$2,IF(C113="RW",RW_2P!B$2,IF(C113="RW2",RW2_4P!B$2,0)))))) | F113: =IF(A113="","", QC_Plan!M113) | G113: =IF(B113="","",IF(H113>1000,"High",IF(H113>500,"Medium","Low")))
D114: =IF(A114="","",IF(C114="2P",OPR_2P!B$2,IF(C114="SEG",SEG_6P!B$2,IF(C114="SOL",SOL_4P!B$2,IF(C114="RW",RW_2P!B$2,IF(C114="RW2",RW2_4P!B$2,0)))))) | F114: =IF(A114="","", QC_Plan!M114) | G114: =IF(B114="","",IF(H114>1000,"High",IF(H114>500,"Medium","Low")))
D115: =IF(A115="","",IF(C115="2P",OPR_2P!B$2,IF(C115="SEG",SEG_6P!B$2,IF(C115="SOL",SOL_4P!B$2,IF(C115="RW",RW_2P!B$2,IF(C115="RW2",RW2_4P!B$2,0)))))) | F115: =IF(A115="","", QC_Plan!M115) | G115: =IF(B115="","",IF(H115>1000,"High",IF(H115>500,"Medium","Low")))
...

Sheet VTL_Plan
BX1: VTL — Monthly Load vs Capacity
BX2: Apr-2026 | BY2: May-2026 | BZ2: Jun-2026 | CA2: Jul-2026 | CB2: Aug-2026 | CC2: Sep-2026 | CD2: Oct-2026 | CE2: Nov-2026 | CF2: Dec-2026 | CG2: Jan-2027
A3: Job ID | B3: Size | C3: Type | D3: Parts | E3: Allocated Machine | F3: Worker | G3: PM Date | H3: PM Hrs | I3: Override | J3: Start Date | K3: Unit CT | L3: Total Load | M3: End Date | N3: Shift | Time | O3: Machine Helper (Pick Compatible) | P3: 46113 | Q3: 46114 | R3: 46115 | S3: 46116 | T3: 46117 | U3: 46118 | V3: 46119 | W3: 46120 | X3: 46121 | Y3: 46122 | Z3: 46123 | AA3: 46124 | AB3: 46125 | AC3: 46126 | AD3: 46127 | AE3: 46128 | AF3: 46129 | AG3: 46130 | AH3: 46131 | AI3: 46132 | AJ3: 46133 | AK3: 46134 | AL3: 46135 | AM3: 46136 | AN3: 46137 | AO3: 46138 | AP3: 46139 | AQ3: 46140 | AR3: 46141 | AS3: 46142 | AT3: 46143 | AU3: 46144 | AV3: 46145 | AW3: 46146 | AX3: 46147 | AY3: 46148 | AZ3: 46149 | BA3: 46150 | BB3: 46151 | BC3: 46152 | BD3: 46153 | BE3: 46154 | BF3: 46155 | BG3: 46156 | BH3: 46157 | BI3: 46158 | BJ3: 46159 | BK3: 46160 | BL3: 46161 | BM3: 46162 | BN3: 46163 | BO3: 46164 | BP3: 46165 | BQ3: 46166 | BR3: 46167 | BS3: 46168 | BT3: 46169 | BU3: 46170 | BV3: 46171 | BW3: Load (Hrs) | BX3: 3330 | BY3: 1678 | BZ3: 1614 | CA3: 1842 | CB3: 780 | CC3: 828 | CD3: 552 | CE3: 0 | CF3: 0 | CG3: 0
A4: =IF(Job_Master!A4="","",Job_Master!A4) -> BJ-104 | B4: =IF($A4="","",Job_Master!B4) -> 28 | C4: =IF($A4="","",Job_Master!C4) -> 2P | D4: =IF($A4="","",Job_Master!D4) -> 2 | E4: =IF($A4="","",IFERROR(INDEX(Machine_List!$B$4:$B$7,MATCH("*"&$B4&"*",Machine_List!$J$4:$J$7,0)),"NO COMPATIBLE MACHINE")) -> VTL-MC-01 | F4: =IF($E4="","",IFERROR(VLOOKUP($E4,Machine_List!$B:$G,6,0),"")) -> General Workman | G4: =IF($E4="","",IFERROR(VLOOKUP($E4,Machine_List!$B:$C,2,0),"")) -> 46133 | H4: =IF($E4="","",IFERROR(VLOOKUP($E4,Machine_List!$B:$D,3,0),"")) -> 6 | J4: =IF($A4="","",IF($I4<>"",$I4,MAX(GlobalStartDate,IFERROR(LOOKUP(2,1/($E$3:INDIRECT("E"&(ROW()-1))=$E4),$M$3:INDIRECT("M"&(ROW()-1))),GlobalStartDate)))) -> 46113.292 | K4: =IF($A4="","",IFERROR(VLOOKUP(B4,CHOOSE(MATCH(C4,Settings!$L$4:$L$10,0),OPR_2P!$A$4:$I$18,SEG_6P!$A$4:$I$18,SOL_4P!$A$4:$I$18,RW_2P!$A$4:$I$18,RW2_4P!$A$4:$I$18,FLAP_4P!$A$4:$I$18,TUBE_4P!$A$4:$I$18),1,0),0)) -> 28 | L4: =IF($A4="","",K4*D4) -> 56 | M4: =IF($A4="","",IF(AND(ISNUMBER(G4),G4>=J4,G4<=(J4+(L4/(IF(F4="Contract Workman",Settings!$K$5,Settings!$K$4))))),J4+(L4/(IF(F4="Contract Workman",Settings!$K$5,Settings!$K$4)))+(H4/(IF(F4="Contract Workman",Settings!$K$5,Settings!$K$4))),J4+(L4/(IF(F4="Contract Workman",Settings!$K$5,Settings!$K$4))))) -> 46115.884 | N4: =IF($A4="","",IF(F4="Contract Workman",IF(AND(MOD(M4,1)>=8/24,MOD(M4,1)<20/24),"Shift S1","Shift S2"),IF(AND(MOD(M4,1)>=7/24,MOD(M4,1)<15/24),"Shift A",IF(AND(MOD(M4,1)>=15/24,MOD(M4,1)<23/24),"Shift B","Shift C")))) -> Shift B | O4: =IF(B4="","", IF(IFERROR(ISNUMBER(SEARCH(B4, VLOOKUP(E4, Machine_List!$B:$J, 9, 0))), FALSE()), "✅ Machine OK", "❌ Sug: " & IFERROR(INDEX(Machine_List!$B$4:$B$50, MATCH("*"&B4&"*", Machine_List!$J$4:$J$50, 0)), "Check Limits"))) -> ✅ Machine OK | BW4: Capacity (Hrs) | BX4: 2592 | BY4: 2678.4 | BZ4: 2592 | CA4: 2678.4 | CB4: 2678.4 | CC4: 2592 | CD4: 2678.4 | CE4: 2592 | CF4: 2678.4 | CG4: 2678.4
A5: =IF(Job_Master!A5="","",Job_Master!A5) -> BJ-101 | B5: =IF($A5="","",Job_Master!B5) -> 42 | C5: =IF($A5="","",Job_Master!C5) -> SOL | D5: =IF($A5="","",Job_Master!D5) -> 4 | E5: =IF($A5="","",IFERROR(INDEX(Machine_List!$B$4:$B$7,MATCH("*"&$B5&"*",Machine_List!$J$4:$J$7,0)),"NO COMPATIBLE MACHINE")) -> VTL-MC-02 | F5: =IF($E5="","",IFERROR(VLOOKUP($E5,Machine_List!$B:$G,6,0),"")) -> General Workman | G5: =IF($E5="","",IFERROR(VLOOKUP($E5,Machine_List!$B:$C,2,0),"")) -> 46521 | H5: =IF($E5="","",IFERROR(VLOOKUP($E5,Machine_List!$B:$D,3,0),"")) -> 6 | J5: =IF($A5="","",IF($I5<>"",$I5,MAX(GlobalStartDate,IFERROR(LOOKUP(2,1/($E$3:INDIRECT("E"&(ROW()-1))=$E5),$M$3:INDIRECT("M"&(ROW()-1))),GlobalStartDate)))) -> 46113.292 | K5: =IF($A5="","",IFERROR(VLOOKUP(B5,CHOOSE(MATCH(C5,Settings!$L$4:$L$10,0),OPR_2P!$A$4:$I$18,SEG_6P!$A$4:$I$18,SOL_4P!$A$4:$I$18,RW_2P!$A$4:$I$18,RW2_4P!$A$4:$I$18,FLAP_4P!$A$4:$I$18,TUBE_4P!$A$4:$I$18),1,0),0)) -> 42 | L5: =IF($A5="","",K5*D5) -> 168 | M5: =IF($A5="","",IF(AND(ISNUMBER(G5),G5>=J5,G5<=(J5+(L5/(IF(F5="Contract Workman",Settings!$K$5,Settings!$K$4))))),J5+(L5/(IF(F5="Contract Workman",Settings!$K$5,Settings!$K$4)))+(H5/(IF(F5="Contract Workman",Settings!$K$5,Settings!$K$4))),J5+(L5/(IF(F5="Contract Workman",Settings!$K$5,Settings!$K$4))))) -> 46121.069 | N5: =IF($A5="","",IF(F5="Contract Workman",IF(AND(MOD(M5,1)>=8/24,MOD(M5,1)<20/24),"Shift S1","Shift S2"),IF(AND(MOD(M5,1)>=7/24,MOD(M5,1)<15/24),"Shift A",IF(AND(MOD(M5,1)>=15/24,MOD(M5,1)<23/24),"Shift B","Shift C")))) -> Shift C | O5: =IF(B5="","", IF(IFERROR(ISNUMBER(SEARCH(B5, VLOOKUP(E5, Machine_List!$B:$J, 9, 0))), FALSE()), "✅ Machine OK", "❌ Sug: " & IFERROR(INDEX(Machine_List!$B$4:$B$50, MATCH("*"&B5&"*", Machine_List!$J$4:$J$50, 0)), "Check Limits"))) -> ✅ Machine OK
A6: =IF(Job_Master!A6="","",Job_Master!A6) -> BJ-105 | B6: =IF($A6="","",Job_Master!B6) -> 28 | C6: =IF($A6="","",Job_Master!C6) -> RW | D6: =IF($A6="","",Job_Master!D6) -> 2 | E6: =IF($A6="","",IFERROR(INDEX(Machine_List!$B$4:$B$7,MATCH("*"&$B6&"*",Machine_List!$J$4:$J$7,0)),"NO COMPATIBLE MACHINE")) -> VTL-MC-01 | F6: =IF($E6="","",IFERROR(VLOOKUP($E6,Machine_List!$B:$G,6,0),"")) -> General Workman | G6: =IF($E6="","",IFERROR(VLOOKUP($E6,Machine_List!$B:$C,2,0),"")) -> 46133 | H6: =IF($E6="","",IFERROR(VLOOKUP($E6,Machine_List!$B:$D,3,0),"")) -> 6 | J6: =IF($A6="","",IF($I6<>"",$I6,MAX(GlobalStartDate,IFERROR(LOOKUP(2,1/($E$3:INDIRECT("E"&(ROW()-1))=$E6),$M$3:INDIRECT("M"&(ROW()-1))),GlobalStartDate)))) -> 46115.884 | K6: =IF($A6="","",IFERROR(VLOOKUP(B6,CHOOSE(MATCH(C6,Settings!$L$4:$L$10,0),OPR_2P!$A$4:$I$18,SEG_6P!$A$4:$I$18,SOL_4P!$A$4:$I$18,RW_2P!$A$4:$I$18,RW2_4P!$A$4:$I$18,FLAP_4P!$A$4:$I$18,TUBE_4P!$A$4:$I$18),1,0),0)) -> 28 | L6: =IF($A6="","",K6*D6) -> 56 | M6: =IF($A6="","",IF(AND(ISNUMBER(G6),G6>=J6,G6<=(J6+(L6/(IF(F6="Contract Workman",Settings!$K$5,Settings!$K$4))))),J6+(L6/(IF(F6="Contract Workman",Settings!$K$5,Settings!$K$4)))+(H6/(IF(F6="Contract Workman",Settings!$K$5,Settings!$K$4))),J6+(L6/(IF(F6="Contract Workman",Settings!$K$5,Settings!$K$4))))) -> 46118.477 | N6: =IF($A6="","",IF(F6="Contract Workman",IF(AND(MOD(M6,1)>=8/24,MOD(M6,1)<20/24),"Shift S1","Shift S2"),IF(AND(MOD(M6,1)>=7/24,MOD(M6,1)<15/24),"Shift A",IF(AND(MOD(M6,1)>=15/24,MOD(M6,1)<23/24),"Shift B","Shift C")))) -> Shift A | O6: =IF(B6="","", IF(IFERROR(ISNUMBER(SEARCH(B6, VLOOKUP(E6, Machine_List!$B:$J, 9, 0))), FALSE()), "✅ Machine OK", "❌ Sug: " & IFERROR(INDEX(Machine_List!$B$4:$B$50, MATCH("*"&B6&"*", Machine_List!$J$4:$J$50, 0)), "Check Limits"))) -> ✅ Machine OK
A7: =IF(Job_Master!A7="","",Job_Master!A7) -> BJ-100 | B7: =IF($A7="","",Job_Master!B7) -> 25 | C7: =IF($A7="","",Job_Master!C7) -> SEG | D7: =IF($A7="","",Job_Master!D7) -> 6 | E7: =IF($A7="","",IFERROR(INDEX(Machine_List!$B$4:$B$7,MATCH("*"&$B7&"*",Machine_List!$J$4:$J$7,0)),"NO COMPATIBLE MACHINE")) -> VTL-MC-01 | F7: =IF($E7="","",IFERROR(VLOOKUP($E7,Machine_List!$B:$G,6,0),"")) -> General Workman | G7: =IF($E7="","",IFERROR(VLOOKUP($E7,Machine_List!$B:$C,2,0),"")) -> 46133 | H7: =IF($E7="","",IFERROR(VLOOKUP($E7,Machine_List!$B:$D,3,0),"")) -> 6 | J7: =IF($A7="","",IF($I7<>"",$I7,MAX(GlobalStartDate,IFERROR(LOOKUP(2,1/($E$3:INDIRECT("E"&(ROW()-1))=$E7),$M$3:INDIRECT("M"&(ROW()-1))),GlobalStartDate)))) -> 46118.477 | K7: =IF($A7="","",IFERROR(VLOOKUP(B7,CHOOSE(MATCH(C7,Settings!$L$4:$L$10,0),OPR_2P!$A$4:$I$18,SEG_6P!$A$4:$I$18,SOL_4P!$A$4:$I$18,RW_2P!$A$4:$I$18,RW2_4P!$A$4:$I$18,FLAP_4P!$A$4:$I$18,TUBE_4P!$A$4:$I$18),1,0),0)) -> 25 | L7: =IF($A7="","",K7*D7) -> 150 | M7: =IF($A7="","",IF(AND(ISNUMBER(G7),G7>=J7,G7<=(J7+(L7/(IF(F7="Contract Workman",Settings!$K$5,Settings!$K$4))))),J7+(L7/(IF(F7="Contract Workman",Settings!$K$5,Settings!$K$4)))+(H7/(IF(F7="Contract Workman",Settings!$K$5,Settings!$K$4))),J7+(L7/(IF(F7="Contract Workman",Settings!$K$5,Settings!$K$4))))) -> 46125.421 | N7: =IF($A7="","",IF(F7="Contract Workman",IF(AND(MOD(M7,1)>=8/24,MOD(M7,1)<20/24),"Shift S1","Shift S2"),IF(AND(MOD(M7,1)>=7/24,MOD(M7,1)<15/24),"Shift A",IF(AND(MOD(M7,1)>=15/24,MOD(M7,1)<23/24),"Shift B","Shift C")))) -> Shift A | O7: =IF(B7="","", IF(IFERROR(ISNUMBER(SEARCH(B7, VLOOKUP(E7, Machine_List!$B:$J, 9, 0))), FALSE()), "✅ Machine OK", "❌ Sug: " & IFERROR(INDEX(Machine_List!$B$4:$B$50, MATCH("*"&B7&"*", Machine_List!$J$4:$J$50, 0)), "Check Limits"))) -> ✅ Machine OK
A8: =IF(Job_Master!A8="","",Job_Master!A8) -> BJ-102 | B8: =IF($A8="","",Job_Master!B8) -> 34 | C8: =IF($A8="","",Job_Master!C8) -> SEG | D8: =IF($A8="","",Job_Master!D8) -> 6 | E8: =IF($A8="","",IFERROR(INDEX(Machine_List!$B$4:$B$7,MATCH("*"&$B8&"*",Machine_List!$J$4:$J$7,0)),"NO COMPATIBLE MACHINE")) -> VTL-MC-02 | F8: =IF($E8="","",IFERROR(VLOOKUP($E8,Machine_List!$B:$G,6,0),"")) -> General Workman | G8: =IF($E8="","",IFERROR(VLOOKUP($E8,Machine_List!$B:$C,2,0),"")) -> 46521 | H8: =IF($E8="","",IFERROR(VLOOKUP($E8,Machine_List!$B:$D,3,0),"")) -> 6 | J8: =IF($A8="","",IF($I8<>"",$I8,MAX(GlobalStartDate,IFERROR(LOOKUP(2,1/($E$3:INDIRECT("E"&(ROW()-1))=$E8),$M$3:INDIRECT("M"&(ROW()-1))),GlobalStartDate)))) -> 46121.069 | K8: =IF($A8="","",IFERROR(VLOOKUP(B8,CHOOSE(MATCH(C8,Settings!$L$4:$L$10,0),OPR_2P!$A$4:$I$18,SEG_6P!$A$4:$I$18,SOL_4P!$A$4:$I$18,RW_2P!$A$4:$I$18,RW2_4P!$A$4:$I$18,FLAP_4P!$A$4:$I$18,TUBE_4P!$A$4:$I$18),1,0),0)) -> 34 | L8: =IF($A8="","",K8*D8) -> 204 | M8: =IF($A8="","",IF(AND(ISNUMBER(G8),G8>=J8,G8<=(J8+(L8/(IF(F8="Contract Workman",Settings!$K$5,Settings!$K$4))))),J8+(L8/(IF(F8="Contract Workman",Settings!$K$5,Settings!$K$4)))+(H8/(IF(F8="Contract Workman",Settings!$K$5,Settings!$K$4))),J8+(L8/(IF(F8="Contract Workman",Settings!$K$5,Settings!$K$4))))) -> 46130.514 | N8: =IF($A8="","",IF(F8="Contract Workman",IF(AND(MOD(M8,1)>=8/24,MOD(M8,1)<20/24),"Shift S1","Shift S2"),IF(AND(MOD(M8,1)>=7/24,MOD(M8,1)<15/24),"Shift A",IF(AND(MOD(M8,1)>=15/24,MOD(M8,1)<23/24),"Shift B","Shift C")))) -> Shift A | O8: =IF(B8="","", IF(IFERROR(ISNUMBER(SEARCH(B8, VLOOKUP(E8, Machine_List!$B:$J, 9, 0))), FALSE()), "✅ Machine OK", "❌ Sug: " & IFERROR(INDEX(Machine_List!$B$4:$B$50, MATCH("*"&B8&"*", Machine_List!$J$4:$J$50, 0)), "Check Limits"))) -> ✅ Machine OK
A9: =IF(Job_Master!A9="","",Job_Master!A9) -> BJ-103 | B9: =IF($A9="","",Job_Master!B9) -> 20 | C9: =IF($A9="","",Job_Master!C9) -> RW | D9: =IF($A9="","",Job_Master!D9) -> 2 | E9: =IF($A9="","",IFERROR(INDEX(Machine_List!$B$4:$B$7,MATCH("*"&$B9&"*",Machine_List!$J$4:$J$7,0)),"NO COMPATIBLE MACHINE")) -> VTL-MC-01 | F9: =IF($E9="","",IFERROR(VLOOKUP($E9,Machine_List!$B:$G,6,0),"")) -> General Workman | G9: =IF($E9="","",IFERROR(VLOOKUP($E9,Machine_List!$B:$C,2,0),"")) -> 46133 | H9: =IF($E9="","",IFERROR(VLOOKUP($E9,Machine_List!$B:$D,3,0),"")) -> 6 | J9: =IF($A9="","",IF($I9<>"",$I9,MAX(GlobalStartDate,IFERROR(LOOKUP(2,1/($E$3:INDIRECT("E"&(ROW()-1))=$E9),$M$3:INDIRECT("M"&(ROW()-1))),GlobalStartDate)))) -> 46125.421 | K9: =IF($A9="","",IFERROR(VLOOKUP(B9,CHOOSE(MATCH(C9,Settings!$L$4:$L$10,0),OPR_2P!$A$4:$I$18,SEG_6P!$A$4:$I$18,SOL_4P!$A$4:$I$18,RW_2P!$A$4:$I$18,RW2_4P!$A$4:$I$18,FLAP_4P!$A$4:$I$18,TUBE_4P!$A$4:$I$18),1,0),0)) -> 20 | L9: =IF($A9="","",K9*D9) -> 40 | M9: =IF($A9="","",IF(AND(ISNUMBER(G9),G9>=J9,G9<=(J9+(L9/(IF(F9="Contract Workman",Settings!$K$5,Settings!$K$4))))),J9+(L9/(IF(F9="Contract Workman",Settings!$K$5,Settings!$K$4)))+(H9/(IF(F9="Contract Workman",Settings!$K$5,Settings!$K$4))),J9+(L9/(IF(F9="Contract Workman",Settings!$K$5,Settings!$K$4))))) -> 46127.273 | N9: =IF($A9="","",IF(F9="Contract Workman",IF(AND(MOD(M9,1)>=8/24,MOD(M9,1)<20/24),"Shift S1","Shift S2"),IF(AND(MOD(M9,1)>=7/24,MOD(M9,1)<15/24),"Shift A",IF(AND(MOD(M9,1)>=15/24,MOD(M9,1)<23/24),"Shift B","Shift C")))) -> Shift C | O9: =IF(B9="","", IF(IFERROR(ISNUMBER(SEARCH(B9, VLOOKUP(E9, Machine_List!$B:$J, 9, 0))), FALSE()), "✅ Machine OK", "❌ Sug: " & IFERROR(INDEX(Machine_List!$B$4:$B$50, MATCH("*"&B9&"*", Machine_List!$J$4:$J$50, 0)), "Check Limits"))) -> ✅ Machine OK
A10: =IF(Job_Master!A10="","",Job_Master!A10) -> BJ-108 | B10: =IF($A10="","",Job_Master!B10) -> 70 | C10: =IF($A10="","",Job_Master!C10) -> RW | D10: =IF($A10="","",Job_Master!D10) -> 2 | E10: =IF($A10="","",IFERROR(INDEX(Machine_List!$B$4:$B$7,MATCH("*"&$B10&"*",Machine_List!$J$4:$J$7,0)),"NO COMPATIBLE MACHINE")) -> VTL-MC-03 | F10: =IF($E10="","",IFERROR(VLOOKUP($E10,Machine_List!$B:$G,6,0),"")) -> General Workman | G10: =IF($E10="","",IFERROR(VLOOKUP($E10,Machine_List!$B:$C,2,0),"")) -> 46174 | H10: =IF($E10="","",IFERROR(VLOOKUP($E10,Machine_List!$B:$D,3,0),"")) -> 6 | J10: =IF($A10="","",IF($I10<>"",$I10,MAX(GlobalStartDate,IFERROR(LOOKUP(2,1/($E$3:INDIRECT("E"&(ROW()-1))=$E10),$M$3:INDIRECT("M"&(ROW()-1))),GlobalStartDate)))) -> 46113.292 | K10: =IF($A10="","",IFERROR(VLOOKUP(B10,CHOOSE(MATCH(C10,Settings!$L$4:$L$10,0),OPR_2P!$A$4:$I$18,SEG_6P!$A$4:$I$18,SOL_4P!$A$4:$I$18,RW_2P!$A$4:$I$18,RW2_4P!$A$4:$I$18,FLAP_4P!$A$4:$I$18,TUBE_4P!$A$4:$I$18),1,0),0)) -> 70 | L10: =IF($A10="","",K10*D10) -> 140 | M10: =IF($A10="","",IF(AND(ISNUMBER(G10),G10>=J10,G10<=(J10+(L10/(IF(F10="Contract Workman",Settings!$K$5,Settings!$K$4))))),J10+(L10/(IF(F10="Contract Workman",Settings!$K$5,Settings!$K$4)))+(H10/(IF(F10="Contract Workman",Settings!$K$5,Settings!$K$4))),J10+(L10/(IF(F10="Contract Workman",Settings!$K$5,Settings!$K$4))))) -> 46119.773 | N10: =IF($A10="","",IF(F10="Contract Workman",IF(AND(MOD(M10,1)>=8/24,MOD(M10,1)<20/24),"Shift S1","Shift S2"),IF(AND(MOD(M10,1)>=7/24,MOD(M10,1)<15/24),"Shift A",IF(AND(MOD(M10,1)>=15/24,MOD(M10,1)<23/24),"Shift B","Shift C")))) -> Shift B | O10: =IF(B10="","", IF(IFERROR(ISNUMBER(SEARCH(B10, VLOOKUP(E10, Machine_List!$B:$J, 9, 0))), FALSE()), "✅ Machine OK", "❌ Sug: " & IFERROR(INDEX(Machine_List!$B$4:$B$50, MATCH("*"&B10&"*", Machine_List!$J$4:$J$50, 0)), "Check Limits"))) -> ✅ Machine OK
A11: =IF(Job_Master!A11="","",Job_Master!A11) -> BJ-106 | B11: =IF($A11="","",Job_Master!B11) -> 15 | C11: =IF($A11="","",Job_Master!C11) -> RW | D11: =IF($A11="","",Job_Master!D11) -> 2 | E11: =IF($A11="","",IFERROR(INDEX(Machine_List!$B$4:$B$7,MATCH("*"&$B11&"*",Machine_List!$J$4:$J$7,0)),"NO COMPATIBLE MACHINE")) -> VTL-MC-01 | F11: =IF($E11="","",IFERROR(VLOOKUP($E11,Machine_List!$B:$G,6,0),"")) -> General Workman | G11: =IF($E11="","",IFERROR(VLOOKUP($E11,Machine_List!$B:$C,2,0),"")) -> 46133 | H11: =IF($E11="","",IFERROR(VLOOKUP($E11,Machine_List!$B:$D,3,0),"")) -> 6 | J11: =IF($A11="","",IF($I11<>"",$I11,MAX(GlobalStartDate,IFERROR(LOOKUP(2,1/($E$3:INDIRECT("E"&(ROW()-1))=$E11),$M$3:INDIRECT("M"&(ROW()-1))),GlobalStartDate)))) -> 46127.273 | K11: =IF($A11="","",IFERROR(VLOOKUP(B11,CHOOSE(MATCH(C11,Settings!$L$4:$L$10,0),OPR_2P!$A$4:$I$18,SEG_6P!$A$4:$I$18,SOL_4P!$A$4:$I$18,RW_2P!$A$4:$I$18,RW2_4P!$A$4:$I$18,FLAP_4P!$A$4:$I$18,TUBE_4P!$A$4:$I$18),1,0),0)) -> 15 | L11: =IF($A11="","",K11*D11) -> 30 | M11: =IF($A11="","",IF(AND(ISNUMBER(G11),G11>=J11,G11<=(J11+(L11/(IF(F11="Contract Workman",Settings!$K$5,Settings!$K$4))))),J11+(L11/(IF(F11="Contract Workman",Settings!$K$5,Settings!$K$4)))+(H11/(IF(F11="Contract Workman",Settings!$K$5,Settings!$K$4))),J11+(L11/(IF(F11="Contract Workman",Settings!$K$5,Settings!$K$4))))) -> 46128.662 | N11: =IF($A11="","",IF(F11="Contract Workman",IF(AND(MOD(M11,1)>=8/24,MOD(M11,1)<20/24),"Shift S1","Shift S2"),IF(AND(MOD(M11,1)>=7/24,MOD(M11,1)<15/24),"Shift A",IF(AND(MOD(M11,1)>=15/24,MOD(M11,1)<23/24),"Shift B","Shift C")))) -> Shift B | O11: =IF(B11="","", IF(IFERROR(ISNUMBER(SEARCH(B11, VLOOKUP(E11, Machine_List!$B:$J, 9, 0))), FALSE()), "✅ Machine OK", "❌ Sug: " & IFERROR(INDEX(Machine_List!$B$4:$B$50, MATCH("*"&B11&"*", Machine_List!$J$4:$J$50, 0)), "Check Limits"))) -> ✅ Machine OK
A12: =IF(Job_Master!A12="","",Job_Master!A12) -> BJ-109 | B12: =IF($A12="","",Job_Master!B12) -> 30 | C12: =IF($A12="","",Job_Master!C12) -> RW | D12: =IF($A12="","",Job_Master!D12) -> 2 | E12: =IF($A12="","",IFERROR(INDEX(Machine_List!$B$4:$B$7,MATCH("*"&$B12&"*",Machine_List!$J$4:$J$7,0)),"NO COMPATIBLE MACHINE")) -> VTL-MC-02 | F12: =IF($E12="","",IFERROR(VLOOKUP($E12,Machine_List!$B:$G,6,0),"")) -> General Workman | G12: =IF($E12="","",IFERROR(VLOOKUP($E12,Machine_List!$B:$C,2,0),"")) -> 46521 | H12: =IF($E12="","",IFERROR(VLOOKUP($E12,Machine_List!$B:$D,3,0),"")) -> 6 | J12: =IF($A12="","",IF($I12<>"",$I12,MAX(GlobalStartDate,IFERROR(LOOKUP(2,1/($E$3:INDIRECT("E"&(ROW()-1))=$E12),$M$3:INDIRECT("M"&(ROW()-1))),GlobalStartDate)))) -> 46130.514 | K12: =IF($A12="","",IFERROR(VLOOKUP(B12,CHOOSE(MATCH(C12,Settings!$L$4:$L$10,0),OPR_2P!$A$4:$I$18,SEG_6P!$A$4:$I$18,SOL_4P!$A$4:$I$18,RW_2P!$A$4:$I$18,RW2_4P!$A$4:$I$18,FLAP_4P!$A$4:$I$18,TUBE_4P!$A$4:$I$18),1,0),0)) -> 30 | L12: =IF($A12="","",K12*D12) -> 60 | M12: =IF($A12="","",IF(AND(ISNUMBER(G12),G12>=J12,G12<=(J12+(L12/(IF(F12="Contract Workman",Settings!$K$5,Settings!$K$4))))),J12+(L12/(IF(F12="Contract Workman",Settings!$K$5,Settings!$K$4)))+(H12/(IF(F12="Contract Workman",Settings!$K$5,Settings!$K$4))),J12+(L12/(IF(F12="Contract Workman",Settings!$K$5,Settings!$K$4))))) -> 46133.292 | N12: =IF($A12="","",IF(F12="Contract Workman",IF(AND(MOD(M12,1)>=8/24,MOD(M12,1)<20/24),"Shift S1","Shift S2"),IF(AND(MOD(M12,1)>=7/24,MOD(M12,1)<15/24),"Shift A",IF(AND(MOD(M12,1)>=15/24,MOD(M12,1)<23/24),"Shift B","Shift C")))) -> Shift C | O12: =IF(B12="","", IF(IFERROR(ISNUMBER(SEARCH(B12, VLOOKUP(E12, Machine_List!$B:$J, 9, 0))), FALSE()), "✅ Machine OK", "❌ Sug: " & IFERROR(INDEX(Machine_List!$B$4:$B$50, MATCH("*"&B12&"*", Machine_List!$J$4:$J$50, 0)), "Check Limits"))) -> ✅ Machine OK
